Workbook

Sheet Revenue Drivers
A1: Revenue Drivers
A2: Source operating drivers. Model Inputs links to these rows.
C4: Stub | D4: Q1 | E4: Q2 | F4: Q3 | G4: Q4 | H4: Q5 | I4: Q6 | J4: Q7 | K4: Q8 | L4: Q9 | M4: Q10 | N4: Q11 | O4: Q12 | P4: Q13 | Q4: Q14 | R4: Q15 | S4: Q16 | T4: Q17 | U4: Q18 | V4: Q19 | W4: Q20 | X4: Y1 | Y4: Y2 | Z4: Y3 | AA4: Y4 | AB4: Y5
C5: 46162 | D5: 46295 | E5: 46387 | F5: 46477 | G5: 46568 | H5: 46660 | I5: 46752 | J5: 46843 | K5: 46934 | L5: 47026 | M5: 47118 | N5: 47208 | O5: 47299 | P5: 47391 | Q5: 47483 | R5: 47573 | S5: 47664 | T5: 47756 | U5: 47848 | V5: 47938 | W5: 48029 | X5: Annual | Y5: Annual | Z5: Annual | AA5: Annual | AB5: Annual
A6: Revenue Driver Source Rows
A7: Primary line of business / Completed repair order
A8: Primary line of business / Completed repair order - Capacity | B8: Source driver | C8: 1495 | D8: 2000 | E8: 2000 | F8: 2000 | G8: 2000 | H8: 2000 | I8: 2000 | J8: 2000 | K8: 2000 | L8: 2000 | M8: 2000 | N8: 2000 | O8: 2000 | P8: 2000 | Q8: 2000 | R8: 2000 | S8: 2000 | T8: 2000 | U8: 2000 | V8: 2000 | W8: 2000
A9: Primary line of business / Completed repair order - Unit Price | B9: Source driver | C9: 625 | D9: 625 | E9: 627.5 | F9: 630 | G9: 632.5 | H9: 635 | I9: 637.5 | J9: 640 | K9: 642.5 | L9: 645 | M9: 647.5 | N9: 650 | O9: 652.77778 | P9: 655.55556 | Q9: 658.33333 | R9: 661.11111 | S9: 663.88889 | T9: 666.66667 | U9: 669.44444 | V9: 672.22222 | W9: 675
A10: Primary line of business / Completed repair order - Utilization | B10: Source driver | C10: 0.82 | D10: 0.82 | E10: 0.822 | F10: 0.824 | G10: 0.826 | H10: 0.828 | I10: 0.83 | J10: 0.832 | K10: 0.834 | L10: 0.836 | M10: 0.838 | N10: 0.84 | O10: 0.84 | P10: 0.84 | Q10: 0.84 | R10: 0.84 | S10: 0.84 | T10: 0.84 | U10: 0.84 | V10: 0.84 | W10: 0.84
A11: Primary line of business / Completed repair order - Revenue | B11: Capacity x Unit Price x Utilization | C11: =C8*C9*C10 | D11: =D8*D9*D10 | E11: =E8*E9*E10 | F11: =F8*F9*F10 | G11: =G8*G9*G10 | H11: =H8*H9*H10 | I11: =I8*I9*I10 | J11: =J8*J9*J10 | ... W11: =W8*W9*W10 | X11: =SUM(D11:G11) | Y11: =SUM(H11:K11) | Z11: =SUM(L11:O11) | AA11: =SUM(P11:S11) | AB11: =SUM(T11:W11)
A13: Total Capacity Units | B13: All revenue driver capacity units | C13: =SUM(C8) | D13: =SUM(D8) | E13: =SUM(E8) | F13: =SUM(F8) | G13: =SUM(G8) | H13: =SUM(H8) | I13: =SUM(I8) | J13: =SUM(J8) | ... W13: =SUM(W8) | X13: =SUM(D13:G13) | Y13: =SUM(H13:K13) | Z13: =SUM(L13:O13) | AA13: =SUM(P13:S13) | AB13: =SUM(T13:W13)
A14: Total Revenue | B14: All revenue products | C14: =SUM(C11) | D14: =SUM(D11) | E14: =SUM(E11) | F14: =SUM(F11) | G14: =SUM(G11) | H14: =SUM(H11) | I14: =SUM(I11) | J14: =SUM(J11) | ... W14: =SUM(W11) | X14: =SUM(D14:G14) | Y14: =SUM(H14:K14) | Z14: =SUM(L14:O14) | AA14: =SUM(P14:S14) | AB14: =SUM(T14:W14)
A16: Stage Ramp Contract
A17: Actual Revenue QoQ Growth | B17: Total revenue growth from modeled revenue drivers | C17: =0 | D17: =IFERROR(D14/C14-1,0) | E17: =IFERROR(E14/D14-1,0) | F17: =IFERROR(F14/E14-1,0) | G17: =IFERROR(G14/F14-1,0) | H17: =IFERROR(H14/G14-1,0) | I17: =IFERROR(I14/H14-1,0) | J17: =IFERROR(J14/I14-1,0) | K17: =IFERROR(K14/J14-1,0) | ... W17: =IFERROR(W14/V14-1,0) | X17: =AVERAGE(D17:G17) | Y17: =AVERAGE(H17:K17) | Z17: =AVERAGE(L17:O17) | AA17: =AVERAGE(P17:S17) | AB17: =AVERAGE(T17:W17)
A18: Stage Ramp Revenue QoQ Target | B18: GPT-selected stage ramp contract | C18: 0 | D18: 0.02 | E18: 0.02 | F18: 0.02 | G18: 0.02 | H18: 0.02 | I18: 0.02 | J18: 0.02 | K18: 0.02 | L18: 0.02 | M18: 0.02 | N18: 0.02 | O18: 0.02 | P18: 0.02 | Q18: 0.02 | R18: 0.02 | S18: 0.02 | T18: 0.02 | U18: 0.02 | V18: 0.02 | W18: 0.02 | X18: =AVERAGE(D18:G18) | Y18: =AVERAGE(H18:K18) | Z18: =AVERAGE(L18:O18) | AA18: =AVERAGE(P18:S18) | AB18: =AVERAGE(T18:W18)
A19: Stage Ramp Revenue QoQ Max | B19: GPT-selected stage ramp contract | C19: 0 | D19: 0.07 | E19: 0.07 | F19: 0.07 | G19: 0.07 | H19: 0.07 | I19: 0.07 | J19: 0.07 | K19: 0.07 | L19: 0.07 | M19: 0.07 | N19: 0.07 | O19: 0.07 | P19: 0.07 | Q19: 0.07 | R19: 0.07 | S19: 0.07 | T19: 0.07 | U19: 0.07 | V19: 0.07 | W19: 0.07 | X19: =AVERAGE(D19:G19) | Y19: =AVERAGE(H19:K19) | Z19: =AVERAGE(L19:O19) | AA19: =AVERAGE(P19:S19) | AB19: =AVERAGE(T19:W19)
A20: Stage Ramp Revenue QoQ Spike Max | B20: GPT-selected stage ramp contract | C20: 0 | D20: 0.07 | E20: 0.07 | F20: 0.07 | G20: 0.07 | H20: 0.07 | I20: 0.07 | J20: 0.07 | K20: 0.07 | L20: 0.07 | M20: 0.07 | N20: 0.07 | O20: 0.07 | P20: 0.07 | Q20: 0.07 | R20: 0.07 | S20: 0.07 | T20: 0.07 | U20: 0.07 | V20: 0.07 | W20: 0.07 | X20: =AVERAGE(D20:G20) | Y20: =AVERAGE(H20:K20) | Z20: =AVERAGE(L20:O20) | AA20: =AVERAGE(P20:S20) | AB20: =AVERAGE(T20:W20)
A21: Stage Ramp Utilization Cap | B21: GPT-selected stage ramp contract | C21: 0 | D21: 0.65 | E21: 0.67 | F21: 0.69 | G21: 0.71 | H21: 0.73 | I21: 0.75 | J21: 0.77 | K21: 0.79 | L21: 0.81 | M21: 0.83 | N21: 0.85 | O21: 0.85 | P21: 0.85 | Q21: 0.85 | R21: 0.85 | S21: 0.85 | T21: 0.85 | U21: 0.85 | V21: 0.85 | W21: 0.85 | X21: =AVERAGE(D21:G21) | Y21: =AVERAGE(H21:K21) | Z21: =AVERAGE(L21:O21) | AA21: =AVERAGE(P21:S21) | AB21: =AVERAGE(T21:W21)
A22: Stage Ramp COGS % Revenue Target | B22: GPT-selected stage ramp contract | C22: 0 | D22: 0.69 | E22: 0.69 | F22: 0.69 | G22: 0.69 | H22: 0.69 | I22: 0.69 | J22: 0.69 | K22: 0.69 | L22: 0.69 | M22: 0.69 | N22: 0.69 | O22: 0.69 | P22: 0.69 | Q22: 0.69 | R22: 0.69 | S22: 0.69 | T22: 0.69 | U22: 0.69 | V22: 0.69 | W22: 0.69 | X22: =AVERAGE(D22:G22) | Y22: =AVERAGE(H22:K22) | Z22: =AVERAGE(L22:O22) | AA22: =AVERAGE(P22:S22) | AB22: =AVERAGE(T22:W22)
A23: Stage Ramp COGS % Revenue Max | B23: GPT-selected stage ramp contract | C23: 0 | D23: 0.9 | E23: 0.9 | F23: 0.9 | G23: 0.9 | H23: 0.9 | I23: 0.9 | J23: 0.9 | K23: 0.9 | L23: 0.9 | M23: 0.9 | N23: 0.9 | O23: 0.9 | P23: 0.9 | Q23: 0.9 | R23: 0.9 | S23: 0.9 | T23: 0.9 | U23: 0.9 | V23: 0.9 | W23: 0.9 | X23: =AVERAGE(D23:G23) | Y23: =AVERAGE(H23:K23) | Z23: =AVERAGE(L23:O23) | AA23: =AVERAGE(P23:S23) | AB23: =AVERAGE(T23:W23)
A24: Stage Ramp Marketing % Revenue Max | B24: GPT-selected stage ramp contract | C24: 0 | D24: 0.4 | E24: 0.4 | F24: 0.4 | G24: 0.4 | H24: 0.4 | I24: 0.4 | J24: 0.4 | K24: 0.4 | L24: 0.4 | M24: 0.4 | N24: 0.4 | O24: 0.4 | P24: 0.4 | Q24: 0.4 | R24: 0.4 | S24: 0.4 | T24: 0.4 | U24: 0.4 | V24: 0.4 | W24: 0.4 | X24: =AVERAGE(D24:G24) | Y24: =AVERAGE(H24:K24) | Z24: =AVERAGE(L24:O24) | AA24: =AVERAGE(P24:S24) | AB24: =AVERAGE(T24:W24)
A25: Stage Ramp R&D % Revenue Max | B25: GPT-selected stage ramp contract | C25: 0 | D25: 0.29 | E25: 0.29 | F25: 0.29 | G25: 0.29 | H25: 0.29 | I25: 0.29 | J25: 0.29 | K25: 0.29 | L25: 0.29 | M25: 0.29 | N25: 0.29 | O25: 0.29 | P25: 0.29 | Q25: 0.29 | R25: 0.29 | S25: 0.29 | T25: 0.29 | U25: 0.29 | V25: 0.29 | W25: 0.29 | X25: =AVERAGE(D25:G25) | Y25: =AVERAGE(H25:K25) | Z25: =AVERAGE(L25:O25) | AA25: =AVERAGE(P25:S25) | AB25: =AVERAGE(T25:W25)
A26: Stage Ramp G&A % Revenue Max | B26: GPT-selected stage ramp contract | C26: 0 | D26: 0.6 | E26: 0.6 | F26: 0.6 | G26: 0.6 | H26: 0.6 | I26: 0.6 | J26: 0.6 | K26: 0.6 | L26: 0.6 | M26: 0.6 | N26: 0.6 | O26: 0.6 | P26: 0.6 | Q26: 0.6 | R26: 0.6 | S26: 0.6 | T26: 0.6 | U26: 0.6 | V26: 0.6 | W26: 0.6 | X26: =AVERAGE(D26:G26) | Y26: =AVERAGE(H26:K26) | Z26: =AVERAGE(L26:O26) | AA26: =AVERAGE(P26:S26) | AB26: =AVERAGE(T26:W26)
A27: Stage Ramp Lease % Revenue Max | B27: GPT-selected stage ramp contract | C27: 0 | D27: 0.3 | E27: 0.3 | F27: 0.3 | G27: 0.3 | H27: 0.3 | I27: 0.3 | J27: 0.3 | K27: 0.3 | L27: 0.3 | M27: 0.3 | N27: 0.3 | O27: 0.3 | P27: 0.3 | Q27: 0.3 | R27: 0.3 | S27: 0.3 | T27: 0.3 | U27: 0.3 | V27: 0.3 | W27: 0.3 | X27: =AVERAGE(D27:G27) | Y27: =AVERAGE(H27:K27) | Z27: =AVERAGE(L27:O27) | AA27: =AVERAGE(P27:S27) | AB27: =AVERAGE(T27:W27)
A28: Stage Ramp Net Income Margin Floor | B28: GPT-selected stage ramp contract | C28: 0 | D28: 0 | E28: 0 | F28: 0 | G28: 0 | H28: 0.05 | I28: 0.05 | J28: 0.05 | K28: 0.05 | L28: 0.05 | M28: 0.05 | N28: 0.07 | O28: 0.07 | P28: 0.07 | Q28: 0.07 | R28: 0.07 | S28: 0.07 | T28: 0.07 | U28: 0.07 | V28: 0.07 | W28: 0.07 | X28: =AVERAGE(D28:G28) | Y28: =AVERAGE(H28:K28) | Z28: =AVERAGE(L28:O28) | AA28: =AVERAGE(P28:S28) | AB28: =AVERAGE(T28:W28)

Sheet Payroll Schedule
A1: Payroll Schedule
A2: OEWS-title, capacity/utilization-driven payroll source. Model Inputs links to Total Payroll.
C4: Stub | D4: Q1 | E4: Q2 | F4: Q3 | G4: Q4 | H4: Q5 | I4: Q6 | J4: Q7 | K4: Q8 | L4: Q9 | M4: Q10 | N4: Q11 | O4: Q12 | P4: Q13 | Q4: Q14 | R4: Q15 | S4: Q16 | T4: Q17 | U4: Q18 | V4: Q19 | W4: Q20 | X4: Y1 | Y4: Y2 | Z4: Y3 | AA4: Y4 | AB4: Y5
C5: 46162 | D5: 46295 | E5: 46387 | F5: 46477 | G5: 46568 | H5: 46660 | I5: 46752 | J5: 46843 | K5: 46934 | L5: 47026 | M5: 47118 | N5: 47208 | O5: 47299 | P5: 47391 | Q5: 47483 | R5: 47573 | S5: 47664 | T5: 47756 | U5: 47848 | V5: 47938 | W5: 48029 | X5: Annual | Y5: Annual | Z5: Annual | AA5: Annual | AB5: Annual
A6: Payroll Assumptions
A7: Capacity Labor Model | B7: labor_driven
A8: Labor Intensity Class | B8: high
A9: Wage Positioning Tier | B9: market
A10: Wage Positioning Multiplier | B10: 1.25
A11: Capacity Units per Supporting FTE | B11: 250
A12: Target Payroll % of Revenue | B12: 0.22
A14: Quarter Summary
A15: Total Ending FTE | B15: Formula output from payroll detail | C15: =SUMIFS($G$27:$G$86,$A$27:$A$86,0) | D15: =SUMIFS($G$27:$G$86,$A$27:$A$86,1) | E15: =SUMIFS($G$27:$G$86,$A$27:$A$86,2) | F15: =SUMIFS($G$27:$G$86,$A$27:$A$86,3) | G15: =SUMIFS($G$27:$G$86,$A$27:$A$86,4) | H15: =SUMIFS($G$27:$G$86,$A$27:$A$86,5) | I15: =SUMIFS($G$27:$G$86,$A$27:$A$86,6) | J15: =SUMIFS($G$27:$G$86,$A$27:$A$86,7) | K15: =SUMIFS($G$27:$G$86,$A$27:$A$86,8) | L15: =SUMIFS($G$27:$G$86,$A$27:$A$86,9) | M15: =SUMIFS($G$27:$G$86,$A$27:$A$86,10) | N15: =SUMIFS($G$27:$G$86,$A$27:$A$86,11) | O15: =SUMIFS($G$27:$G$86,$A$27:$A$86,12) | P15: =SUMIFS($G$27:$G$86,$A$27:$A$86,13) | Q15: =SUMIFS($G$27:$G$86,$A$27:$A$86,14) | R15: =SUMIFS($G$27:$G$86,$A$27:$A$86,15) | S15: =SUMIFS($G$27:$G$86,$A$27:$A$86,16) | T15: =SUMIFS($G$27:$G$86,$A$27:$A$86,17) | U15: =SUMIFS($G$27:$G$86,$A$27:$A$86,18) | V15: =SUMIFS($G$27:$G$86,$A$27:$A$86,19) | W15: =SUMIFS($G$27:$G$86,$A$27:$A$86,20) | X15: =G15 | Y15: =K15 | Z15: =O15 | AA15: =S15 | AB15: =W15
A16: Total Average FTE | B16: Formula output from payroll detail | C16: =SUMIFS($H$27:$H$86,$A$27:$A$86,0) | D16: =SUMIFS($H$27:$H$86,$A$27:$A$86,1) | E16: =SUMIFS($H$27:$H$86,$A$27:$A$86,2) | F16: =SUMIFS($H$27:$H$86,$A$27:$A$86,3) | G16: =SUMIFS($H$27:$H$86,$A$27:$A$86,4) | H16: =SUMIFS($H$27:$H$86,$A$27:$A$86,5) | I16: =SUMIFS($H$27:$H$86,$A$27:$A$86,6) | J16: =SUMIFS($H$27:$H$86,$A$27:$A$86,7) | K16: =SUMIFS($H$27:$H$86,$A$27:$A$86,8) | L16: =SUMIFS($H$27:$H$86,$A$27:$A$86,9) | M16: =SUMIFS($H$27:$H$86,$A$27:$A$86,10) | N16: =SUMIFS($H$27:$H$86,$A$27:$A$86,11) | O16: =SUMIFS($H$27:$H$86,$A$27:$A$86,12) | P16: =SUMIFS($H$27:$H$86,$A$27:$A$86,13) | Q16: =SUMIFS($H$27:$H$86,$A$27:$A$86,14) | R16: =SUMIFS($H$27:$H$86,$A$27:$A$86,15) | S16: =SUMIFS($H$27:$H$86,$A$27:$A$86,16) | T16: =SUMIFS($H$27:$H$86,$A$27:$A$86,17) | U16: =SUMIFS($H$27:$H$86,$A$27:$A$86,18) | V16: =SUMIFS($H$27:$H$86,$A$27:$A$86,19) | W16: =SUMIFS($H$27:$H$86,$A$27:$A$86,20) | X16: =AVERAGE(D16:G16) | Y16: =AVERAGE(H16:K16) | Z16: =AVERAGE(L16:O16) | AA16: =AVERAGE(P16:S16) | AB16: =AVERAGE(T16:W16)
A17: Total Payroll | B17: Formula output from payroll detail | C17: =SUMIFS($M$27:$M$86,$A$27:$A$86,0) | D17: =SUMIFS($M$27:$M$86,$A$27:$A$86,1) | E17: =SUMIFS($M$27:$M$86,$A$27:$A$86,2) | F17: =SUMIFS($M$27:$M$86,$A$27:$A$86,3) | G17: =SUMIFS($M$27:$M$86,$A$27:$A$86,4) | H17: =SUMIFS($M$27:$M$86,$A$27:$A$86,5) | I17: =SUMIFS($M$27:$M$86,$A$27:$A$86,6) | J17: =SUMIFS($M$27:$M$86,$A$27:$A$86,7) | K17: =SUMIFS($M$27:$M$86,$A$27:$A$86,8) | L17: =SUMIFS($M$27:$M$86,$A$27:$A$86,9) | M17: =SUMIFS($M$27:$M$86,$A$27:$A$86,10) | N17: =SUMIFS($M$27:$M$86,$A$27:$A$86,11) | O17: =SUMIFS($M$27:$M$86,$A$27:$A$86,12) | P17: =SUMIFS($M$27:$M$86,$A$27:$A$86,13) | Q17: =SUMIFS($M$27:$M$86,$A$27:$A$86,14) | R17: =SUMIFS($M$27:$M$86,$A$27:$A$86,15) | S17: =SUMIFS($M$27:$M$86,$A$27:$A$86,16) | T17: =SUMIFS($M$27:$M$86,$A$27:$A$86,17) | U17: =SUMIFS($M$27:$M$86,$A$27:$A$86,18) | V17: =SUMIFS($M$27:$M$86,$A$27:$A$86,19) | W17: =SUMIFS($M$27:$M$86,$A$27:$A$86,20) | X17: =SUM(D17:G17) | Y17: =SUM(H17:K17) | Z17: =SUM(L17:O17) | AA17: =SUM(P17:S17) | AB17: =SUM(T17:W17)
A18: Total Revenue | B18: Linked from Revenue Drivers | C18: ='Revenue Drivers'!C14 | D18: ='Revenue Drivers'!D14 | E18: ='Revenue Drivers'!E14 | F18: ='Revenue Drivers'!F14 | G18: ='Revenue Drivers'!G14 | H18: ='Revenue Drivers'!H14 | I18: ='Revenue Drivers'!I14 | J18: ='Revenue Drivers'!J14 | ... W18: ='Revenue Drivers'!W14 | X18: =SUM(D18:G18) | Y18: =SUM(H18:K18) | Z18: =SUM(L18:O18) | AA18: =SUM(P18:S18) | AB18: =SUM(T18:W18)
A19: Total Capacity Units | B19: Linked from Revenue Drivers | C19: ='Revenue Drivers'!C13 | D19: ='Revenue Drivers'!D13 | E19: ='Revenue Drivers'!E13 | F19: ='Revenue Drivers'!F13 | G19: ='Revenue Drivers'!G13 | H19: ='Revenue Drivers'!H13 | I19: ='Revenue Drivers'!I13 | J19: ='Revenue Drivers'!J13 | ... W19: ='Revenue Drivers'!W13 | X19: =SUM(D19:G19) | Y19: =SUM(H19:K19) | Z19: =SUM(L19:O19) | AA19: =SUM(P19:S19) | AB19: =SUM(T19:W19)
A20: Revenue per Employee | B20: Python-built productivity formula | C20: =IFERROR(C18/C16,0) | D20: =IFERROR(D18/D16,0) | E20: =IFERROR(E18/E16,0) | F20: =IFERROR(F18/F16,0) | G20: =IFERROR(G18/G16,0) | H20: =IFERROR(H18/H16,0) | I20: =IFERROR(I18/I16,0) | J20: =IFERROR(J18/J16,0) | ... AB20: =IFERROR(AB18/AB16,0)
A21: Units per Employee | B21: Python-built productivity formula | C21: =IFERROR(C19/C16,0) | D21: =IFERROR(D19/D16,0) | E21: =IFERROR(E19/E16,0) | F21: =IFERROR(F19/F16,0) | G21: =IFERROR(G19/G16,0) | H21: =IFERROR(H19/H16,0) | I21: =IFERROR(I19/I16,0) | J21: =IFERROR(J19/J16,0) | ... AB21: =IFERROR(AB19/AB16,0)
A22: Payroll % of Revenue | B22: Python-built productivity formula | C22: =IFERROR(C17/C18,0) | D22: =IFERROR(D17/D18,0) | E22: =IFERROR(E17/E18,0) | F22: =IFERROR(F17/F18,0) | G22: =IFERROR(G17/G18,0) | H22: =IFERROR(H17/H18,0) | I22: =IFERROR(I17/I18,0) | J22: =IFERROR(J17/J18,0) | ... AB22: =IFERROR(AB17/AB18,0)
A25: Payroll Detail
A26: Quarter | B26: Staffing Class | C26: Title / Person | D26: OEWS Title | E26: Starting FTE | F26: Hires | G26: Ending FTE | H26: Average FTE | I26: Annual Wage | J26: Benefits % | K26: Wage Cost | L26: Taxes & Benefits | M26: Total Payroll | N26: Wage Source
A27: 1 | B27: key_person | C27: Owner & General Manager | E27: 1 | F27: 0 | G27: =E27+F27 | H27: =(E27+G27)/2 | I27: 78840 | J27: 0.22 | K27: =H27*I27/4 | L27: =K27*J27 | M27: =K27+L27 | N27: oews_median
A28: 2 | B28: key_person | C28: Owner & General Manager | E28: 1 | F28: 0 | G28: =E28+F28 | H28: =(E28+G28)/2 | I28: 78840 | J28: 0.22 | K28: =H28*I28/4 | L28: =K28*J28 | M28: =K28+L28 | N28: oews_median
A29: 3 | B29: key_person | C29: Owner & General Manager | E29: 1 | F29: 0 | G29: =E29+F29 | H29: =(E29+G29)/2 | I29: 78840 | J29: 0.22 | K29: =H29*I29/4 | L29: =K29*J29 | M29: =K29+L29 | N29: oews_median
A30: 4 | B30: key_person | C30: Owner & General Manager | E30: 1 | F30: 0 | G30: =E30+F30 | H30: =(E30+G30)/2 | I30: 78840 | J30: 0.22 | K30: =H30*I30/4 | L30: =K30*J30 | M30: =K30+L30 | N30: oews_median
A31: 5 | B31: key_person | C31: Owner & General Manager | E31: 1 | F31: 0 | G31: =E31+F31 | H31: =(E31+G31)/2 | I31: 81205 | J31: 0.22 | K31: =H31*I31/4 | L31: =K31*J31 | M31: =K31+L31 | N31: oews_median
A32: 6 | B32: key_person | C32: Owner & General Manager | E32: 1 | F32: 0 | G32: =E32+F32 | H32: =(E32+G32)/2 | I32: 81205 | J32: 0.22 | K32: =H32*I32/4 | L32: =K32*J32 | M32: =K32+L32 | N32: oews_median
A33: 7 | B33: key_person | C33: Owner & General Manager | E33: 1 | F33: 0 | G33: =E33+F33 | H33: =(E33+G33)/2 | I33: 81205 | J33: 0.22 | K33: =H33*I33/4 | L33: =K33*J33 | M33: =K33+L33 | N33: oews_median
A34: 8 | B34: key_person | C34: Owner & General Manager | E34: 1 | F34: 0 | G34: =E34+F34 | H34: =(E34+G34)/2 | I34: 81205 | J34: 0.22 | K34: =H34*I34/4 | L34: =K34*J34 | M34: =K34+L34 | N34: oews_median
A35: 9 | B35: key_person | C35: Owner & General Manager | E35: 1 | F35: 0 | G35: =E35+F35 | H35: =(E35+G35)/2 | I35: 83641 | J35: 0.22 | K35: =H35*I35/4 | L35: =K35*J35 | M35: =K35+L35 | N35: oews_median
A36: 10 | B36: key_person | C36: Owner & General Manager | E36: 1 | F36: 0 | G36: =E36+F36 | H36: =(E36+G36)/2 | I36: 83641 | J36: 0.22 | K36: =H36*I36/4 | L36: =K36*J36 | M36: =K36+L36 | N36: oews_median
A37: 11 | B37: key_person | C37: Owner & General Manager | E37: 1 | F37: 0 | G37: =E37+F37 | H37: =(E37+G37)/2 | I37: 83641 | J37: 0.22 | K37: =H37*I37/4 | L37: =K37*J37 | M37: =K37+L37 | N37: oews_median
A38: 12 | B38: key_person | C38: Owner & General Manager | E38: 1 | F38: 0 | G38: =E38+F38 | H38: =(E38+G38)/2 | I38: 83641 | J38: 0.22 | K38: =H38*I38/4 | L38: =K38*J38 | M38: =K38+L38 | N38: oews_median
... A66: 20 | B66: key_person | C66: Service Manager | E66: 1 | F66: 0 | G66: =E66+F66 | H66: =(E66+G66)/2 | I66: 73147 | J66: 0.22 | K66: =H66*I66/4 | L66: =K66*J66 | M66: =K66+L66 | N66: oews_median
A67: 1 | B67: supporting_staff | C67: Automotive Service Technicians and Mechanics | D67: Automotive Service Technicians and Mechanics | E67: 6 | F67: 0 | G67: =E67+F67 | H67: =(E67+G67)/2 | I67: 60400 | J67: 0.22 | K67: =H67*I67/4 | L67: =K67*J67 | M67: =K67+L67 | N67: oews_title_catalog:oews_median
A68: 2 | B68: supporting_staff | C68: Automotive Service Technicians and Mechanics | D68: Automotive Service Technicians and Mechanics | E68: 6 | F68: 0 | G68: =E68+F68 | H68: =(E68+G68)/2 | I68: 60400 | J68: 0.22 | K68: =H68*I68/4 | L68: =K68*J68 | M68: =K68+L68 | N68: oews_title_catalog:oews_median
A69: 3 | B69: supporting_staff | C69: Automotive Service Technicians and Mechanics | D69: Automotive Service Technicians and Mechanics | E69: 6 | F69: 0 | G69: =E69+F69 | H69: =(E69+G69)/2 | I69: 60400 | J69: 0.22 | K69: =H69*I69/4 | L69: =K69*J69 | M69: =K69+L69 | N69: oews_title_catalog:oews_median
A70: 4 | B70: supporting_staff | C70: Automotive Service Technicians and Mechanics | D70: Automotive Service Technicians and Mechanics | E70: 6 | F70: 0 | G70: =E70+F70 | H70: =(E70+G70)/2 | I70: 60400 | J70: 0.22 | K70: =H70*I70/4 | L70: =K70*J70 | M70: =K70+L70 | N70: oews_title_catalog:oews_median
A71: 5 | B71: supporting_staff | C71: Automotive Service Technicians and Mechanics | D71: Automotive Service Technicians and Mechanics | E71: 6 | F71: 0 | G71: =E71+F71 | H71: =(E71+G71)/2 | I71: 62212 | J71: 0.22 | K71: =H71*I71/4 | L71: =K71*J71 | M71: =K71+L71 | N71: oews_title_catalog:oews_median
...

Sheet Debt Schedule
A1: Debt Schedule
A2: Debt, interest, and capital lease mechanics. Model Inputs links to calculated outputs.
C4: Stub | D4: Q1 | E4: Q2 | F4: Q3 | G4: Q4 | H4: Q5 | I4: Q6 | J4: Q7 | K4: Q8 | L4: Q9 | M4: Q10 | N4: Q11 | O4: Q12 | P4: Q13 | Q4: Q14 | R4: Q15 | S4: Q16 | T4: Q17 | U4: Q18 | V4: Q19 | W4: Q20 | X4: Y1 | Y4: Y2 | Z4: Y3 | AA4: Y4 | AB4: Y5
C5: 46162 | D5: 46295 | E5: 46387 | F5: 46477 | G5: 46568 | H5: 46660 | I5: 46752 | J5: 46843 | K5: 46934 | L5: 47026 | M5: 47118 | N5: 47208 | O5: 47299 | P5: 47391 | Q5: 47483 | R5: 47573 | S5: 47664 | T5: 47756 | U5: 47848 | V5: 47938 | W5: 48029 | X5: Annual | Y5: Annual | Z5: Annual | AA5: Annual | AB5: Annual
A6: Debt Amortization
A7: Opening Debt | B7: Calculated | C7: 450000 | D7: =C11 | E7: =D11 | F7: =E11 | G7: =F11 | H7: =G11 | I7: =H11 | J7: =I11 | K7: =J11 | ... W7: =V11 | X7: =G7 | Y7: =K7 | Z7: =O7 | AA7: =S7 | AB7: =W7
A8: Debt Issuance | B8: Source borrowing | C8: 0 | D8: 0 | E8: 0 | F8: 0 | G8: 0 | H8: 0 | I8: 0 | J8: 0 | K8: 0 | L8: 0 | M8: 0 | N8: 0 | O8: 0 | P8: 0 | Q8: 0 | R8: 0 | S8: 0 | T8: 0 | U8: 0 | V8: 0 | W8: 0 | X8: =SUM(D8:G8) | Y8: =SUM(H8:K8) | Z8: =SUM(L8:O8) | AA8: =SUM(P8:S8) | AB8: =SUM(T8:W8)
A9: Requested Debt Repayment | B9: Source scheduled repayment | C9: 0 | D9: 22500 | E9: 22500 | F9: 22500 | G9: 22500 | H9: 22500 | I9: 22500 | J9: 22500 | K9: 22500 | L9: 22500 | M9: 22500 | N9: 37380 | O9: 63635 | P9: 65328 | Q9: 58657 | R9: 22500 | S9: 22500 | T9: 22500 | U9: 22500 | V9: 22500 | W9: 22500 | X9: =SUM(D9:G9) | Y9: =SUM(H9:K9) | Z9: =SUM(L9:O9) | AA9: =SUM(P9:S9) | AB9: =SUM(T9:W9)
A10: Actual Debt Repayment | B10: MIN(requested repayment, opening debt + issuance) | C10: =MIN(C9,C7+C8) | D10: =MIN(D9,D7+D8) | E10: =MIN(E9,E7+E8) | F10: =MIN(F9,F7+F8) | G10: =MIN(G9,G7+G8) | H10: =MIN(H9,H7+H8) | I10: =MIN(I9,I7+I8) | J10: =MIN(J9,J7+J8) | ... W10: =MIN(W9,W7+W8) | X10: =SUM(D10:G10) | Y10: =SUM(H10:K10) | Z10: =SUM(L10:O10) | AA10: =SUM(P10:S10) | AB10: =SUM(T10:W10)
A11: Closing Debt | B11: Calculated | C11: =MAX(0,C7+C8-C10) | D11: =MAX(0,D7+D8-D10) | E11: =MAX(0,E7+E8-E10) | F11: =MAX(0,F7+F8-F10) | G11: =MAX(0,G7+G8-G10) | H11: =MAX(0,H7+H8-H10) | I11: =MAX(0,I7+I8-I10) | J11: =MAX(0,J7+J8-J10) | ... W11: =MAX(0,W7+W8-W10) | X11: =G11 | Y11: =K11 | Z11: =O11 | AA11: =S11 | AB11: =W11
A12: Interest Rate | B12: Source rate | C12: 0.017778 | D12: 0.023125 | E12: 0.023125 | F12: 0.023125 | G12: 0.023125 | H12: 0.023125 | I12: 0.023125 | J12: 0.023125 | K12: 0.023125 | L12: 0.023125 | M12: 0.023125 | N12: 0.023125 | O12: 0.023125 | P12: 0.023125 | Q12: 0.023125 | R12: 0.023125 | S12: 0.023125 | T12: 0.023125 | U12: 0.023125 | V12: 0.023125 | W12: 0.023125 | X12: =SUM(D12:G12) | Y12: =SUM(H12:K12) | Z12: =SUM(L12:O12) | AA12: =SUM(P12:S12) | AB12: =SUM(T12:W12)
A13: Interest Expense | B13: Average debt balance x rate | C13: =((C7+C11)/2)*C12 | D13: =((D7+D11)/2)*D12 | E13: =((E7+E11)/2)*E12 | F13: =((F7+F11)/2)*F12 | G13: =((G7+G11)/2)*G12 | H13: =((H7+H11)/2)*H12 | I13: =((I7+I11)/2)*I12 | J13: =((J7+J11)/2)*J12 | ... W13: =((W7+W11)/2)*W12 | X13: =SUM(D13:G13) | Y13: =SUM(H13:K13) | Z13: =SUM(L13:O13) | AA13: =SUM(P13:S13) | AB13: =SUM(T13:W13)
A14: Total Debt Service | B14: Interest + actual repayment | C14: =C13+C10 | D14: =D13+D10 | E14: =E13+E10 | F14: =F13+F10 | G14: =G13+G10 | H14: =H13+H10 | I14: =I13+I10 | J14: =J13+J10 | ... W14: =W13+W10 | X14: =SUM(D14:G14) | Y14: =SUM(H14:K14) | Z14: =SUM(L14:O14) | AA14: =SUM(P14:S14) | AB14: =SUM(T14:W14)
A17: Capital Lease Schedule
A18: Lease Opening Balance | B18: Capital leases | C18: 54000 | D18: =C23 | E18: =D23 | F18: =E23 | G18: =F23 | H18: =G23 | I18: =H23 | J18: =I23 | K18: =J23 | ... W18: =V23 | X18: =G18 | Y18: =K18 | Z18: =O18 | AA18: =S18 | AB18: =W18
A19: Requested Lease Principal Repayments | B19: Capital leases | C19: 0 | D19: 17500 | E19: 17500 | F19: 17500 | G19: 17500 | H19: 17500 | I19: 17500 | J19: 17500 | K19: 17500 | L19: 17500 | M19: 17500 | N19: 17500 | O19: 17500 | P19: 17500 | Q19: 17500 | R19: 17500 | S19: 17500 | T19: 17500 | U19: 17500 | V19: 17500 | W19: 17500 | X19: =SUM(D19:G19) | Y19: =SUM(H19:K19) | Z19: =SUM(L19:O19) | AA19: =SUM(P19:S19) | AB19: =SUM(T19:W19)
A20: Lease Principal Repayments | B20: Capital leases | C20: =MIN(C19,C18+C21) | D20: =MIN(D19,D18+D21) | E20: =MIN(E19,E18+E21) | F20: =MIN(F19,F18+F21) | G20: =MIN(G19,G18+G21) | H20: =MIN(H19,H18+H21) | I20: =MIN(I19,I18+I21) | J20: =MIN(J19,J18+J21) | ... W20: =MIN(W19,W18+W21) | X20: =SUM(D20:G20) | Y20: =SUM(H20:K20) | Z20: =SUM(L20:O20) | AA20: =SUM(P20:S20) | AB20: =SUM(T20:W20)
A21: Lease Net Additions | B21: Capital leases | C21: 0 | D21: 0 | E21: 0 | F21: 0 | G21: 0 | H21: 0 | I21: 0 | J21: 0 | K21: 0 | L21: 0 | M21: 0 | N21: 0 | O21: 0 | P21: 0 | Q21: 0 | R21: 0 | S21: 0 | T21: 0 | U21: 0 | V21: 0 | W21: 0 | X21: =SUM(D21:G21) | Y21: =SUM(H21:K21) | Z21: =SUM(L21:O21) | AA21: =SUM(P21:S21) | AB21: =SUM(T21:W21)
A22: Lease Interest Expense | B22: Capital leases | C22: 0 | D22: =D18*D12 | E22: =E18*E12 | F22: =F18*F12 | G22: =G18*G12 | H22: =H18*H12 | I22: =I18*I12 | J22: =J18*J12 | K22: =K18*K12 | ... W22: =W18*W12 | X22: =SUM(D22:G22) | Y22: =SUM(H22:K22) | Z22: =SUM(L22:O22) | AA22: =SUM(P22:S22) | AB22: =SUM(T22:W22)
A23: Lease Closing Balance | B23: Capital leases | C23: =MAX(0,C18+C21-C20) | D23: =MAX(0,D18+D21-D20) | E23: =MAX(0,E18+E21-E20) | F23: =MAX(0,F18+F21-F20) | G23: =MAX(0,G18+G21-G20) | H23: =MAX(0,H18+H21-H20) | I23: =MAX(0,I18+I21-I20) | J23: =MAX(0,J18+J21-J20) | ... W23: =MAX(0,W18+W21-W20) | X23: =G23 | Y23: =K23 | Z23: =O23 | AA23: =S23 | AB23: =W23
A24: Right-of-Use Asset Opening | B24: Capital leases | C24: 54000 | D24: =C26 | E24: =D26 | F24: =E26 | G24: =F26 | H24: =G26 | I24: =H26 | J24: =I26 | K24: =J26 | ... W24: =V26 | X24: =G24 | Y24: =K24 | Z24: =O24 | AA24: =S24 | AB24: =W24
A25: Lease Asset Depreciation | B25: Capital leases | C25: 0 | D25: =MIN((C18/20),D24) | E25: =MIN((C18/20),E24) | F25: =MIN((C18/20),F24) | G25: =MIN((C18/20),G24) | H25: =MIN((C18/20),H24) | I25: =MIN((C18/20),I24) | J25: =MIN((C18/20),J24) | K25: =MIN((C18/20),K24) | L25: =MIN((C18/20),L24) | M25: =MIN((C18/20),M24) | N25: =MIN((C18/20),N24) | O25: =MIN((C18/20),O24) | P25: =MIN((C18/20),P24) | Q25: =MIN((C18/20),Q24) | R25: =MIN((C18/20),R24) | S25: =MIN((C18/20),S24) | T25: =MIN((C18/20),T24) | U25: =MIN((C18/20),U24) | V25: =MIN((C18/20),V24) | W25: =MIN((C18/20),W24) | X25: =SUM(D25:G25) | Y25: =SUM(H25:K25) | Z25: =SUM(L25:O25) | AA25: =SUM(P25:S25) | AB25: =SUM(T25:W25)
A26: Right-of-Use Asset Closing | B26: Capital leases | C26: =MAX(0,C24-C25) | D26: =MAX(0,D24-D25) | E26: =MAX(0,E24-E25) | F26: =MAX(0,F24-F25) | G26: =MAX(0,G24-G25) | H26: =MAX(0,H24-H25) | I26: =MAX(0,I24-I25) | J26: =MAX(0,J24-J25) | ... W26: =MAX(0,W24-W25) | X26: =G26 | Y26: =K26 | Z26: =O26 | AA26: =S26 | AB26: =W26

Sheet CapEx Depreciation
A1: CapEx & Depreciation Schedule
A2: Capital expenditure and depreciation mechanics. Model Inputs links to calculated outputs.
C4: Stub | D4: Q1 | E4: Q2 | F4: Q3 | G4: Q4 | H4: Q5 | I4: Q6 | J4: Q7 | K4: Q8 | L4: Q9 | M4: Q10 | N4: Q11 | O4: Q12 | P4: Q13 | Q4: Q14 | R4: Q15 | S4: Q16 | T4: Q17 | U4: Q18 | V4: Q19 | W4: Q20 | X4: Y1 | Y4: Y2 | Z4: Y3 | AA4: Y4 | AB4: Y5
C5: 46162 | D5: 46295 | E5: 46387 | F5: 46477 | G5: 46568 | H5: 46660 | I5: 46752 | J5: 46843 | K5: 46934 | L5: 47026 | M5: 47118 | N5: 47208 | O5: 47299 | P5: 47391 | Q5: 47483 | R5: 47573 | S5: 47664 | T5: 47756 | U5: 47848 | V5: 47938 | W5: 48029 | X5: Annual | Y5: Annual | Z5: Annual | AA5: Annual | AB5: Annual
A6: PPE and Depreciation
A7: Opening PPE | B7: Calculated | C7: 1200000 | D7: =C12 | E7: =D12 | F7: =E12 | G7: =F12 | H7: =G12 | I7: =H12 | J7: =I12 | K7: =J12 | ... W7: =V12 | X7: =G7 | Y7: =K7 | Z7: =O7 | AA7: =S7 | AB7: =W7
A8: Capital Expenditures | B8: Schedule source | C8: 0 | D8: 8396.4 | E8: 8452.2109 | F8: 8505.4598 | G8: 8556.1013 | H8: 8604.101 | I8: 8649.4274 | J8: 8692.0518 | K8: 8731.931 | L8: 8769.0329 | M8: 8803.3286 | N8: 8834.7829 | O8: 8863.3634 | P8: 8889.0495 | Q8: 8911.8054 | R8: 8931.5985 | S8: 8948.4078 | T8: 8962.2063 | U8: 8972.9609 | V8: 8980.6507 | W8: 8985.2578 | X8: =SUM(D8:G8) | Y8: =SUM(H8:K8) | Z8: =SUM(L8:O8) | AA8: =SUM(P8:S8) | AB8: =SUM(T8:W8)
A9: Lease Additions | B9: Schedule source | C9: 0 | D9: ='Debt Schedule'!D21 | E9: ='Debt Schedule'!E21 | F9: ='Debt Schedule'!F21 | G9: ='Debt Schedule'!G21 | H9: ='Debt Schedule'!H21 | I9: ='Debt Schedule'!I21 | J9: ='Debt Schedule'!J21 | K9: ='Debt Schedule'!K21 | ... W9: ='Debt Schedule'!W21 | X9: =SUM(D9:G9) | Y9: =SUM(H9:K9) | Z9: =SUM(L9:O9) | AA9: =SUM(P9:S9) | AB9: =SUM(T9:W9)
A10: Depreciation Rate | B10: Schedule source | C10: 0 | D10: 0.00035 | E10: 0.000697 | F10: 0.001043 | G10: 0.001387 | H10: 0.001729 | I10: 0.002069 | J10: 0.002409 | K10: 0.002748 | L10: 0.003086 | M10: 0.003424 | N10: 0.003762 | O10: 0.004099 | P10: 0.004437 | Q10: 0.004776 | R10: 0.005115 | S10: 0.005455 | T10: 0.005797 | U10: 0.00614 | V10: 0.006484 | W10: 0.006831 | X10: =SUM(D10:G10) | Y10: =SUM(H10:K10) | Z10: =SUM(L10:O10) | AA10: =SUM(P10:S10) | AB10: =SUM(T10:W10)
A11: Depreciation Expense | B11: Calculated | C11: =MIN(C7*C10,C7) | D11: =MIN(D7*D10,D7) | E11: =MIN(E7*E10,E7) | F11: =MIN(F7*F10,F7) | G11: =MIN(G7*G10,G7) | H11: =MIN(H7*H10,H7) | I11: =MIN(I7*I10,I7) | J11: =MIN(J7*J10,J7) | ... W11: =MIN(W7*W10,W7) | X11: =SUM(D11:G11) | Y11: =SUM(H11:K11) | Z11: =SUM(L11:O11) | AA11: =SUM(P11:S11) | AB11: =SUM(T11:W11)
A12: Closing PPE | B12: Calculated | C12: =MAX(0,C7+C8+C9-C11) | D12: =MAX(0,D7+D8+D9-D11) | E12: =MAX(0,E7+E8+E9-E11) | F12: =MAX(0,F7+F8+F9-F11) | G12: =MAX(0,G7+G8+G9-G11) | H12: =MAX(0,H7+H8+H9-H11) | I12: =MAX(0,I7+I8+I9-I11) | J12: =MAX(0,J7+J8+J9-J11) | ... W12: =MAX(0,W7+W8+W9-W11) | X12: =G12 | Y12: =K12 | Z12: =O12 | AA12: =S12 | AB12: =W12
A13: Opening Accumulated Depreciation | B13: Calculated | C13: 0 | D13: =C14 | E13: =D14 | F13: =E14 | G13: =F14 | H13: =G14 | I13: =H14 | J13: =I14 | K13: =J14 | ... W13: =V14 | X13: =G13 | Y13: =K13 | Z13: =O13 | AA13: =S13 | AB13: =W13
A14: Accumulated Depreciation | B14: Calculated | C14: =C13-C11 | D14: =D13-D11 | E14: =E13-E11 | F14: =F13-F11 | G14: =G13-G11 | H14: =H13-H11 | I14: =I13-I11 | J14: =J13-J11 | ... W14: =W13-W11 | X14: =G14 | Y14: =K14 | Z14: =O14 | AA14: =S14 | AB14: =W14

Sheet Working Capital
A1: Working Capital Schedule
A2: Working-capital drivers. Model Inputs links to these source rows.
C4: Stub | D4: Q1 | E4: Q2 | F4: Q3 | G4: Q4 | H4: Q5 | I4: Q6 | J4: Q7 | K4: Q8 | L4: Q9 | M4: Q10 | N4: Q11 | O4: Q12 | P4: Q13 | Q4: Q14 | R4: Q15 | S4: Q16 | T4: Q17 | U4: Q18 | V4: Q19 | W4: Q20 | X4: Y1 | Y4: Y2 | Z4: Y3 | AA4: Y4 | AB4: Y5
C5: 46162 | D5: 46295 | E5: 46387 | F5: 46477 | G5: 46568 | H5: 46660 | I5: 46752 | J5: 46843 | K5: 46934 | L5: 47026 | M5: 47118 | N5: 47208 | O5: 47299 | P5: 47391 | Q5: 47483 | R5: 47573 | S5: 47664 | T5: 47756 | U5: 47848 | V5: 47938 | W5: 48029 | X5: Annual | Y5: Annual | Z5: Annual | AA5: Annual | AB5: Annual
A6: Working Capital Drivers
A7: Accounts Receivable Days | B7: Working capital driver | C7: 0 | D7: 15 | E7: 15 | F7: 15 | G7: 15 | H7: 15 | I7: 15 | J7: 15 | K7: 15 | L7: 15 | M7: 15 | N7: 15 | O7: 15 | P7: 15 | Q7: 15 | R7: 15 | S7: 15 | T7: 15 | U7: 15 | V7: 15 | W7: 15
A8: Inventory Days | B8: Working capital driver | C8: 0 | D8: 20 | E8: 20 | F8: 20 | G8: 20 | H8: 20 | I8: 20 | J8: 20 | K8: 20 | L8: 20 | M8: 20 | N8: 20 | O8: 20 | P8: 20 | Q8: 20 | R8: 20 | S8: 20 | T8: 20 | U8: 20 | V8: 20 | W8: 20
A9: Accounts Payable Days | B9: Working capital driver | C9: 0 | D9: 30 | E9: 30 | F9: 30 | G9: 30 | H9: 30 | I9: 30 | J9: 30 | K9: 30 | L9: 30 | M9: 30 | N9: 30 | O9: 30 | P9: 30 | Q9: 30 | R9: 30 | S9: 30 | T9: 30 | U9: 30 | V9: 30 | W9: 30
A10: Prepaid Expenses (% of Revenue) | B10: Working capital driver | C10: 0 | D10: 0 | E10: 0 | F10: 0 | G10: 0 | H10: 0 | I10: 0 | J10: 0 | K10: 0 | L10: 0 | M10: 0 | N10: 0 | O10: 0 | P10: 0 | Q10: 0 | R10: 0 | S10: 0 | T10: 0 | U10: 0 | V10: 0 | W10: 0
A11: Deferred Revenue (% of Revenue) | B11: Working capital driver | C11: 0 | D11: 0 | E11: 0 | F11: 0 | G11: 0 | H11: 0 | I11: 0 | J11: 0 | K11: 0 | L11: 0 | M11: 0 | N11: 0 | O11: 0 | P11: 0 | Q11: 0 | R11: 0 | S11: 0 | T11: 0 | U11: 0 | V11: 0 | W11: 0
A12: Short Term Debt (% of LTD) | B12: Working capital driver | C12: 0 | D12: 0 | E12: 0 | F12: 0 | G12: 0 | H12: 0 | I12: 0 | J12: 0 | K12: 0 | L12: 0 | M12: 0 | N12: 0 | O12: 0 | P12: 0 | Q12: 0 | R12: 0 | S12: 0 | T12: 0 | U12: 0 | V12: 0 | W12: 0
A14: Opening Working Capital Seeds
A15: Cash Opening Balance | B15: Opening balance seed | C15: 180000 | D15: 0 | E15: 0 | F15: 0 | G15: 0 | H15: 0 | I15: 0 | J15: 0 | K15: 0 | L15: 0 | M15: 0 | N15: 0 | O15: 0 | P15: 0 | Q15: 0 | R15: 0 | S15: 0 | T15: 0 | U15: 0 | V15: 0 | W15: 0
A16: Accounts Receivable Opening Balance | B16: Opening balance seed | C16: 35000 | D16: 0 | E16: 0 | F16: 0 | G16: 0 | H16: 0 | I16: 0 | J16: 0 | K16: 0 | L16: 0 | M16: 0 | N16: 0 | O16: 0 | P16: 0 | Q16: 0 | R16: 0 | S16: 0 | T16: 0 | U16: 0 | V16: 0 | W16: 0
A17: Inventory Opening Balance | B17: Opening balance seed | C17: 85000 | D17: 0 | E17: 0 | F17: 0 | G17: 0 | H17: 0 | I17: 0 | J17: 0 | K17: 0 | L17: 0 | M17: 0 | N17: 0 | O17: 0 | P17: 0 | Q17: 0 | R17: 0 | S17: 0 | T17: 0 | U17: 0 | V17: 0 | W17: 0
A18: Accounts Payable Opening Balance | B18: Opening balance seed | C18: 70000 | D18: 0 | E18: 0 | F18: 0 | G18: 0 | H18: 0 | I18: 0 | J18: 0 | K18: 0 | L18: 0 | M18: 0 | N18: 0 | O18: 0 | P18: 0 | Q18: 0 | R18: 0 | S18: 0 | T18: 0 | U18: 0 | V18: 0 | W18: 0
A19: Short Term Debt Opening Balance | B19: Opening balance seed | C19: 0 | D19: 0 | E19: 0 | F19: 0 | G19: 0 | H19: 0 | I19: 0 | J19: 0 | K19: 0 | L19: 0 | M19: 0 | N19: 0 | O19: 0 | P19: 0 | Q19: 0 | R19: 0 | S19: 0 | T19: 0 | U19: 0 | V19: 0 | W19: 0

Sheet Cash Equity Schedule
A1: Cash & Equity Schedule
A2: Equity, distributions, lease/rent, and opening cash seeds. Model Inputs links to these rows.
C4: Stub | D4: Q1 | E4: Q2 | F4: Q3 | G4: Q4 | H4: Q5 | I4: Q6 | J4: Q7 | K4: Q8 | L4: Q9 | M4: Q10 | N4: Q11 | O4: Q12 | P4: Q13 | Q4: Q14 | R4: Q15 | S4: Q16 | T4: Q17 | U4: Q18 | V4: Q19 | W4: Q20 | X4: Y1 | Y4: Y2 | Z4: Y3 | AA4: Y4 | AB4: Y5
C5: 46162 | D5: 46295 | E5: 46387 | F5: 46477 | G5: 46568 | H5: 46660 | I5: 46752 | J5: 46843 | K5: 46934 | L5: 47026 | M5: 47118 | N5: 47208 | O5: 47299 | P5: 47391 | Q5: 47483 | R5: 47573 | S5: 47664 | T5: 47756 | U5: 47848 | V5: 47938 | W5: 48029 | X5: Annual | Y5: Annual | Z5: Annual | AA5: Annual | AB5: Annual
A6: Equity and Distributions
A7: Owner's Capital | B7: Equity / distribution input | C7: 650000 | D7: 1181676 | E7: 1301272 | F7: 1398809 | G7: 1454018 | H7: 1489178 | I7: 1503569 | J7: 1503569 | K7: 1503569 | L7: 1503569 | M7: 1503569 | N7: 1503569 | O7: 1503569 | P7: 1503569 | Q7: 1503569 | R7: 1503569 | S7: 1503569 | T7: 1503569 | U7: 1503569 | V7: 1503569 | W7: 1503569
A8: Other Equity | B8: Equity / distribution input | C8: 0 | D8: 0 | E8: 0 | F8: 0 | G8: 0 | H8: 0 | I8: 0 | J8: 0 | K8: 0 | L8: 0 | M8: 0 | N8: 0 | O8: 0 | P8: 0 | Q8: 0 | R8: 0 | S8: 0 | T8: 0 | U8: 0 | V8: 0 | W8: 0
A9: Distributions | B9: Equity / distribution input | C9: 0 | D9: 0 | E9: 0 | F9: 0 | G9: 0 | H9: 0 | I9: 0 | J9: 0 | K9: 0 | L9: 0 | M9: 0 | N9: 14883 | O9: 41137 | P9: 42830 | Q9: 58499 | R9: 122522 | S9: 134394 | T9: 136755 | U9: 144900 | V9: 149825 | W9: 162176
A11: Operating Fixed Cash Items
A12: Lease | B12: Operating lease/rent input | C12: 72000 | D12: 54000 | E12: 54000 | F12: 54000 | G12: 54000 | H12: 54000 | I12: 54000 | J12: 54000 | K12: 54000 | L12: 54000 | M12: 54000 | N12: 54000 | O12: 54000 | P12: 54000 | Q12: 54000 | R12: 54000 | S12: 54000 | T12: 54000 | U12: 54000 | V12: 54000 | W12: 54000

Sheet Model Inputs
A1: Model Inputs
A2: Formula-driven bridge from schedules into FINMO. FINMO references this sheet only.
C4: Stub | D4: Q1 | E4: Q2 | F4: Q3 | G4: Q4 | H4: Q5 | I4: Q6 | J4: Q7 | K4: Q8 | L4: Q9 | M4: Q10 | N4: Q11 | O4: Q12 | P4: Q13 | Q4: Q14 | R4: Q15 | S4: Q16 | T4: Q17 | U4: Q18 | V4: Q19 | W4: Q20 | X4: Y1 | Y4: Y2 | Z4: Y3 | AA4: Y4 | AB4: Y5
C5: 46162 | D5: 46295 | E5: 46387 | F5: 46477 | G5: 46568 | H5: 46660 | I5: 46752 | J5: 46843 | K5: 46934 | L5: 47026 | M5: 47118 | N5: 47208 | O5: 47299 | P5: 47391 | Q5: 47483 | R5: 47573 | S5: 47664 | T5: 47756 | U5: 47848 | V5: 47938 | W5: 48029 | X5: Annual | Y5: Annual | Z5: Annual | AA5: Annual | AB5: Annual
A6: Income Statement Inputs
A7: Primary line of business / Completed repair order - Capacity | B7: Revenue Drivers schedule | C7: ='Revenue Drivers'!C8 | D7: ='Revenue Drivers'!D8 | E7: ='Revenue Drivers'!E8 | F7: ='Revenue Drivers'!F8 | G7: ='Revenue Drivers'!G8 | H7: ='Revenue Drivers'!H8 | I7: ='Revenue Drivers'!I8 | J7: ='Revenue Drivers'!J8 | ... W7: ='Revenue Drivers'!W8 | X7: =SUM(D7:G7) | Y7: =SUM(H7:K7) | Z7: =SUM(L7:O7) | AA7: =SUM(P7:S7) | AB7: =SUM(T7:W7)
A8: Primary line of business / Completed repair order - Unit Price | B8: Revenue Drivers schedule | C8: ='Revenue Drivers'!C9 | D8: ='Revenue Drivers'!D9 | E8: ='Revenue Drivers'!E9 | F8: ='Revenue Drivers'!F9 | G8: ='Revenue Drivers'!G9 | H8: ='Revenue Drivers'!H9 | I8: ='Revenue Drivers'!I9 | J8: ='Revenue Drivers'!J9 | ... W8: ='Revenue Drivers'!W9 | X8: =SUM(D8:G8) | Y8: =SUM(H8:K8) | Z8: =SUM(L8:O8) | AA8: =SUM(P8:S8) | AB8: =SUM(T8:W8)
A9: Primary line of business / Completed repair order - Utilization | B9: Revenue Drivers schedule | C9: ='Revenue Drivers'!C10 | D9: ='Revenue Drivers'!D10 | E9: ='Revenue Drivers'!E10 | F9: ='Revenue Drivers'!F10 | G9: ='Revenue Drivers'!G10 | H9: ='Revenue Drivers'!H10 | I9: ='Revenue Drivers'!I10 | J9: ='Revenue Drivers'!J10 | ... W9: ='Revenue Drivers'!W10 | X9: =SUM(D9:G9) | Y9: =SUM(H9:K9) | Z9: =SUM(L9:O9) | AA9: =SUM(P9:S9) | AB9: =SUM(T9:W9)
A10: Primary line of business / Completed repair order - Revenue | B10: Revenue Drivers schedule | C10: ='Revenue Drivers'!C11 | D10: ='Revenue Drivers'!D11 | E10: ='Revenue Drivers'!E11 | F10: ='Revenue Drivers'!F11 | G10: ='Revenue Drivers'!G11 | H10: ='Revenue Drivers'!H11 | I10: ='Revenue Drivers'!I11 | J10: ='Revenue Drivers'!J11 | ... W10: ='Revenue Drivers'!W11 | X10: =SUM(D10:G10) | Y10: =SUM(H10:K10) | Z10: =SUM(L10:O10) | AA10: =SUM(P10:S10) | AB10: =SUM(T10:W10)
A11: Revenue | B11: Revenue Drivers schedule | C11: ='Revenue Drivers'!C14 | D11: ='Revenue Drivers'!D14 | E11: ='Revenue Drivers'!E14 | F11: ='Revenue Drivers'!F14 | G11: ='Revenue Drivers'!G14 | H11: ='Revenue Drivers'!H14 | I11: ='Revenue Drivers'!I14 | J11: ='Revenue Drivers'!J14 | ... W11: ='Revenue Drivers'!W14 | X11: =SUM(D11:G11) | Y11: =SUM(H11:K11) | Z11: =SUM(L11:O11) | AA11: =SUM(P11:S11) | AB11: =SUM(T11:W11)
A12: Cost of Goods Sold | B12: Direct model driver | C12: 0.34 | D12: 0.46 | E12: 0.456 | F12: 0.452 | G12: 0.448 | H12: 0.444 | I12: 0.44 | J12: 0.436 | K12: 0.432 | L12: 0.428 | M12: 0.424 | N12: 0.42 | O12: 0.41777778 | P12: 0.41555556 | Q12: 0.41333333 | R12: 0.41111111 | S12: 0.40888889 | T12: 0.40666667 | U12: 0.40444444 | V12: 0.40222222 | W12: 0.4 | X12: =SUM(D12:G12) | Y12: =SUM(H12:K12) | Z12: =SUM(L12:O12) | AA12: =SUM(P12:S12) | AB12: =SUM(T12:W12)
A13: Marketing | B13: Direct model driver | C13: 0.072 | D13: 0.21 | E13: 0.199 | F13: 0.188 | G13: 0.177 | H13: 0.166 | I13: 0.155 | J13: 0.144 | K13: 0.133 | L13: 0.122 | M13: 0.111 | N13: 0.1 | O13: 0.097777778 | P13: 0.095555556 | Q13: 0.093333333 | R13: 0.091111111 | S13: 0.088888889 | T13: 0.086666667 | U13: 0.084444444 | V13: 0.082222222 | W13: 0.08 | X13: =SUM(D13:G13) | Y13: =SUM(H13:K13) | Z13: =SUM(L13:O13) | AA13: =SUM(P13:S13) | AB13: =SUM(T13:W13)
A14: Research & Development | B14: Direct model driver | C14: 0 | D14: 0 | E14: 0 | F14: 0 | G14: 0 | H14: 0 | I14: 0 | J14: 0 | K14: 0 | L14: 0 | M14: 0 | N14: 0 | O14: 0 | P14: 0 | Q14: 0 | R14: 0 | S14: 0 | T14: 0 | U14: 0 | V14: 0 | W14: 0 | X14: =SUM(D14:G14) | Y14: =SUM(H14:K14) | Z14: =SUM(L14:O14) | AA14: =SUM(P14:S14) | AB14: =SUM(T14:W14)
A15: Lease | B15: Cash Equity Schedule output | C15: ='Cash Equity Schedule'!C12 | D15: ='Cash Equity Schedule'!D12 | E15: ='Cash Equity Schedule'!E12 | F15: ='Cash Equity Schedule'!F12 | G15: ='Cash Equity Schedule'!G12 | H15: ='Cash Equity Schedule'!H12 | I15: ='Cash Equity Schedule'!I12 | J15: ='Cash Equity Schedule'!J12 | ... W15: ='Cash Equity Schedule'!W12 | X15: =SUM(D15:G15) | Y15: =SUM(H15:K15) | Z15: =SUM(L15:O15) | AA15: =SUM(P15:S15) | AB15: =SUM(T15:W15)
A16: Payroll | B16: Payroll Schedule output | C16: 212500 | D16: ='Payroll Schedule'!D17 | E16: ='Payroll Schedule'!E17 | F16: ='Payroll Schedule'!F17 | G16: ='Payroll Schedule'!G17 | H16: ='Payroll Schedule'!H17 | I16: ='Payroll Schedule'!I17 | J16: ='Payroll Schedule'!J17 | K16: ='Payroll Schedule'!K17 | ... W16: ='Payroll Schedule'!W17 | X16: =SUM(D16:G16) | Y16: =SUM(H16:K16) | Z16: =SUM(L16:O16) | AA16: =SUM(P16:S16) | AB16: =SUM(T16:W16)
A17: General & Administrative | B17: Direct model driver | C17: 0.00507 | D17: 0.21 | E17: 0.204 | F17: 0.198 | G17: 0.192 | H17: 0.186 | I17: 0.18 | J17: 0.174 | K17: 0.168 | L17: 0.162 | M17: 0.156 | N17: 0.15 | O17: 0.14666667 | P17: 0.14333333 | Q17: 0.14 | R17: 0.13666667 | S17: 0.13333333 | T17: 0.13 | U17: 0.12666667 | V17: 0.12333333 | W17: 0.12 | X17: =SUM(D17:G17) | Y17: =SUM(H17:K17) | Z17: =SUM(L17:O17) | AA17: =SUM(P17:S17) | AB17: =SUM(T17:W17)
A18: Interest Rate | B18: Debt Schedule output | C18: ='Debt Schedule'!C12 | D18: ='Debt Schedule'!D12 | E18: ='Debt Schedule'!E12 | F18: ='Debt Schedule'!F12 | G18: ='Debt Schedule'!G12 | H18: ='Debt Schedule'!H12 | I18: ='Debt Schedule'!I12 | J18: ='Debt Schedule'!J12 | ... W18: ='Debt Schedule'!W12 | X18: =SUM(D18:G18) | Y18: =SUM(H18:K18) | Z18: =SUM(L18:O18) | AA18: =SUM(P18:S18) | AB18: =SUM(T18:W18)
A19: Interest Expense | B19: Debt Schedule output | C19: 0 | D19: ='Debt Schedule'!D13 | E19: ='Debt Schedule'!E13 | F19: ='Debt Schedule'!F13 | G19: ='Debt Schedule'!G13 | H19: ='Debt Schedule'!H13 | I19: ='Debt Schedule'!I13 | J19: ='Debt Schedule'!J13 | K19: ='Debt Schedule'!K13 | ... W19: ='Debt Schedule'!W13 | X19: =SUM(D19:G19) | Y19: =SUM(H19:K19) | Z19: =SUM(L19:O19) | AA19: =SUM(P19:S19) | AB19: =SUM(T19:W19)
A20: Depreciation | B20: CapEx Depreciation output | C20: ='CapEx Depreciation'!C10 | D20: ='CapEx Depreciation'!D10 | E20: ='CapEx Depreciation'!E10 | F20: ='CapEx Depreciation'!F10 | G20: ='CapEx Depreciation'!G10 | H20: ='CapEx Depreciation'!H10 | I20: ='CapEx Depreciation'!I10 | J20: ='CapEx Depreciation'!J10 | ... W20: ='CapEx Depreciation'!W10 | X20: =SUM(D20:G20) | Y20: =SUM(H20:K20) | Z20: =SUM(L20:O20) | AA20: =SUM(P20:S20) | AB20: =SUM(T20:W20)
A21: Depreciation Expense | B21: CapEx Depreciation output | C21: ='CapEx Depreciation'!C11 | D21: ='CapEx Depreciation'!D11 | E21: ='CapEx Depreciation'!E11 | F21: ='CapEx Depreciation'!F11 | G21: ='CapEx Depreciation'!G11 | H21: ='CapEx Depreciation'!H11 | I21: ='CapEx Depreciation'!I11 | J21: ='CapEx Depreciation'!J11 | ... W21: ='CapEx Depreciation'!W11 | X21: =SUM(D21:G21) | Y21: =SUM(H21:K21) | Z21: =SUM(L21:O21) | AA21: =SUM(P21:S21) | AB21: =SUM(T21:W21)
A22: Taxes | B22: Direct model driver | C22: 0.269425 | D22: 0.269425 | E22: 0.269425 | F22: 0.269425 | G22: 0.269425 | H22: 0.269425 | I22: 0.269425 | J22: 0.269425 | K22: 0.269425 | L22: 0.269425 | M22: 0.269425 | N22: 0.269425 | O22: 0.269425 | P22: 0.269425 | Q22: 0.269425 | R22: 0.269425 | S22: 0.269425 | T22: 0.269425 | U22: 0.269425 | V22: 0.269425 | W22: 0.269425 | X22: =SUM(D22:G22) | Y22: =SUM(H22:K22) | Z22: =SUM(L22:O22) | AA22: =SUM(P22:S22) | AB22: =SUM(T22:W22)
A24: Balance Sheet Inputs
A25: Accounts Receivable Days | B25: Working Capital schedule | C25: ='Working Capital'!C7 | D25: ='Working Capital'!D7 | E25: ='Working Capital'!E7 | F25: ='Working Capital'!F7 | G25: ='Working Capital'!G7 | H25: ='Working Capital'!H7 | I25: ='Working Capital'!I7 | J25: ='Working Capital'!J7 | ... W25: ='Working Capital'!W7 | X25: =SUM(D25:G25) | Y25: =SUM(H25:K25) | Z25: =SUM(L25:O25) | AA25: =SUM(P25:S25) | AB25: =SUM(T25:W25)
A26: Inventory Days | B26: Working Capital schedule | C26: ='Working Capital'!C8 | D26: ='Working Capital'!D8 | E26: ='Working Capital'!E8 | F26: ='Working Capital'!F8 | G26: ='Working Capital'!G8 | H26: ='Working Capital'!H8 | I26: ='Working Capital'!I8 | J26: ='Working Capital'!J8 | ... W26: ='Working Capital'!W8 | X26: =SUM(D26:G26) | Y26: =SUM(H26:K26) | Z26: =SUM(L26:O26) | AA26: =SUM(P26:S26) | AB26: =SUM(T26:W26)
A27: Accounts Payable Days | B27: Working Capital schedule | C27: ='Working Capital'!C9 | D27: ='Working Capital'!D9 | E27: ='Working Capital'!E9 | F27: ='Working Capital'!F9 | G27: ='Working Capital'!G9 | H27: ='Working Capital'!H9 | I27: ='Working Capital'!I9 | J27: ='Working Capital'!J9 | ... W27: ='Working Capital'!W9 | X27: =SUM(D27:G27) | Y27: =SUM(H27:K27) | Z27: =SUM(L27:O27) | AA27: =SUM(P27:S27) | AB27: =SUM(T27:W27)
A28: Prepaid Expenses (% of Revenue) | B28: Working Capital schedule | C28: ='Working Capital'!C10 | D28: ='Working Capital'!D10 | E28: ='Working Capital'!E10 | F28: ='Working Capital'!F10 | G28: ='Working Capital'!G10 | H28: ='Working Capital'!H10 | I28: ='Working Capital'!I10 | J28: ='Working Capital'!J10 | ... W28: ='Working Capital'!W10 | X28: =SUM(D28:G28) | Y28: =SUM(H28:K28) | Z28: =SUM(L28:O28) | AA28: =SUM(P28:S28) | AB28: =SUM(T28:W28)
A29: Deferred Revenue (% of Revenue) | B29: Working Capital schedule | C29: ='Working Capital'!C11 | D29: ='Working Capital'!D11 | E29: ='Working Capital'!E11 | F29: ='Working Capital'!F11 | G29: ='Working Capital'!G11 | H29: ='Working Capital'!H11 | I29: ='Working Capital'!I11 | J29: ='Working Capital'!J11 | ... W29: ='Working Capital'!W11 | X29: =SUM(D29:G29) | Y29: =SUM(H29:K29) | Z29: =SUM(L29:O29) | AA29: =SUM(P29:S29) | AB29: =SUM(T29:W29)
A30: Short Term Debt (% of LTD) | B30: Working Capital schedule | C30: ='Working Capital'!C12 | D30: ='Working Capital'!D12 | E30: ='Working Capital'!E12 | F30: ='Working Capital'!F12 | G30: ='Working Capital'!G12 | H30: ='Working Capital'!H12 | I30: ='Working Capital'!I12 | J30: ='Working Capital'!J12 | ... W30: ='Working Capital'!W12 | X30: =SUM(D30:G30) | Y30: =SUM(H30:K30) | Z30: =SUM(L30:O30) | AA30: =SUM(P30:S30) | AB30: =SUM(T30:W30)
A31: Owner's Capital | B31: Cash Equity Schedule schedule | C31: ='Cash Equity Schedule'!C7 | D31: ='Cash Equity Schedule'!D7 | E31: ='Cash Equity Schedule'!E7 | F31: ='Cash Equity Schedule'!F7 | G31: ='Cash Equity Schedule'!G7 | H31: ='Cash Equity Schedule'!H7 | I31: ='Cash Equity Schedule'!I7 | J31: ='Cash Equity Schedule'!J7 | ... W31: ='Cash Equity Schedule'!W7 | X31: =G31 | Y31: =K31 | Z31: =O31 | AA31: =S31 | AB31: =W31
A32: Other Equity | B32: Cash Equity Schedule schedule | C32: ='Cash Equity Schedule'!C8 | D32: ='Cash Equity Schedule'!D8 | E32: ='Cash Equity Schedule'!E8 | F32: ='Cash Equity Schedule'!F8 | G32: ='Cash Equity Schedule'!G8 | H32: ='Cash Equity Schedule'!H8 | I32: ='Cash Equity Schedule'!I8 | J32: ='Cash Equity Schedule'!J8 | ... W32: ='Cash Equity Schedule'!W8 | X32: =G32 | Y32: =K32 | Z32: =O32 | AA32: =S32 | AB32: =W32
A33: Distributions | B33: Cash Equity Schedule schedule | C33: ='Cash Equity Schedule'!C9 | D33: ='Cash Equity Schedule'!D9 | E33: ='Cash Equity Schedule'!E9 | F33: ='Cash Equity Schedule'!F9 | G33: ='Cash Equity Schedule'!G9 | H33: ='Cash Equity Schedule'!H9 | I33: ='Cash Equity Schedule'!I9 | J33: ='Cash Equity Schedule'!J9 | ... W33: ='Cash Equity Schedule'!W9 | X33: =G33 | Y33: =K33 | Z33: =O33 | AA33: =S33 | AB33: =W33
A35: Cash Flow and Schedule Inputs
A36: Cash Opening Balance | B36: Working Capital schedule | C36: ='Working Capital'!C15 | D36: ='Working Capital'!D15 | E36: ='Working Capital'!E15 | F36: ='Working Capital'!F15 | G36: ='Working Capital'!G15 | H36: ='Working Capital'!H15 | I36: ='Working Capital'!I15 | J36: ='Working Capital'!J15 | ... W36: ='Working Capital'!W15 | X36: =G36 | Y36: =K36 | Z36: =O36 | AA36: =S36 | AB36: =W36
A37: Accounts Receivable Opening Balance | B37: Working Capital schedule | C37: ='Working Capital'!C16 | D37: ='Working Capital'!D16 | E37: ='Working Capital'!E16 | F37: ='Working Capital'!F16 | G37: ='Working Capital'!G16 | H37: ='Working Capital'!H16 | I37: ='Working Capital'!I16 | J37: ='Working Capital'!J16 | ... W37: ='Working Capital'!W16 | X37: =G37 | Y37: =K37 | Z37: =O37 | AA37: =S37 | AB37: =W37
A38: Inventory Opening Balance | B38: Working Capital schedule | C38: ='Working Capital'!C17 | D38: ='Working Capital'!D17 | E38: ='Working Capital'!E17 | F38: ='Working Capital'!F17 | G38: ='Working Capital'!G17 | H38: ='Working Capital'!H17 | I38: ='Working Capital'!I17 | J38: ='Working Capital'!J17 | ... W38: ='Working Capital'!W17 | X38: =G38 | Y38: =K38 | Z38: =O38 | AA38: =S38 | AB38: =W38
A39: Accounts Payable Opening Balance | B39: Working Capital schedule | C39: ='Working Capital'!C18 | D39: ='Working Capital'!D18 | E39: ='Working Capital'!E18 | F39: ='Working Capital'!F18 | G39: ='Working Capital'!G18 | H39: ='Working Capital'!H18 | I39: ='Working Capital'!I18 | J39: ='Working Capital'!J18 | ... W39: ='Working Capital'!W18 | X39: =G39 | Y39: =K39 | Z39: =O39 | AA39: =S39 | AB39: =W39
A40: Short Term Debt Opening Balance | B40: Working Capital schedule | C40: ='Working Capital'!C19 | D40: ='Working Capital'!D19 | E40: ='Working Capital'!E19 | F40: ='Working Capital'!F19 | G40: ='Working Capital'!G19 | H40: ='Working Capital'!H19 | I40: ='Working Capital'!I19 | J40: ='Working Capital'!J19 | ... W40: ='Working Capital'!W19 | X40: =G40 | Y40: =K40 | Z40: =O40 | AA40: =S40 | AB40: =W40
A41: Debt Opening Balance | B41: Debt Schedule schedule | C41: ='Debt Schedule'!C7 | D41: ='Debt Schedule'!D7 | E41: ='Debt Schedule'!E7 | F41: ='Debt Schedule'!F7 | G41: ='Debt Schedule'!G7 | H41: ='Debt Schedule'!H7 | I41: ='Debt Schedule'!I7 | J41: ='Debt Schedule'!J7 | ... W41: ='Debt Schedule'!W7 | X41: =G41 | Y41: =K41 | Z41: =O41 | AA41: =S41 | AB41: =W41
A42: Debt Issuance | B42: Debt Schedule schedule | C42: ='Debt Schedule'!C8 | D42: ='Debt Schedule'!D8 | E42: ='Debt Schedule'!E8 | F42: ='Debt Schedule'!F8 | G42: ='Debt Schedule'!G8 | H42: ='Debt Schedule'!H8 | I42: ='Debt Schedule'!I8 | J42: ='Debt Schedule'!J8 | ... W42: ='Debt Schedule'!W8 | X42: =SUM(D42:G42) | Y42: =SUM(H42:K42) | Z42: =SUM(L42:O42) | AA42: =SUM(P42:S42) | AB42: =SUM(T42:W42)
A43: Debt Repayment | B43: Debt Schedule schedule | C43: ='Debt Schedule'!C10 | D43: ='Debt Schedule'!D10 | E43: ='Debt Schedule'!E10 | F43: ='Debt Schedule'!F10 | G43: ='Debt Schedule'!G10 | H43: ='Debt Schedule'!H10 | I43: ='Debt Schedule'!I10 | J43: ='Debt Schedule'!J10 | ... W43: ='Debt Schedule'!W10 | X43: =SUM(D43:G43) | Y43: =SUM(H43:K43) | Z43: =SUM(L43:O43) | AA43: =SUM(P43:S43) | AB43: =SUM(T43:W43)
...

Sheet FINMO
A1: FINMO
A2: Three-statement financial model. All formulas reference Model Inputs and in-sheet statement rows.
C4: Stub | D4: Q1 | E4: Q2 | F4: Q3 | G4: Q4 | H4: Q5 | I4: Q6 | J4: Q7 | K4: Q8 | L4: Q9 | M4: Q10 | N4: Q11 | O4: Q12 | P4: Q13 | Q4: Q14 | R4: Q15 | S4: Q16 | T4: Q17 | U4: Q18 | V4: Q19 | W4: Q20 | X4: Y1 | Y4: Y2 | Z4: Y3 | AA4: Y4 | AB4: Y5
C5: 46162 | D5: 46295 | E5: 46387 | F5: 46477 | G5: 46568 | H5: 46660 | I5: 46752 | J5: 46843 | K5: 46934 | L5: 47026 | M5: 47118 | N5: 47208 | O5: 47299 | P5: 47391 | Q5: 47483 | R5: 47573 | S5: 47664 | T5: 47756 | U5: 47848 | V5: 47938 | W5: 48029 | X5: Annual | Y5: Annual | Z5: Annual | AA5: Annual | AB5: Annual
A6: Days in Quarter | C6: 0 | D6: 92 | E6: 92 | F6: 90 | G6: 91 | H6: 92 | I6: 92 | J6: 91 | K6: 91 | L6: 92 | M6: 92 | N6: 90 | O6: 91 | P6: 92 | Q6: 92 | R6: 90 | S6: 91 | T6: 92 | U6: 92 | V6: 90 | W6: 91
A7: Income Statement
A8: Revenue | B8: Formula | C8: ='Model Inputs'!C11 | D8: ='Model Inputs'!D11 | E8: ='Model Inputs'!E11 | F8: ='Model Inputs'!F11 | G8: ='Model Inputs'!G11 | H8: ='Model Inputs'!H11 | I8: ='Model Inputs'!I11 | J8: ='Model Inputs'!J11 | ... W8: ='Model Inputs'!W11 | X8: =SUM(D8:G8) | Y8: =SUM(H8:K8) | Z8: =SUM(L8:O8) | AA8: =SUM(P8:S8) | AB8: =SUM(T8:W8)
A9: Cost of Goods Sold | B9: Formula | C9: =C8*'Model Inputs'!C12 | D9: =D8*'Model Inputs'!D12 | E9: =E8*'Model Inputs'!E12 | F9: =F8*'Model Inputs'!F12 | G9: =G8*'Model Inputs'!G12 | H9: =H8*'Model Inputs'!H12 | I9: =I8*'Model Inputs'!I12 | J9: =J8*'Model Inputs'!J12 | ... W9: =W8*'Model Inputs'!W12 | X9: =SUM(D9:G9) | Y9: =SUM(H9:K9) | Z9: =SUM(L9:O9) | AA9: =SUM(P9:S9) | AB9: =SUM(T9:W9)
A10: Gross Profit | B10: Formula | C10: =C8-C9 | D10: =D8-D9 | E10: =E8-E9 | F10: =F8-F9 | G10: =G8-G9 | H10: =H8-H9 | I10: =I8-I9 | J10: =J8-J9 | ... W10: =W8-W9 | X10: =SUM(D10:G10) | Y10: =SUM(H10:K10) | Z10: =SUM(L10:O10) | AA10: =SUM(P10:S10) | AB10: =SUM(T10:W10)
A11: Marketing | B11: Formula | C11: =C8*'Model Inputs'!C13 | D11: =D8*'Model Inputs'!D13 | E11: =E8*'Model Inputs'!E13 | F11: =F8*'Model Inputs'!F13 | G11: =G8*'Model Inputs'!G13 | H11: =H8*'Model Inputs'!H13 | I11: =I8*'Model Inputs'!I13 | J11: =J8*'Model Inputs'!J13 | ... W11: =W8*'Model Inputs'!W13 | X11: =SUM(D11:G11) | Y11: =SUM(H11:K11) | Z11: =SUM(L11:O11) | AA11: =SUM(P11:S11) | AB11: =SUM(T11:W11)
A12: Research & Development | B12: Formula | C12: =C8*'Model Inputs'!C14 | D12: =D8*'Model Inputs'!D14 | E12: =E8*'Model Inputs'!E14 | F12: =F8*'Model Inputs'!F14 | G12: =G8*'Model Inputs'!G14 | H12: =H8*'Model Inputs'!H14 | I12: =I8*'Model Inputs'!I14 | J12: =J8*'Model Inputs'!J14 | ... W12: =W8*'Model Inputs'!W14 | X12: =SUM(D12:G12) | Y12: =SUM(H12:K12) | Z12: =SUM(L12:O12) | AA12: =SUM(P12:S12) | AB12: =SUM(T12:W12)
A13: Lease/Rent | B13: Formula | C13: ='Model Inputs'!C15 | D13: ='Model Inputs'!D15 | E13: ='Model Inputs'!E15 | F13: ='Model Inputs'!F15 | G13: ='Model Inputs'!G15 | H13: ='Model Inputs'!H15 | I13: ='Model Inputs'!I15 | J13: ='Model Inputs'!J15 | ... W13: ='Model Inputs'!W15 | X13: =SUM(D13:G13) | Y13: =SUM(H13:K13) | Z13: =SUM(L13:O13) | AA13: =SUM(P13:S13) | AB13: =SUM(T13:W13)
A14: Payroll | B14: Formula | C14: ='Model Inputs'!C16 | D14: ='Model Inputs'!D16 | E14: ='Model Inputs'!E16 | F14: ='Model Inputs'!F16 | G14: ='Model Inputs'!G16 | H14: ='Model Inputs'!H16 | I14: ='Model Inputs'!I16 | J14: ='Model Inputs'!J16 | ... W14: ='Model Inputs'!W16 | X14: =SUM(D14:G14) | Y14: =SUM(H14:K14) | Z14: =SUM(L14:O14) | AA14: =SUM(P14:S14) | AB14: =SUM(T14:W14)
A15: General & Administrative | B15: Formula | C15: =C8*'Model Inputs'!C17 | D15: =D8*'Model Inputs'!D17 | E15: =E8*'Model Inputs'!E17 | F15: =F8*'Model Inputs'!F17 | G15: =G8*'Model Inputs'!G17 | H15: =H8*'Model Inputs'!H17 | I15: =I8*'Model Inputs'!I17 | J15: =J8*'Model Inputs'!J17 | ... W15: =W8*'Model Inputs'!W17 | X15: =SUM(D15:G15) | Y15: =SUM(H15:K15) | Z15: =SUM(L15:O15) | AA15: =SUM(P15:S15) | AB15: =SUM(T15:W15)
A16: EBITDA | B16: Formula | C16: =C10-SUM(C11:C15) | D16: =D10-SUM(D11:D15) | E16: =E10-SUM(E11:E15) | F16: =F10-SUM(F11:F15) | G16: =G10-SUM(G11:G15) | H16: =H10-SUM(H11:H15) | I16: =I10-SUM(I11:I15) | J16: =J10-SUM(J11:J15) | ... W16: =W10-SUM(W11:W15) | X16: =SUM(D16:G16) | Y16: =SUM(H16:K16) | Z16: =SUM(L16:O16) | AA16: =SUM(P16:S16) | AB16: =SUM(T16:W16)
A17: Interest | B17: Formula | C17: ='Model Inputs'!C19+'Model Inputs'!C48 | D17: ='Model Inputs'!D19+'Model Inputs'!D48 | E17: ='Model Inputs'!E19+'Model Inputs'!E48 | F17: ='Model Inputs'!F19+'Model Inputs'!F48 | G17: ='Model Inputs'!G19+'Model Inputs'!G48 | H17: ='Model Inputs'!H19+'Model Inputs'!H48 | I17: ='Model Inputs'!I19+'Model Inputs'!I48 | J17: ='Model Inputs'!J19+'Model Inputs'!J48 | ... W17: ='Model Inputs'!W19+'Model Inputs'!W48 | X17: =SUM(D17:G17) | Y17: =SUM(H17:K17) | Z17: =SUM(L17:O17) | AA17: =SUM(P17:S17) | AB17: =SUM(T17:W17)
A18: Depreciation | B18: Formula | C18: ='Model Inputs'!C21+'Model Inputs'!C51 | D18: ='Model Inputs'!D21+'Model Inputs'!D51 | E18: ='Model Inputs'!E21+'Model Inputs'!E51 | F18: ='Model Inputs'!F21+'Model Inputs'!F51 | G18: ='Model Inputs'!G21+'Model Inputs'!G51 | H18: ='Model Inputs'!H21+'Model Inputs'!H51 | I18: ='Model Inputs'!I21+'Model Inputs'!I51 | J18: ='Model Inputs'!J21+'Model Inputs'!J51 | ... W18: ='Model Inputs'!W21+'Model Inputs'!W51 | X18: =SUM(D18:G18) | Y18: =SUM(H18:K18) | Z18: =SUM(L18:O18) | AA18: =SUM(P18:S18) | AB18: =SUM(T18:W18)
A19: Taxes | B19: Formula | C19: =MAX(0,C16-C17-C18)*'Model Inputs'!C22 | D19: =MAX(0,D16-D17-D18)*'Model Inputs'!D22 | E19: =MAX(0,E16-E17-E18)*'Model Inputs'!E22 | F19: =MAX(0,F16-F17-F18)*'Model Inputs'!F22 | G19: =MAX(0,G16-G17-G18)*'Model Inputs'!G22 | H19: =MAX(0,H16-H17-H18)*'Model Inputs'!H22 | I19: =MAX(0,I16-I17-I18)*'Model Inputs'!I22 | J19: =MAX(0,J16-J17-J18)*'Model Inputs'!J22 | ... W19: =MAX(0,W16-W17-W18)*'Model Inputs'!W22 | X19: =SUM(D19:G19) | Y19: =SUM(H19:K19) | Z19: =SUM(L19:O19) | AA19: =SUM(P19:S19) | AB19: =SUM(T19:W19)
A20: Net Income | B20: Formula | C20: =C16-SUM(C17:C19) | D20: =D16-SUM(D17:D19) | E20: =E16-SUM(E17:E19) | F20: =F16-SUM(F17:F19) | G20: =G16-SUM(G17:G19) | H20: =H16-SUM(H17:H19) | I20: =I16-SUM(I17:I19) | J20: =J16-SUM(J17:J19) | ... W20: =W16-SUM(W17:W19) | X20: =SUM(D20:G20) | Y20: =SUM(H20:K20) | Z20: =SUM(L20:O20) | AA20: =SUM(P20:S20) | AB20: =SUM(T20:W20)
A22: Balance Sheet
A23: Cash | B23: Formula | C23: =C61 | D23: =D61 | E23: =E61 | F23: =F61 | G23: =G61 | H23: =H61 | I23: =I61 | J23: =J61 | ... W23: =W61 | X23: =G23 | Y23: =K23 | Z23: =O23 | AA23: =S23 | AB23: =W23
A24: Accounts Receivable | B24: Formula | C24: ='Model Inputs'!C37 | D24: =('Model Inputs'!D25/D6)*D8 | E24: =('Model Inputs'!E25/E6)*E8 | F24: =('Model Inputs'!F25/F6)*F8 | G24: =('Model Inputs'!G25/G6)*G8 | H24: =('Model Inputs'!H25/H6)*H8 | I24: =('Model Inputs'!I25/I6)*I8 | J24: =('Model Inputs'!J25/J6)*J8 | K24: =('Model Inputs'!K25/K6)*K8 | ... W24: =('Model Inputs'!W25/W6)*W8 | X24: =G24 | Y24: =K24 | Z24: =O24 | AA24: =S24 | AB24: =W24
A25: Inventory | B25: Formula | C25: ='Model Inputs'!C38 | D25: =('Model Inputs'!D26/D6)*D9 | E25: =('Model Inputs'!E26/E6)*E9 | F25: =('Model Inputs'!F26/F6)*F9 | G25: =('Model Inputs'!G26/G6)*G9 | H25: =('Model Inputs'!H26/H6)*H9 | I25: =('Model Inputs'!I26/I6)*I9 | J25: =('Model Inputs'!J26/J6)*J9 | K25: =('Model Inputs'!K26/K6)*K9 | ... W25: =('Model Inputs'!W26/W6)*W9 | X25: =G25 | Y25: =K25 | Z25: =O25 | AA25: =S25 | AB25: =W25
A26: Prepaid Expenses | B26: Formula | C26: =0 | D26: =D8*'Model Inputs'!D28 | E26: =E8*'Model Inputs'!E28 | F26: =F8*'Model Inputs'!F28 | G26: =G8*'Model Inputs'!G28 | H26: =H8*'Model Inputs'!H28 | I26: =I8*'Model Inputs'!I28 | J26: =J8*'Model Inputs'!J28 | K26: =K8*'Model Inputs'!K28 | ... W26: =W8*'Model Inputs'!W28 | X26: =G26 | Y26: =K26 | Z26: =O26 | AA26: =S26 | AB26: =W26
A27: Current Assets | B27: Formula | C27: =SUM(C23:C26) | D27: =SUM(D23:D26) | E27: =SUM(E23:E26) | F27: =SUM(F23:F26) | G27: =SUM(G23:G26) | H27: =SUM(H23:H26) | I27: =SUM(I23:I26) | J27: =SUM(J23:J26) | ... W27: =SUM(W23:W26) | X27: =G27 | Y27: =K27 | Z27: =O27 | AA27: =S27 | AB27: =W27
A28: PPE | B28: Formula | C28: ='Model Inputs'!C53 | D28: ='Model Inputs'!D53 | E28: ='Model Inputs'!E53 | F28: ='Model Inputs'!F53 | G28: ='Model Inputs'!G53 | H28: ='Model Inputs'!H53 | I28: ='Model Inputs'!I53 | J28: ='Model Inputs'!J53 | ... W28: ='Model Inputs'!W53 | X28: =G28 | Y28: =K28 | Z28: =O28 | AA28: =S28 | AB28: =W28
A29: Right-of-Use Asset (Capital Lease) | B29: Formula | C29: ='Model Inputs'!C50 | D29: ='Model Inputs'!D50 | E29: ='Model Inputs'!E50 | F29: ='Model Inputs'!F50 | G29: ='Model Inputs'!G50 | H29: ='Model Inputs'!H50 | I29: ='Model Inputs'!I50 | J29: ='Model Inputs'!J50 | ... W29: ='Model Inputs'!W50 | X29: =G29 | Y29: =K29 | Z29: =O29 | AA29: =S29 | AB29: =W29
A30: Accumulated Depreciation | B30: Formula | C30: ='Model Inputs'!C54 | D30: ='Model Inputs'!D54 | E30: ='Model Inputs'!E54 | F30: ='Model Inputs'!F54 | G30: ='Model Inputs'!G54 | H30: ='Model Inputs'!H54 | I30: ='Model Inputs'!I54 | J30: ='Model Inputs'!J54 | ... W30: ='Model Inputs'!W54 | X30: =G30 | Y30: =K30 | Z30: =O30 | AA30: =S30 | AB30: =W30
A31: Total Assets | B31: Formula | C31: =C27+C28+C29 | D31: =D27+D28+D29 | E31: =E27+E28+E29 | F31: =F27+F28+F29 | G31: =G27+G28+G29 | H31: =H27+H28+H29 | I31: =I27+I28+I29 | J31: =J27+J28+J29 | ... W31: =W27+W28+W29 | X31: =G31 | Y31: =K31 | Z31: =O31 | AA31: =S31 | AB31: =W31
A32: Accounts Payable | B32: Formula | C32: ='Model Inputs'!C39 | D32: =('Model Inputs'!D27/D6)*SUM(D11:D15) | E32: =('Model Inputs'!E27/E6)*SUM(E11:E15) | F32: =('Model Inputs'!F27/F6)*SUM(F11:F15) | G32: =('Model Inputs'!G27/G6)*SUM(G11:G15) | H32: =('Model Inputs'!H27/H6)*SUM(H11:H15) | I32: =('Model Inputs'!I27/I6)*SUM(I11:I15) | J32: =('Model Inputs'!J27/J6)*SUM(J11:J15) | K32: =('Model Inputs'!K27/K6)*SUM(K11:K15) | ... W32: =('Model Inputs'!W27/W6)*SUM(W11:W15) | X32: =G32 | Y32: =K32 | Z32: =O32 | AA32: =S32 | AB32: =W32
