Workbook

Sheet Revenue Drivers
A1: Revenue Drivers
A2: Source operating drivers. Model Inputs links to these rows.
C4: Stub | D4: Q1 | E4: Q2 | F4: Q3 | G4: Q4 | H4: Q5 | I4: Q6 | J4: Q7 | K4: Q8 | L4: Q9 | M4: Q10 | N4: Q11 | O4: Q12 | P4: Q13 | Q4: Q14 | R4: Q15 | S4: Q16 | T4: Q17 | U4: Q18 | V4: Q19 | W4: Q20 | X4: Y1 | Y4: Y2 | Z4: Y3 | AA4: Y4 | AB4: Y5
C5: 46162 | D5: 46295 | E5: 46387 | F5: 46477 | G5: 46568 | H5: 46660 | I5: 46752 | J5: 46843 | K5: 46934 | L5: 47026 | M5: 47118 | N5: 47208 | O5: 47299 | P5: 47391 | Q5: 47483 | R5: 47573 | S5: 47664 | T5: 47756 | U5: 47848 | V5: 47938 | W5: 48029 | X5: Annual | Y5: Annual | Z5: Annual | AA5: Annual | AB5: Annual
A6: Revenue Driver Source Rows
A7: Primary line of business / Individual IV session
A8: Primary line of business / Individual IV session - Capacity | B8: Source driver | C8: 260 | D8: 293.49069 | E8: 293.49069 | F8: 293.49069 | G8: 293.49069 | H8: 293.49069 | I8: 293.49069 | J8: 293.49069 | K8: 293.49069 | L8: 293.49069 | M8: 293.49069 | N8: 293.49069 | O8: 293.49069 | P8: 293.49069 | Q8: 293.49069 | R8: 293.49069 | S8: 293.49069 | T8: 293.49069 | U8: 293.49069 | V8: 293.49069 | W8: 308.16522
A9: Primary line of business / Individual IV session - Unit Price | B9: Source driver | C9: 150 | D9: 150 | E9: 154 | F9: 158 | G9: 162 | H9: 166 | I9: 170 | J9: 174 | K9: 178 | L9: 182 | M9: 186 | N9: 190 | O9: 192.22222 | P9: 194.44444 | Q9: 196.66667 | R9: 198.88889 | S9: 201.11111 | T9: 203.33333 | U9: 205.55556 | V9: 207.77778 | W9: 210
A10: Primary line of business / Individual IV session - Utilization | B10: Source driver | C10: 0.7 | D10: 0.7 | E10: 0.714 | F10: 0.728 | G10: 0.742 | H10: 0.756 | I10: 0.77 | J10: 0.784 | K10: 0.798 | L10: 0.812 | M10: 0.826 | N10: 0.84 | O10: 0.84 | P10: 0.84 | Q10: 0.84 | R10: 0.84 | S10: 0.84 | T10: 0.84 | U10: 0.84 | V10: 0.84 | W10: 0.84
A11: Primary line of business / Individual IV session - Revenue | B11: Capacity x Unit Price x Utilization | C11: =C8*C9*C10 | D11: =D8*D9*D10 | E11: =E8*E9*E10 | F11: =F8*F9*F10 | G11: =G8*G9*G10 | H11: =H8*H9*H10 | I11: =I8*I9*I10 | J11: =J8*J9*J10 | ... W11: =W8*W9*W10 | X11: =SUM(D11:G11) | Y11: =SUM(H11:K11) | Z11: =SUM(L11:O11) | AA11: =SUM(P11:S11) | AB11: =SUM(T11:W11)
A13: Primary line of business / Monthly IV membership
A14: Primary line of business / Monthly IV membership - Capacity | B14: Source driver | C14: 60 | D14: 67.728621 | E14: 67.728621 | F14: 67.728621 | G14: 67.728621 | H14: 67.728621 | I14: 67.728621 | J14: 67.728621 | K14: 67.728621 | L14: 67.728621 | M14: 67.728621 | N14: 67.728621 | O14: 67.728621 | P14: 67.728621 | Q14: 67.728621 | R14: 67.728621 | S14: 67.728621 | T14: 67.728621 | U14: 67.728621 | V14: 67.728621 | W14: 71.115052
A15: Primary line of business / Monthly IV membership - Unit Price | B15: Source driver | C15: 400 | D15: 150 | E15: 154 | F15: 158 | G15: 162 | H15: 166 | I15: 170 | J15: 174 | K15: 178 | L15: 182 | M15: 186 | N15: 190 | O15: 192.22222 | P15: 194.44444 | Q15: 196.66667 | R15: 198.88889 | S15: 201.11111 | T15: 203.33333 | U15: 205.55556 | V15: 207.77778 | W15: 210
A16: Primary line of business / Monthly IV membership - Utilization | B16: Source driver | C16: 0.5 | D16: 0.7 | E16: 0.714 | F16: 0.728 | G16: 0.742 | H16: 0.756 | I16: 0.77 | J16: 0.784 | K16: 0.798 | L16: 0.812 | M16: 0.826 | N16: 0.84 | O16: 0.84 | P16: 0.84 | Q16: 0.84 | R16: 0.84 | S16: 0.84 | T16: 0.84 | U16: 0.84 | V16: 0.84 | W16: 0.84
A17: Primary line of business / Monthly IV membership - Revenue | B17: Capacity x Unit Price x Utilization | C17: =C14*C15*C16 | D17: =D14*D15*D16 | E17: =E14*E15*E16 | F17: =F14*F15*F16 | G17: =G14*G15*G16 | H17: =H14*H15*H16 | I17: =I14*I15*I16 | J17: =J14*J15*J16 | ... W17: =W14*W15*W16 | X17: =SUM(D17:G17) | Y17: =SUM(H17:K17) | Z17: =SUM(L17:O17) | AA17: =SUM(P17:S17) | AB17: =SUM(T17:W17)
A19: Primary line of business / Retail wellness products
A20: Primary line of business / Retail wellness products - Capacity | B20: Source driver | C20: 260 | D20: 293.49069 | E20: 293.49069 | F20: 293.49069 | G20: 293.49069 | H20: 293.49069 | I20: 293.49069 | J20: 293.49069 | K20: 293.49069 | L20: 293.49069 | M20: 293.49069 | N20: 293.49069 | O20: 293.49069 | P20: 293.49069 | Q20: 293.49069 | R20: 293.49069 | S20: 293.49069 | T20: 293.49069 | U20: 293.49069 | V20: 293.49069 | W20: 308.16522
A21: Primary line of business / Retail wellness products - Unit Price | B21: Source driver | C21: 20 | D21: 150 | E21: 154 | F21: 158 | G21: 162 | H21: 166 | I21: 170 | J21: 174 | K21: 178 | L21: 182 | M21: 186 | N21: 190 | O21: 192.22222 | P21: 194.44444 | Q21: 196.66667 | R21: 198.88889 | S21: 201.11111 | T21: 203.33333 | U21: 205.55556 | V21: 207.77778 | W21: 210
A22: Primary line of business / Retail wellness products - Utilization | B22: Source driver | C22: 0 | D22: 0.7 | E22: 0.714 | F22: 0.728 | G22: 0.742 | H22: 0.756 | I22: 0.77 | J22: 0.784 | K22: 0.798 | L22: 0.812 | M22: 0.826 | N22: 0.84 | O22: 0.84 | P22: 0.84 | Q22: 0.84 | R22: 0.84 | S22: 0.84 | T22: 0.84 | U22: 0.84 | V22: 0.84 | W22: 0.84
A23: Primary line of business / Retail wellness products - Revenue | B23: Capacity x Unit Price x Utilization | C23: =C20*C21*C22 | D23: =D20*D21*D22 | E23: =E20*E21*E22 | F23: =F20*F21*F22 | G23: =G20*G21*G22 | H23: =H20*H21*H22 | I23: =I20*I21*I22 | J23: =J20*J21*J22 | ... W23: =W20*W21*W22 | X23: =SUM(D23:G23) | Y23: =SUM(H23:K23) | Z23: =SUM(L23:O23) | AA23: =SUM(P23:S23) | AB23: =SUM(T23:W23)
A25: Total Capacity Units | B25: All revenue driver capacity units | C25: =SUM(C8,C14,C20) | D25: =SUM(D8,D14,D20) | E25: =SUM(E8,E14,E20) | F25: =SUM(F8,F14,F20) | G25: =SUM(G8,G14,G20) | H25: =SUM(H8,H14,H20) | I25: =SUM(I8,I14,I20) | J25: =SUM(J8,J14,J20) | ... W25: =SUM(W8,W14,W20) | X25: =SUM(D25:G25) | Y25: =SUM(H25:K25) | Z25: =SUM(L25:O25) | AA25: =SUM(P25:S25) | AB25: =SUM(T25:W25)
A26: Total Revenue | B26: All revenue products | C26: =SUM(C11,C17,C23) | D26: =SUM(D11,D17,D23) | E26: =SUM(E11,E17,E23) | F26: =SUM(F11,F17,F23) | G26: =SUM(G11,G17,G23) | H26: =SUM(H11,H17,H23) | I26: =SUM(I11,I17,I23) | J26: =SUM(J11,J17,J23) | ... W26: =SUM(W11,W17,W23) | X26: =SUM(D26:G26) | Y26: =SUM(H26:K26) | Z26: =SUM(L26:O26) | AA26: =SUM(P26:S26) | AB26: =SUM(T26:W26)
A28: Stage Ramp Contract
A29: Actual Revenue QoQ Growth | B29: Total revenue growth from modeled revenue drivers | C29: =0 | D29: =IFERROR(D26/C26-1,0) | E29: =IFERROR(E26/D26-1,0) | F29: =IFERROR(F26/E26-1,0) | G29: =IFERROR(G26/F26-1,0) | H29: =IFERROR(H26/G26-1,0) | I29: =IFERROR(I26/H26-1,0) | J29: =IFERROR(J26/I26-1,0) | K29: =IFERROR(K26/J26-1,0) | ... W29: =IFERROR(W26/V26-1,0) | X29: =AVERAGE(D29:G29) | Y29: =AVERAGE(H29:K29) | Z29: =AVERAGE(L29:O29) | AA29: =AVERAGE(P29:S29) | AB29: =AVERAGE(T29:W29)
A30: Stage Ramp Revenue QoQ Target | B30: GPT-selected stage ramp contract | C30: 0 | D30: 0.02 | E30: 0.02 | F30: 0.02 | G30: 0.02 | H30: 0.02 | I30: 0.02 | J30: 0.02 | K30: 0.02 | L30: 0.02 | M30: 0.02 | N30: 0.02 | O30: 0.02 | P30: 0.02 | Q30: 0.02 | R30: 0.02 | S30: 0.02 | T30: 0.02 | U30: 0.02 | V30: 0.02 | W30: 0.02 | X30: =AVERAGE(D30:G30) | Y30: =AVERAGE(H30:K30) | Z30: =AVERAGE(L30:O30) | AA30: =AVERAGE(P30:S30) | AB30: =AVERAGE(T30:W30)
A31: Stage Ramp Revenue QoQ Max | B31: GPT-selected stage ramp contract | C31: 0 | D31: 0.07 | E31: 0.07 | F31: 0.07 | G31: 0.07 | H31: 0.07 | I31: 0.07 | J31: 0.07 | K31: 0.07 | L31: 0.07 | M31: 0.07 | N31: 0.07 | O31: 0.07 | P31: 0.07 | Q31: 0.07 | R31: 0.07 | S31: 0.07 | T31: 0.07 | U31: 0.07 | V31: 0.07 | W31: 0.07 | X31: =AVERAGE(D31:G31) | Y31: =AVERAGE(H31:K31) | Z31: =AVERAGE(L31:O31) | AA31: =AVERAGE(P31:S31) | AB31: =AVERAGE(T31:W31)
A32: Stage Ramp Revenue QoQ Spike Max | B32: GPT-selected stage ramp contract | C32: 0 | D32: 0.07 | E32: 0.07 | F32: 0.07 | G32: 0.07 | H32: 0.07 | I32: 0.07 | J32: 0.07 | K32: 0.07 | L32: 0.07 | M32: 0.07 | N32: 0.07 | O32: 0.07 | P32: 0.07 | Q32: 0.07 | R32: 0.07 | S32: 0.07 | T32: 0.07 | U32: 0.07 | V32: 0.07 | W32: 0.07 | X32: =AVERAGE(D32:G32) | Y32: =AVERAGE(H32:K32) | Z32: =AVERAGE(L32:O32) | AA32: =AVERAGE(P32:S32) | AB32: =AVERAGE(T32:W32)
A33: Stage Ramp Utilization Cap | B33: GPT-selected stage ramp contract | C33: 0 | D33: 0.65 | E33: 0.67 | F33: 0.69 | G33: 0.71 | H33: 0.73 | I33: 0.75 | J33: 0.77 | K33: 0.79 | L33: 0.81 | M33: 0.83 | N33: 0.85 | O33: 0.85 | P33: 0.85 | Q33: 0.85 | R33: 0.85 | S33: 0.85 | T33: 0.85 | U33: 0.85 | V33: 0.85 | W33: 0.85 | X33: =AVERAGE(D33:G33) | Y33: =AVERAGE(H33:K33) | Z33: =AVERAGE(L33:O33) | AA33: =AVERAGE(P33:S33) | AB33: =AVERAGE(T33:W33)
A34: Stage Ramp COGS % Revenue Target | B34: GPT-selected stage ramp contract | C34: 0 | D34: 0.47 | E34: 0.47 | F34: 0.47 | G34: 0.47 | H34: 0.47 | I34: 0.47 | J34: 0.47 | K34: 0.47 | L34: 0.47 | M34: 0.47 | N34: 0.47 | O34: 0.47 | P34: 0.47 | Q34: 0.47 | R34: 0.47 | S34: 0.47 | T34: 0.47 | U34: 0.47 | V34: 0.47 | W34: 0.47 | X34: =AVERAGE(D34:G34) | Y34: =AVERAGE(H34:K34) | Z34: =AVERAGE(L34:O34) | AA34: =AVERAGE(P34:S34) | AB34: =AVERAGE(T34:W34)
A35: Stage Ramp COGS % Revenue Max | B35: GPT-selected stage ramp contract | C35: 0 | D35: 0.69 | E35: 0.69 | F35: 0.69 | G35: 0.69 | H35: 0.69 | I35: 0.69 | J35: 0.69 | K35: 0.69 | L35: 0.69 | M35: 0.69 | N35: 0.69 | O35: 0.69 | P35: 0.69 | Q35: 0.69 | R35: 0.69 | S35: 0.69 | T35: 0.69 | U35: 0.69 | V35: 0.69 | W35: 0.69 | X35: =AVERAGE(D35:G35) | Y35: =AVERAGE(H35:K35) | Z35: =AVERAGE(L35:O35) | AA35: =AVERAGE(P35:S35) | AB35: =AVERAGE(T35:W35)
A36: Stage Ramp Marketing % Revenue Max | B36: GPT-selected stage ramp contract | C36: 0 | D36: 0.38 | E36: 0.38 | F36: 0.38 | G36: 0.38 | H36: 0.38 | I36: 0.38 | J36: 0.38 | K36: 0.38 | L36: 0.38 | M36: 0.38 | N36: 0.38 | O36: 0.38 | P36: 0.38 | Q36: 0.38 | R36: 0.38 | S36: 0.38 | T36: 0.38 | U36: 0.38 | V36: 0.38 | W36: 0.38 | X36: =AVERAGE(D36:G36) | Y36: =AVERAGE(H36:K36) | Z36: =AVERAGE(L36:O36) | AA36: =AVERAGE(P36:S36) | AB36: =AVERAGE(T36:W36)
A37: Stage Ramp R&D % Revenue Max | B37: GPT-selected stage ramp contract | C37: 0 | D37: 0.25 | E37: 0.25 | F37: 0.25 | G37: 0.25 | H37: 0.25 | I37: 0.25 | J37: 0.25 | K37: 0.25 | L37: 0.25 | M37: 0.25 | N37: 0.25 | O37: 0.25 | P37: 0.25 | Q37: 0.25 | R37: 0.25 | S37: 0.25 | T37: 0.25 | U37: 0.25 | V37: 0.25 | W37: 0.25 | X37: =AVERAGE(D37:G37) | Y37: =AVERAGE(H37:K37) | Z37: =AVERAGE(L37:O37) | AA37: =AVERAGE(P37:S37) | AB37: =AVERAGE(T37:W37)
A38: Stage Ramp G&A % Revenue Max | B38: GPT-selected stage ramp contract | C38: 0 | D38: 0.38 | E38: 0.38 | F38: 0.38 | G38: 0.38 | H38: 0.38 | I38: 0.38 | J38: 0.38 | K38: 0.38 | L38: 0.38 | M38: 0.38 | N38: 0.38 | O38: 0.38 | P38: 0.38 | Q38: 0.38 | R38: 0.38 | S38: 0.38 | T38: 0.38 | U38: 0.38 | V38: 0.38 | W38: 0.38 | X38: =AVERAGE(D38:G38) | Y38: =AVERAGE(H38:K38) | Z38: =AVERAGE(L38:O38) | AA38: =AVERAGE(P38:S38) | AB38: =AVERAGE(T38:W38)
A39: Stage Ramp Lease % Revenue Max | B39: GPT-selected stage ramp contract | C39: 0 | D39: 0.04 | E39: 0.04 | F39: 0.04 | G39: 0.04 | H39: 0.04 | I39: 0.04 | J39: 0.04 | K39: 0.04 | L39: 0.04 | M39: 0.04 | N39: 0.04 | O39: 0.04 | P39: 0.04 | Q39: 0.04 | R39: 0.04 | S39: 0.04 | T39: 0.04 | U39: 0.04 | V39: 0.04 | W39: 0.04 | X39: =AVERAGE(D39:G39) | Y39: =AVERAGE(H39:K39) | Z39: =AVERAGE(L39:O39) | AA39: =AVERAGE(P39:S39) | AB39: =AVERAGE(T39:W39)
A40: Stage Ramp Net Income Margin Floor | B40: GPT-selected stage ramp contract | C40: 0 | D40: 0 | E40: 0 | F40: 0 | G40: 0 | H40: 0.02 | I40: 0.02 | J40: 0.02 | K40: 0.02 | L40: 0.02 | M40: 0.02 | N40: 0.02 | O40: 0.02 | P40: 0.02 | Q40: 0.02 | R40: 0.02 | S40: 0.02 | T40: 0.02 | U40: 0.02 | V40: 0.02 | W40: 0.02 | X40: =AVERAGE(D40:G40) | Y40: =AVERAGE(H40:K40) | Z40: =AVERAGE(L40:O40) | AA40: =AVERAGE(P40:S40) | AB40: =AVERAGE(T40:W40)

Sheet Payroll Schedule
A1: Payroll Schedule
A2: OEWS-title, capacity/utilization-driven payroll source. Model Inputs links to Total Payroll.
C4: Stub | D4: Q1 | E4: Q2 | F4: Q3 | G4: Q4 | H4: Q5 | I4: Q6 | J4: Q7 | K4: Q8 | L4: Q9 | M4: Q10 | N4: Q11 | O4: Q12 | P4: Q13 | Q4: Q14 | R4: Q15 | S4: Q16 | T4: Q17 | U4: Q18 | V4: Q19 | W4: Q20 | X4: Y1 | Y4: Y2 | Z4: Y3 | AA4: Y4 | AB4: Y5
C5: 46162 | D5: 46295 | E5: 46387 | F5: 46477 | G5: 46568 | H5: 46660 | I5: 46752 | J5: 46843 | K5: 46934 | L5: 47026 | M5: 47118 | N5: 47208 | O5: 47299 | P5: 47391 | Q5: 47483 | R5: 47573 | S5: 47664 | T5: 47756 | U5: 47848 | V5: 47938 | W5: 48029 | X5: Annual | Y5: Annual | Z5: Annual | AA5: Annual | AB5: Annual
A6: Payroll Assumptions
A7: Capacity Labor Model | B7: labor_driven
A8: Labor Intensity Class | B8: high
A9: Wage Positioning Tier | B9: floor
A10: Wage Positioning Multiplier | B10: 1.05
A11: Capacity Units per Supporting FTE | B11: 654.71
A12: Target Payroll % of Revenue | B12: 0.4
A14: Quarter Summary
A15: Total Ending FTE | B15: Formula output from payroll detail | C15: =SUMIFS($G$27:$G$66,$A$27:$A$66,0) | D15: =SUMIFS($G$27:$G$66,$A$27:$A$66,1) | E15: =SUMIFS($G$27:$G$66,$A$27:$A$66,2) | F15: =SUMIFS($G$27:$G$66,$A$27:$A$66,3) | G15: =SUMIFS($G$27:$G$66,$A$27:$A$66,4) | H15: =SUMIFS($G$27:$G$66,$A$27:$A$66,5) | I15: =SUMIFS($G$27:$G$66,$A$27:$A$66,6) | J15: =SUMIFS($G$27:$G$66,$A$27:$A$66,7) | K15: =SUMIFS($G$27:$G$66,$A$27:$A$66,8) | L15: =SUMIFS($G$27:$G$66,$A$27:$A$66,9) | M15: =SUMIFS($G$27:$G$66,$A$27:$A$66,10) | N15: =SUMIFS($G$27:$G$66,$A$27:$A$66,11) | O15: =SUMIFS($G$27:$G$66,$A$27:$A$66,12) | P15: =SUMIFS($G$27:$G$66,$A$27:$A$66,13) | Q15: =SUMIFS($G$27:$G$66,$A$27:$A$66,14) | R15: =SUMIFS($G$27:$G$66,$A$27:$A$66,15) | S15: =SUMIFS($G$27:$G$66,$A$27:$A$66,16) | T15: =SUMIFS($G$27:$G$66,$A$27:$A$66,17) | U15: =SUMIFS($G$27:$G$66,$A$27:$A$66,18) | V15: =SUMIFS($G$27:$G$66,$A$27:$A$66,19) | W15: =SUMIFS($G$27:$G$66,$A$27:$A$66,20) | X15: =G15 | Y15: =K15 | Z15: =O15 | AA15: =S15 | AB15: =W15
A16: Total Average FTE | B16: Formula output from payroll detail | C16: =SUMIFS($H$27:$H$66,$A$27:$A$66,0) | D16: =SUMIFS($H$27:$H$66,$A$27:$A$66,1) | E16: =SUMIFS($H$27:$H$66,$A$27:$A$66,2) | F16: =SUMIFS($H$27:$H$66,$A$27:$A$66,3) | G16: =SUMIFS($H$27:$H$66,$A$27:$A$66,4) | H16: =SUMIFS($H$27:$H$66,$A$27:$A$66,5) | I16: =SUMIFS($H$27:$H$66,$A$27:$A$66,6) | J16: =SUMIFS($H$27:$H$66,$A$27:$A$66,7) | K16: =SUMIFS($H$27:$H$66,$A$27:$A$66,8) | L16: =SUMIFS($H$27:$H$66,$A$27:$A$66,9) | M16: =SUMIFS($H$27:$H$66,$A$27:$A$66,10) | N16: =SUMIFS($H$27:$H$66,$A$27:$A$66,11) | O16: =SUMIFS($H$27:$H$66,$A$27:$A$66,12) | P16: =SUMIFS($H$27:$H$66,$A$27:$A$66,13) | Q16: =SUMIFS($H$27:$H$66,$A$27:$A$66,14) | R16: =SUMIFS($H$27:$H$66,$A$27:$A$66,15) | S16: =SUMIFS($H$27:$H$66,$A$27:$A$66,16) | T16: =SUMIFS($H$27:$H$66,$A$27:$A$66,17) | U16: =SUMIFS($H$27:$H$66,$A$27:$A$66,18) | V16: =SUMIFS($H$27:$H$66,$A$27:$A$66,19) | W16: =SUMIFS($H$27:$H$66,$A$27:$A$66,20) | X16: =AVERAGE(D16:G16) | Y16: =AVERAGE(H16:K16) | Z16: =AVERAGE(L16:O16) | AA16: =AVERAGE(P16:S16) | AB16: =AVERAGE(T16:W16)
A17: Total Payroll | B17: Formula output from payroll detail | C17: =SUMIFS($M$27:$M$66,$A$27:$A$66,0) | D17: =SUMIFS($M$27:$M$66,$A$27:$A$66,1) | E17: =SUMIFS($M$27:$M$66,$A$27:$A$66,2) | F17: =SUMIFS($M$27:$M$66,$A$27:$A$66,3) | G17: =SUMIFS($M$27:$M$66,$A$27:$A$66,4) | H17: =SUMIFS($M$27:$M$66,$A$27:$A$66,5) | I17: =SUMIFS($M$27:$M$66,$A$27:$A$66,6) | J17: =SUMIFS($M$27:$M$66,$A$27:$A$66,7) | K17: =SUMIFS($M$27:$M$66,$A$27:$A$66,8) | L17: =SUMIFS($M$27:$M$66,$A$27:$A$66,9) | M17: =SUMIFS($M$27:$M$66,$A$27:$A$66,10) | N17: =SUMIFS($M$27:$M$66,$A$27:$A$66,11) | O17: =SUMIFS($M$27:$M$66,$A$27:$A$66,12) | P17: =SUMIFS($M$27:$M$66,$A$27:$A$66,13) | Q17: =SUMIFS($M$27:$M$66,$A$27:$A$66,14) | R17: =SUMIFS($M$27:$M$66,$A$27:$A$66,15) | S17: =SUMIFS($M$27:$M$66,$A$27:$A$66,16) | T17: =SUMIFS($M$27:$M$66,$A$27:$A$66,17) | U17: =SUMIFS($M$27:$M$66,$A$27:$A$66,18) | V17: =SUMIFS($M$27:$M$66,$A$27:$A$66,19) | W17: =SUMIFS($M$27:$M$66,$A$27:$A$66,20) | X17: =SUM(D17:G17) | Y17: =SUM(H17:K17) | Z17: =SUM(L17:O17) | AA17: =SUM(P17:S17) | AB17: =SUM(T17:W17)
A18: Total Revenue | B18: Linked from Revenue Drivers | C18: ='Revenue Drivers'!C26 | D18: ='Revenue Drivers'!D26 | E18: ='Revenue Drivers'!E26 | F18: ='Revenue Drivers'!F26 | G18: ='Revenue Drivers'!G26 | H18: ='Revenue Drivers'!H26 | I18: ='Revenue Drivers'!I26 | J18: ='Revenue Drivers'!J26 | ... W18: ='Revenue Drivers'!W26 | X18: =SUM(D18:G18) | Y18: =SUM(H18:K18) | Z18: =SUM(L18:O18) | AA18: =SUM(P18:S18) | AB18: =SUM(T18:W18)
A19: Total Capacity Units | B19: Linked from Revenue Drivers | C19: ='Revenue Drivers'!C25 | D19: ='Revenue Drivers'!D25 | E19: ='Revenue Drivers'!E25 | F19: ='Revenue Drivers'!F25 | G19: ='Revenue Drivers'!G25 | H19: ='Revenue Drivers'!H25 | I19: ='Revenue Drivers'!I25 | J19: ='Revenue Drivers'!J25 | ... W19: ='Revenue Drivers'!W25 | X19: =SUM(D19:G19) | Y19: =SUM(H19:K19) | Z19: =SUM(L19:O19) | AA19: =SUM(P19:S19) | AB19: =SUM(T19:W19)
A20: Revenue per Employee | B20: Python-built productivity formula | C20: =IFERROR(C18/C16,0) | D20: =IFERROR(D18/D16,0) | E20: =IFERROR(E18/E16,0) | F20: =IFERROR(F18/F16,0) | G20: =IFERROR(G18/G16,0) | H20: =IFERROR(H18/H16,0) | I20: =IFERROR(I18/I16,0) | J20: =IFERROR(J18/J16,0) | ... AB20: =IFERROR(AB18/AB16,0)
A21: Units per Employee | B21: Python-built productivity formula | C21: =IFERROR(C19/C16,0) | D21: =IFERROR(D19/D16,0) | E21: =IFERROR(E19/E16,0) | F21: =IFERROR(F19/F16,0) | G21: =IFERROR(G19/G16,0) | H21: =IFERROR(H19/H16,0) | I21: =IFERROR(I19/I16,0) | J21: =IFERROR(J19/J16,0) | ... AB21: =IFERROR(AB19/AB16,0)
A22: Payroll % of Revenue | B22: Python-built productivity formula | C22: =IFERROR(C17/C18,0) | D22: =IFERROR(D17/D18,0) | E22: =IFERROR(E17/E18,0) | F22: =IFERROR(F17/F18,0) | G22: =IFERROR(G17/G18,0) | H22: =IFERROR(H17/H18,0) | I22: =IFERROR(I17/I18,0) | J22: =IFERROR(J17/J18,0) | ... AB22: =IFERROR(AB17/AB18,0)
A25: Payroll Detail
A26: Quarter | B26: Staffing Class | C26: Title / Person | D26: OEWS Title | E26: Starting FTE | F26: Hires | G26: Ending FTE | H26: Average FTE | I26: Annual Wage | J26: Benefits % | K26: Wage Cost | L26: Taxes & Benefits | M26: Total Payroll | N26: Wage Source
A27: 1 | B27: key_person | C27: Founder and CEO | E27: 1 | F27: 0 | G27: =E27+F27 | H27: =(E27+G27)/2 | I27: 96750 | J27: 0.22 | K27: =H27*I27/4 | L27: =K27*J27 | M27: =K27+L27 | N27: oews_median
A28: 2 | B28: key_person | C28: Founder and CEO | E28: 1 | F28: 0 | G28: =E28+F28 | H28: =(E28+G28)/2 | I28: 96750 | J28: 0.22 | K28: =H28*I28/4 | L28: =K28*J28 | M28: =K28+L28 | N28: oews_median
A29: 3 | B29: key_person | C29: Founder and CEO | E29: 1 | F29: 0 | G29: =E29+F29 | H29: =(E29+G29)/2 | I29: 96750 | J29: 0.22 | K29: =H29*I29/4 | L29: =K29*J29 | M29: =K29+L29 | N29: oews_median
A30: 4 | B30: key_person | C30: Founder and CEO | E30: 1 | F30: 0 | G30: =E30+F30 | H30: =(E30+G30)/2 | I30: 96750 | J30: 0.22 | K30: =H30*I30/4 | L30: =K30*J30 | M30: =K30+L30 | N30: oews_median
A31: 5 | B31: key_person | C31: Founder and CEO | E31: 1 | F31: 0 | G31: =E31+F31 | H31: =(E31+G31)/2 | I31: 99652 | J31: 0.22 | K31: =H31*I31/4 | L31: =K31*J31 | M31: =K31+L31 | N31: oews_median
A32: 6 | B32: key_person | C32: Founder and CEO | E32: 1 | F32: 0 | G32: =E32+F32 | H32: =(E32+G32)/2 | I32: 99652 | J32: 0.22 | K32: =H32*I32/4 | L32: =K32*J32 | M32: =K32+L32 | N32: oews_median
A33: 7 | B33: key_person | C33: Founder and CEO | E33: 1 | F33: 0 | G33: =E33+F33 | H33: =(E33+G33)/2 | I33: 99652 | J33: 0.22 | K33: =H33*I33/4 | L33: =K33*J33 | M33: =K33+L33 | N33: oews_median
A34: 8 | B34: key_person | C34: Founder and CEO | E34: 1 | F34: 0 | G34: =E34+F34 | H34: =(E34+G34)/2 | I34: 99652 | J34: 0.22 | K34: =H34*I34/4 | L34: =K34*J34 | M34: =K34+L34 | N34: oews_median
A35: 9 | B35: key_person | C35: Founder and CEO | E35: 1 | F35: 0 | G35: =E35+F35 | H35: =(E35+G35)/2 | I35: 102642 | J35: 0.22 | K35: =H35*I35/4 | L35: =K35*J35 | M35: =K35+L35 | N35: oews_median
A36: 10 | B36: key_person | C36: Founder and CEO | E36: 1 | F36: 0 | G36: =E36+F36 | H36: =(E36+G36)/2 | I36: 102642 | J36: 0.22 | K36: =H36*I36/4 | L36: =K36*J36 | M36: =K36+L36 | N36: oews_median
A37: 11 | B37: key_person | C37: Founder and CEO | E37: 1 | F37: 0 | G37: =E37+F37 | H37: =(E37+G37)/2 | I37: 102642 | J37: 0.22 | K37: =H37*I37/4 | L37: =K37*J37 | M37: =K37+L37 | N37: oews_median
A38: 12 | B38: key_person | C38: Founder and CEO | E38: 1 | F38: 0 | G38: =E38+F38 | H38: =(E38+G38)/2 | I38: 102642 | J38: 0.22 | K38: =H38*I38/4 | L38: =K38*J38 | M38: =K38+L38 | N38: oews_median
... A46: 20 | B46: key_person | C46: Founder and CEO | E46: 1 | F46: 0 | G46: =E46+F46 | H46: =(E46+G46)/2 | I46: 108893 | J46: 0.22 | K46: =H46*I46/4 | L46: =K46*J46 | M46: =K46+L46 | N46: oews_median
A47: 1 | B47: supporting_staff | C47: Registered Nurses | D47: Registered Nurses | E47: 0 | F47: 0 | G47: =E47+F47 | H47: =(E47+G47)/2 | I47: 87392 | J47: 0.2 | K47: =H47*I47/4 | L47: =K47*J47 | M47: =K47+L47 | N47: oews_title_catalog:oews_median
A48: 2 | B48: supporting_staff | C48: Registered Nurses | D48: Registered Nurses | E48: 0 | F48: 0 | G48: =E48+F48 | H48: =(E48+G48)/2 | I48: 87392 | J48: 0.2 | K48: =H48*I48/4 | L48: =K48*J48 | M48: =K48+L48 | N48: oews_title_catalog:oews_median
A49: 3 | B49: supporting_staff | C49: Registered Nurses | D49: Registered Nurses | E49: 0 | F49: 0 | G49: =E49+F49 | H49: =(E49+G49)/2 | I49: 87392 | J49: 0.2 | K49: =H49*I49/4 | L49: =K49*J49 | M49: =K49+L49 | N49: oews_title_catalog:oews_median
A50: 4 | B50: supporting_staff | C50: Registered Nurses | D50: Registered Nurses | E50: 0 | F50: 0 | G50: =E50+F50 | H50: =(E50+G50)/2 | I50: 87392 | J50: 0.2 | K50: =H50*I50/4 | L50: =K50*J50 | M50: =K50+L50 | N50: oews_title_catalog:oews_median
A51: 5 | B51: supporting_staff | C51: Registered Nurses | D51: Registered Nurses | E51: 0 | F51: 0 | G51: =E51+F51 | H51: =(E51+G51)/2 | I51: 90013 | J51: 0.2 | K51: =H51*I51/4 | L51: =K51*J51 | M51: =K51+L51 | N51: oews_title_catalog:oews_median
...

Sheet Debt Schedule
A1: Debt Schedule
A2: Debt, interest, and capital lease mechanics. Model Inputs links to calculated outputs.
C4: Stub | D4: Q1 | E4: Q2 | F4: Q3 | G4: Q4 | H4: Q5 | I4: Q6 | J4: Q7 | K4: Q8 | L4: Q9 | M4: Q10 | N4: Q11 | O4: Q12 | P4: Q13 | Q4: Q14 | R4: Q15 | S4: Q16 | T4: Q17 | U4: Q18 | V4: Q19 | W4: Q20 | X4: Y1 | Y4: Y2 | Z4: Y3 | AA4: Y4 | AB4: Y5
C5: 46162 | D5: 46295 | E5: 46387 | F5: 46477 | G5: 46568 | H5: 46660 | I5: 46752 | J5: 46843 | K5: 46934 | L5: 47026 | M5: 47118 | N5: 47208 | O5: 47299 | P5: 47391 | Q5: 47483 | R5: 47573 | S5: 47664 | T5: 47756 | U5: 47848 | V5: 47938 | W5: 48029 | X5: Annual | Y5: Annual | Z5: Annual | AA5: Annual | AB5: Annual
A6: Debt Amortization
A7: Opening Debt | B7: Calculated | C7: 0 | D7: =C11 | E7: =D11 | F7: =E11 | G7: =F11 | H7: =G11 | I7: =H11 | J7: =I11 | K7: =J11 | ... W7: =V11 | X7: =G7 | Y7: =K7 | Z7: =O7 | AA7: =S7 | AB7: =W7
A8: Debt Issuance | B8: Source borrowing | C8: 0 | D8: 0 | E8: 0 | F8: 0 | G8: 0 | H8: 0 | I8: 0 | J8: 0 | K8: 0 | L8: 0 | M8: 0 | N8: 0 | O8: 0 | P8: 0 | Q8: 0 | R8: 0 | S8: 0 | T8: 0 | U8: 0 | V8: 0 | W8: 0 | X8: =SUM(D8:G8) | Y8: =SUM(H8:K8) | Z8: =SUM(L8:O8) | AA8: =SUM(P8:S8) | AB8: =SUM(T8:W8)
A9: Requested Debt Repayment | B9: Source scheduled repayment | C9: 0 | D9: 0 | E9: 0 | F9: 0 | G9: 0 | H9: 0 | I9: 0 | J9: 0 | K9: 0 | L9: 0 | M9: 0 | N9: 0 | O9: 0 | P9: 0 | Q9: 0 | R9: 0 | S9: 0 | T9: 0 | U9: 0 | V9: 0 | W9: 0 | X9: =SUM(D9:G9) | Y9: =SUM(H9:K9) | Z9: =SUM(L9:O9) | AA9: =SUM(P9:S9) | AB9: =SUM(T9:W9)
A10: Actual Debt Repayment | B10: MIN(requested repayment, opening debt + issuance) | C10: =MIN(C9,C7+C8) | D10: =MIN(D9,D7+D8) | E10: =MIN(E9,E7+E8) | F10: =MIN(F9,F7+F8) | G10: =MIN(G9,G7+G8) | H10: =MIN(H9,H7+H8) | I10: =MIN(I9,I7+I8) | J10: =MIN(J9,J7+J8) | ... W10: =MIN(W9,W7+W8) | X10: =SUM(D10:G10) | Y10: =SUM(H10:K10) | Z10: =SUM(L10:O10) | AA10: =SUM(P10:S10) | AB10: =SUM(T10:W10)
A11: Closing Debt | B11: Calculated | C11: =MAX(0,C7+C8-C10) | D11: =MAX(0,D7+D8-D10) | E11: =MAX(0,E7+E8-E10) | F11: =MAX(0,F7+F8-F10) | G11: =MAX(0,G7+G8-G10) | H11: =MAX(0,H7+H8-H10) | I11: =MAX(0,I7+I8-I10) | J11: =MAX(0,J7+J8-J10) | ... W11: =MAX(0,W7+W8-W10) | X11: =G11 | Y11: =K11 | Z11: =O11 | AA11: =S11 | AB11: =W11
A12: Interest Rate | B12: Source rate | C12: 0 | D12: 0.024375 | E12: 0.024375 | F12: 0.024375 | G12: 0.024375 | H12: 0.024375 | I12: 0.024375 | J12: 0.024375 | K12: 0.024375 | L12: 0.024375 | M12: 0.024375 | N12: 0.024375 | O12: 0.024375 | P12: 0.024375 | Q12: 0.024375 | R12: 0.024375 | S12: 0.024375 | T12: 0.024375 | U12: 0.024375 | V12: 0.024375 | W12: 0.024375 | X12: =SUM(D12:G12) | Y12: =SUM(H12:K12) | Z12: =SUM(L12:O12) | AA12: =SUM(P12:S12) | AB12: =SUM(T12:W12)
A13: Interest Expense | B13: Average debt balance x rate | C13: =((C7+C11)/2)*C12 | D13: =((D7+D11)/2)*D12 | E13: =((E7+E11)/2)*E12 | F13: =((F7+F11)/2)*F12 | G13: =((G7+G11)/2)*G12 | H13: =((H7+H11)/2)*H12 | I13: =((I7+I11)/2)*I12 | J13: =((J7+J11)/2)*J12 | ... W13: =((W7+W11)/2)*W12 | X13: =SUM(D13:G13) | Y13: =SUM(H13:K13) | Z13: =SUM(L13:O13) | AA13: =SUM(P13:S13) | AB13: =SUM(T13:W13)
A14: Total Debt Service | B14: Interest + actual repayment | C14: =C13+C10 | D14: =D13+D10 | E14: =E13+E10 | F14: =F13+F10 | G14: =G13+G10 | H14: =H13+H10 | I14: =I13+I10 | J14: =J13+J10 | ... W14: =W13+W10 | X14: =SUM(D14:G14) | Y14: =SUM(H14:K14) | Z14: =SUM(L14:O14) | AA14: =SUM(P14:S14) | AB14: =SUM(T14:W14)
A17: Capital Lease Schedule
A18: Lease Opening Balance | B18: Capital leases | C18: 0 | D18: =C23 | E18: =D23 | F18: =E23 | G18: =F23 | H18: =G23 | I18: =H23 | J18: =I23 | K18: =J23 | ... W18: =V23 | X18: =G18 | Y18: =K18 | Z18: =O18 | AA18: =S18 | AB18: =W18
A19: Requested Lease Principal Repayments | B19: Capital leases | C19: 0 | D19: 0 | E19: 0 | F19: 0 | G19: 0 | H19: 0 | I19: 0 | J19: 0 | K19: 0 | L19: 0 | M19: 0 | N19: 0 | O19: 0 | P19: 0 | Q19: 0 | R19: 0 | S19: 0 | T19: 0 | U19: 0 | V19: 0 | W19: 0 | X19: =SUM(D19:G19) | Y19: =SUM(H19:K19) | Z19: =SUM(L19:O19) | AA19: =SUM(P19:S19) | AB19: =SUM(T19:W19)
A20: Lease Principal Repayments | B20: Capital leases | C20: =MIN(C19,C18+C21) | D20: =MIN(D19,D18+D21) | E20: =MIN(E19,E18+E21) | F20: =MIN(F19,F18+F21) | G20: =MIN(G19,G18+G21) | H20: =MIN(H19,H18+H21) | I20: =MIN(I19,I18+I21) | J20: =MIN(J19,J18+J21) | ... W20: =MIN(W19,W18+W21) | X20: =SUM(D20:G20) | Y20: =SUM(H20:K20) | Z20: =SUM(L20:O20) | AA20: =SUM(P20:S20) | AB20: =SUM(T20:W20)
A21: Lease Net Additions | B21: Capital leases | C21: 0 | D21: 0 | E21: 0 | F21: 0 | G21: 0 | H21: 0 | I21: 0 | J21: 0 | K21: 0 | L21: 0 | M21: 0 | N21: 0 | O21: 0 | P21: 0 | Q21: 0 | R21: 0 | S21: 0 | T21: 0 | U21: 0 | V21: 0 | W21: 0 | X21: =SUM(D21:G21) | Y21: =SUM(H21:K21) | Z21: =SUM(L21:O21) | AA21: =SUM(P21:S21) | AB21: =SUM(T21:W21)
A22: Lease Interest Expense | B22: Capital leases | C22: 0 | D22: =D18*D12 | E22: =E18*E12 | F22: =F18*F12 | G22: =G18*G12 | H22: =H18*H12 | I22: =I18*I12 | J22: =J18*J12 | K22: =K18*K12 | ... W22: =W18*W12 | X22: =SUM(D22:G22) | Y22: =SUM(H22:K22) | Z22: =SUM(L22:O22) | AA22: =SUM(P22:S22) | AB22: =SUM(T22:W22)
A23: Lease Closing Balance | B23: Capital leases | C23: =MAX(0,C18+C21-C20) | D23: =MAX(0,D18+D21-D20) | E23: =MAX(0,E18+E21-E20) | F23: =MAX(0,F18+F21-F20) | G23: =MAX(0,G18+G21-G20) | H23: =MAX(0,H18+H21-H20) | I23: =MAX(0,I18+I21-I20) | J23: =MAX(0,J18+J21-J20) | ... W23: =MAX(0,W18+W21-W20) | X23: =G23 | Y23: =K23 | Z23: =O23 | AA23: =S23 | AB23: =W23
A24: Right-of-Use Asset Opening | B24: Capital leases | C24: 0 | D24: =C26 | E24: =D26 | F24: =E26 | G24: =F26 | H24: =G26 | I24: =H26 | J24: =I26 | K24: =J26 | ... W24: =V26 | X24: =G24 | Y24: =K24 | Z24: =O24 | AA24: =S24 | AB24: =W24
A25: Lease Asset Depreciation | B25: Capital leases | C25: 0 | D25: =MIN((C18/20),D24) | E25: =MIN((C18/20),E24) | F25: =MIN((C18/20),F24) | G25: =MIN((C18/20),G24) | H25: =MIN((C18/20),H24) | I25: =MIN((C18/20),I24) | J25: =MIN((C18/20),J24) | K25: =MIN((C18/20),K24) | L25: =MIN((C18/20),L24) | M25: =MIN((C18/20),M24) | N25: =MIN((C18/20),N24) | O25: =MIN((C18/20),O24) | P25: =MIN((C18/20),P24) | Q25: =MIN((C18/20),Q24) | R25: =MIN((C18/20),R24) | S25: =MIN((C18/20),S24) | T25: =MIN((C18/20),T24) | U25: =MIN((C18/20),U24) | V25: =MIN((C18/20),V24) | W25: =MIN((C18/20),W24) | X25: =SUM(D25:G25) | Y25: =SUM(H25:K25) | Z25: =SUM(L25:O25) | AA25: =SUM(P25:S25) | AB25: =SUM(T25:W25)
A26: Right-of-Use Asset Closing | B26: Capital leases | C26: =MAX(0,C24-C25) | D26: =MAX(0,D24-D25) | E26: =MAX(0,E24-E25) | F26: =MAX(0,F24-F25) | G26: =MAX(0,G24-G25) | H26: =MAX(0,H24-H25) | I26: =MAX(0,I24-I25) | J26: =MAX(0,J24-J25) | ... W26: =MAX(0,W24-W25) | X26: =G26 | Y26: =K26 | Z26: =O26 | AA26: =S26 | AB26: =W26

Sheet CapEx Depreciation
A1: CapEx & Depreciation Schedule
A2: Capital expenditure and depreciation mechanics. Model Inputs links to calculated outputs.
C4: Stub | D4: Q1 | E4: Q2 | F4: Q3 | G4: Q4 | H4: Q5 | I4: Q6 | J4: Q7 | K4: Q8 | L4: Q9 | M4: Q10 | N4: Q11 | O4: Q12 | P4: Q13 | Q4: Q14 | R4: Q15 | S4: Q16 | T4: Q17 | U4: Q18 | V4: Q19 | W4: Q20 | X4: Y1 | Y4: Y2 | Z4: Y3 | AA4: Y4 | AB4: Y5
C5: 46162 | D5: 46295 | E5: 46387 | F5: 46477 | G5: 46568 | H5: 46660 | I5: 46752 | J5: 46843 | K5: 46934 | L5: 47026 | M5: 47118 | N5: 47208 | O5: 47299 | P5: 47391 | Q5: 47483 | R5: 47573 | S5: 47664 | T5: 47756 | U5: 47848 | V5: 47938 | W5: 48029 | X5: Annual | Y5: Annual | Z5: Annual | AA5: Annual | AB5: Annual
A6: PPE and Depreciation
A7: Opening PPE | B7: Calculated | C7: 12000 | D7: =C12 | E7: =D12 | F7: =E12 | G7: =F12 | H7: =G12 | I7: =H12 | J7: =I12 | K7: =J12 | ... W7: =V12 | X7: =G7 | Y7: =K7 | Z7: =O7 | AA7: =S7 | AB7: =W7
A8: Capital Expenditures | B8: Schedule source | C8: 0 | D8: 70.98 | E8: 71.378837 | F8: 71.758929 | G8: 72.120092 | H8: 72.462013 | I8: 72.784541 | J8: 73.087471 | K8: 73.370538 | L8: 73.633572 | M8: 73.876415 | N8: 74.098857 | O8: 74.300702 | P8: 74.481773 | Q8: 74.641835 | R8: 74.780818 | S8: 74.898448 | T8: 74.994692 | U8: 75.069312 | V8: 75.122161 | W8: 675.1531 | X8: =SUM(D8:G8) | Y8: =SUM(H8:K8) | Z8: =SUM(L8:O8) | AA8: =SUM(P8:S8) | AB8: =SUM(T8:W8)
A9: Lease Additions | B9: Schedule source | C9: 0 | D9: ='Debt Schedule'!D21 | E9: ='Debt Schedule'!E21 | F9: ='Debt Schedule'!F21 | G9: ='Debt Schedule'!G21 | H9: ='Debt Schedule'!H21 | I9: ='Debt Schedule'!I21 | J9: ='Debt Schedule'!J21 | K9: ='Debt Schedule'!K21 | ... W9: ='Debt Schedule'!W21 | X9: =SUM(D9:G9) | Y9: =SUM(H9:K9) | Z9: =SUM(L9:O9) | AA9: =SUM(P9:S9) | AB9: =SUM(T9:W9)
A10: Depreciation Rate | B10: Schedule source | C10: 0 | D10: 0.000296 | E10: 0.00059 | F10: 0.000882 | G10: 0.001174 | H10: 0.001464 | I10: 0.001753 | J10: 0.002042 | K10: 0.00233 | L10: 0.002617 | M10: 0.002904 | N10: 0.003191 | O10: 0.003478 | P10: 0.003766 | Q10: 0.004053 | R10: 0.004342 | S10: 0.00463 | T10: 0.00492 | U10: 0.005211 | V10: 0.005503 | W10: 0.008158 | X10: =SUM(D10:G10) | Y10: =SUM(H10:K10) | Z10: =SUM(L10:O10) | AA10: =SUM(P10:S10) | AB10: =SUM(T10:W10)
A11: Depreciation Expense | B11: Calculated | C11: =MIN(C7*C10,C7) | D11: =MIN(D7*D10,D7) | E11: =MIN(E7*E10,E7) | F11: =MIN(F7*F10,F7) | G11: =MIN(G7*G10,G7) | H11: =MIN(H7*H10,H7) | I11: =MIN(I7*I10,I7) | J11: =MIN(J7*J10,J7) | ... W11: =MIN(W7*W10,W7) | X11: =SUM(D11:G11) | Y11: =SUM(H11:K11) | Z11: =SUM(L11:O11) | AA11: =SUM(P11:S11) | AB11: =SUM(T11:W11)
A12: Closing PPE | B12: Calculated | C12: =MAX(0,C7+C8+C9-C11) | D12: =MAX(0,D7+D8+D9-D11) | E12: =MAX(0,E7+E8+E9-E11) | F12: =MAX(0,F7+F8+F9-F11) | G12: =MAX(0,G7+G8+G9-G11) | H12: =MAX(0,H7+H8+H9-H11) | I12: =MAX(0,I7+I8+I9-I11) | J12: =MAX(0,J7+J8+J9-J11) | ... W12: =MAX(0,W7+W8+W9-W11) | X12: =G12 | Y12: =K12 | Z12: =O12 | AA12: =S12 | AB12: =W12
A13: Opening Accumulated Depreciation | B13: Calculated | C13: 0 | D13: =C14 | E13: =D14 | F13: =E14 | G13: =F14 | H13: =G14 | I13: =H14 | J13: =I14 | K13: =J14 | ... W13: =V14 | X13: =G13 | Y13: =K13 | Z13: =O13 | AA13: =S13 | AB13: =W13
A14: Accumulated Depreciation | B14: Calculated | C14: =C13-C11 | D14: =D13-D11 | E14: =E13-E11 | F14: =F13-F11 | G14: =G13-G11 | H14: =H13-H11 | I14: =I13-I11 | J14: =J13-J11 | ... W14: =W13-W11 | X14: =G14 | Y14: =K14 | Z14: =O14 | AA14: =S14 | AB14: =W14

Sheet Working Capital
A1: Working Capital Schedule
A2: Working-capital drivers. Model Inputs links to these source rows.
C4: Stub | D4: Q1 | E4: Q2 | F4: Q3 | G4: Q4 | H4: Q5 | I4: Q6 | J4: Q7 | K4: Q8 | L4: Q9 | M4: Q10 | N4: Q11 | O4: Q12 | P4: Q13 | Q4: Q14 | R4: Q15 | S4: Q16 | T4: Q17 | U4: Q18 | V4: Q19 | W4: Q20 | X4: Y1 | Y4: Y2 | Z4: Y3 | AA4: Y4 | AB4: Y5
C5: 46162 | D5: 46295 | E5: 46387 | F5: 46477 | G5: 46568 | H5: 46660 | I5: 46752 | J5: 46843 | K5: 46934 | L5: 47026 | M5: 47118 | N5: 47208 | O5: 47299 | P5: 47391 | Q5: 47483 | R5: 47573 | S5: 47664 | T5: 47756 | U5: 47848 | V5: 47938 | W5: 48029 | X5: Annual | Y5: Annual | Z5: Annual | AA5: Annual | AB5: Annual
A6: Working Capital Drivers
A7: Accounts Receivable Days | B7: Working capital driver | C7: 0 | D7: 15 | E7: 15 | F7: 15 | G7: 15 | H7: 15 | I7: 15 | J7: 15 | K7: 15 | L7: 15 | M7: 15 | N7: 15 | O7: 15 | P7: 15 | Q7: 15 | R7: 15 | S7: 15 | T7: 15 | U7: 15 | V7: 15 | W7: 15
A8: Inventory Days | B8: Working capital driver | C8: 0 | D8: 10 | E8: 10 | F8: 10 | G8: 10 | H8: 10 | I8: 10 | J8: 10 | K8: 10 | L8: 10 | M8: 10 | N8: 10 | O8: 10 | P8: 10 | Q8: 10 | R8: 10 | S8: 10 | T8: 10 | U8: 10 | V8: 10 | W8: 10
A9: Accounts Payable Days | B9: Working capital driver | C9: 0 | D9: 30 | E9: 30 | F9: 30 | G9: 30 | H9: 30 | I9: 30 | J9: 30 | K9: 30 | L9: 30 | M9: 30 | N9: 30 | O9: 30 | P9: 30 | Q9: 30 | R9: 30 | S9: 30 | T9: 30 | U9: 30 | V9: 30 | W9: 30
A10: Prepaid Expenses (% of Revenue) | B10: Working capital driver | C10: 0 | D10: 0.05 | E10: 0.05 | F10: 0.05 | G10: 0.05 | H10: 0.05 | I10: 0.05 | J10: 0.05 | K10: 0.05 | L10: 0.05 | M10: 0.05 | N10: 0.05 | O10: 0.05 | P10: 0.05 | Q10: 0.05 | R10: 0.05 | S10: 0.05 | T10: 0.05 | U10: 0.05 | V10: 0.05 | W10: 0.05
A11: Deferred Revenue (% of Revenue) | B11: Working capital driver | C11: 0 | D11: 0 | E11: 0 | F11: 0 | G11: 0 | H11: 0 | I11: 0 | J11: 0 | K11: 0 | L11: 0 | M11: 0 | N11: 0 | O11: 0 | P11: 0 | Q11: 0 | R11: 0 | S11: 0 | T11: 0 | U11: 0 | V11: 0 | W11: 0
A12: Short Term Debt (% of LTD) | B12: Working capital driver | C12: 0 | D12: 0 | E12: 0 | F12: 0 | G12: 0 | H12: 0 | I12: 0 | J12: 0 | K12: 0 | L12: 0 | M12: 0 | N12: 0 | O12: 0 | P12: 0 | Q12: 0 | R12: 0 | S12: 0 | T12: 0 | U12: 0 | V12: 0 | W12: 0
A14: Opening Working Capital Seeds
A15: Cash Opening Balance | B15: Opening balance seed | C15: 10000 | D15: 0 | E15: 0 | F15: 0 | G15: 0 | H15: 0 | I15: 0 | J15: 0 | K15: 0 | L15: 0 | M15: 0 | N15: 0 | O15: 0 | P15: 0 | Q15: 0 | R15: 0 | S15: 0 | T15: 0 | U15: 0 | V15: 0 | W15: 0
A16: Accounts Receivable Opening Balance | B16: Opening balance seed | C16: 0 | D16: 0 | E16: 0 | F16: 0 | G16: 0 | H16: 0 | I16: 0 | J16: 0 | K16: 0 | L16: 0 | M16: 0 | N16: 0 | O16: 0 | P16: 0 | Q16: 0 | R16: 0 | S16: 0 | T16: 0 | U16: 0 | V16: 0 | W16: 0
A17: Inventory Opening Balance | B17: Opening balance seed | C17: 3000 | D17: 0 | E17: 0 | F17: 0 | G17: 0 | H17: 0 | I17: 0 | J17: 0 | K17: 0 | L17: 0 | M17: 0 | N17: 0 | O17: 0 | P17: 0 | Q17: 0 | R17: 0 | S17: 0 | T17: 0 | U17: 0 | V17: 0 | W17: 0
A18: Accounts Payable Opening Balance | B18: Opening balance seed | C18: 1200 | D18: 0 | E18: 0 | F18: 0 | G18: 0 | H18: 0 | I18: 0 | J18: 0 | K18: 0 | L18: 0 | M18: 0 | N18: 0 | O18: 0 | P18: 0 | Q18: 0 | R18: 0 | S18: 0 | T18: 0 | U18: 0 | V18: 0 | W18: 0
A19: Short Term Debt Opening Balance | B19: Opening balance seed | C19: 0 | D19: 0 | E19: 0 | F19: 0 | G19: 0 | H19: 0 | I19: 0 | J19: 0 | K19: 0 | L19: 0 | M19: 0 | N19: 0 | O19: 0 | P19: 0 | Q19: 0 | R19: 0 | S19: 0 | T19: 0 | U19: 0 | V19: 0 | W19: 0

Sheet Cash Equity Schedule
A1: Cash & Equity Schedule
A2: Equity, distributions, lease/rent, and opening cash seeds. Model Inputs links to these rows.
C4: Stub | D4: Q1 | E4: Q2 | F4: Q3 | G4: Q4 | H4: Q5 | I4: Q6 | J4: Q7 | K4: Q8 | L4: Q9 | M4: Q10 | N4: Q11 | O4: Q12 | P4: Q13 | Q4: Q14 | R4: Q15 | S4: Q16 | T4: Q17 | U4: Q18 | V4: Q19 | W4: Q20 | X4: Y1 | Y4: Y2 | Z4: Y3 | AA4: Y4 | AB4: Y5
C5: 46162 | D5: 46295 | E5: 46387 | F5: 46477 | G5: 46568 | H5: 46660 | I5: 46752 | J5: 46843 | K5: 46934 | L5: 47026 | M5: 47118 | N5: 47208 | O5: 47299 | P5: 47391 | Q5: 47483 | R5: 47573 | S5: 47664 | T5: 47756 | U5: 47848 | V5: 47938 | W5: 48029 | X5: Annual | Y5: Annual | Z5: Annual | AA5: Annual | AB5: Annual
A6: Equity and Distributions
A7: Owner's Capital | B7: Equity / distribution input | C7: 20000 | D7: 84858 | E7: 114346 | F7: 141217 | G7: 165562 | H7: 188001 | I7: 207086 | J7: 222769 | K7: 234867 | L7: 244170 | M7: 249196 | N7: 250013 | O7: 250013 | P7: 250013 | Q7: 250013 | R7: 250013 | S7: 250013 | T7: 250013 | U7: 250013 | V7: 250013 | W7: 250013
A8: Other Equity | B8: Equity / distribution input | C8: 0 | D8: 0 | E8: 0 | F8: 0 | G8: 0 | H8: 0 | I8: 0 | J8: 0 | K8: 0 | L8: 0 | M8: 0 | N8: 0 | O8: 0 | P8: 0 | Q8: 0 | R8: 0 | S8: 0 | T8: 0 | U8: 0 | V8: 0 | W8: 0
A9: Distributions | B9: Equity / distribution input | C9: 0 | D9: 0 | E9: 0 | F9: 0 | G9: 0 | H9: 0 | I9: 0 | J9: 0 | K9: 0 | L9: 0 | M9: 0 | N9: 0 | O9: 0 | P9: 0 | Q9: 0 | R9: 0 | S9: 135 | T9: 6481 | U9: 8197 | V9: 9534 | W9: 7611
A11: Operating Fixed Cash Items
A12: Lease | B12: Operating lease/rent input | C12: 3600 | D12: 3600 | E12: 3600 | F12: 3600 | G12: 3600 | H12: 3600 | I12: 3600 | J12: 3600 | K12: 3600 | L12: 3600 | M12: 3600 | N12: 3600 | O12: 3600 | P12: 3600 | Q12: 3600 | R12: 3600 | S12: 3600 | T12: 3600 | U12: 3600 | V12: 3600 | W12: 3600

Sheet Model Inputs
A1: Model Inputs
A2: Formula-driven bridge from schedules into FINMO. FINMO references this sheet only.
C4: Stub | D4: Q1 | E4: Q2 | F4: Q3 | G4: Q4 | H4: Q5 | I4: Q6 | J4: Q7 | K4: Q8 | L4: Q9 | M4: Q10 | N4: Q11 | O4: Q12 | P4: Q13 | Q4: Q14 | R4: Q15 | S4: Q16 | T4: Q17 | U4: Q18 | V4: Q19 | W4: Q20 | X4: Y1 | Y4: Y2 | Z4: Y3 | AA4: Y4 | AB4: Y5
C5: 46162 | D5: 46295 | E5: 46387 | F5: 46477 | G5: 46568 | H5: 46660 | I5: 46752 | J5: 46843 | K5: 46934 | L5: 47026 | M5: 47118 | N5: 47208 | O5: 47299 | P5: 47391 | Q5: 47483 | R5: 47573 | S5: 47664 | T5: 47756 | U5: 47848 | V5: 47938 | W5: 48029 | X5: Annual | Y5: Annual | Z5: Annual | AA5: Annual | AB5: Annual
A6: Income Statement Inputs
A7: Primary line of business / Individual IV session - Capacity | B7: Revenue Drivers schedule | C7: ='Revenue Drivers'!C8 | D7: ='Revenue Drivers'!D8 | E7: ='Revenue Drivers'!E8 | F7: ='Revenue Drivers'!F8 | G7: ='Revenue Drivers'!G8 | H7: ='Revenue Drivers'!H8 | I7: ='Revenue Drivers'!I8 | J7: ='Revenue Drivers'!J8 | ... W7: ='Revenue Drivers'!W8 | X7: =SUM(D7:G7) | Y7: =SUM(H7:K7) | Z7: =SUM(L7:O7) | AA7: =SUM(P7:S7) | AB7: =SUM(T7:W7)
A8: Primary line of business / Individual IV session - Unit Price | B8: Revenue Drivers schedule | C8: ='Revenue Drivers'!C9 | D8: ='Revenue Drivers'!D9 | E8: ='Revenue Drivers'!E9 | F8: ='Revenue Drivers'!F9 | G8: ='Revenue Drivers'!G9 | H8: ='Revenue Drivers'!H9 | I8: ='Revenue Drivers'!I9 | J8: ='Revenue Drivers'!J9 | ... W8: ='Revenue Drivers'!W9 | X8: =SUM(D8:G8) | Y8: =SUM(H8:K8) | Z8: =SUM(L8:O8) | AA8: =SUM(P8:S8) | AB8: =SUM(T8:W8)
A9: Primary line of business / Individual IV session - Utilization | B9: Revenue Drivers schedule | C9: ='Revenue Drivers'!C10 | D9: ='Revenue Drivers'!D10 | E9: ='Revenue Drivers'!E10 | F9: ='Revenue Drivers'!F10 | G9: ='Revenue Drivers'!G10 | H9: ='Revenue Drivers'!H10 | I9: ='Revenue Drivers'!I10 | J9: ='Revenue Drivers'!J10 | ... W9: ='Revenue Drivers'!W10 | X9: =SUM(D9:G9) | Y9: =SUM(H9:K9) | Z9: =SUM(L9:O9) | AA9: =SUM(P9:S9) | AB9: =SUM(T9:W9)
A10: Primary line of business / Individual IV session - Revenue | B10: Revenue Drivers schedule | C10: ='Revenue Drivers'!C11 | D10: ='Revenue Drivers'!D11 | E10: ='Revenue Drivers'!E11 | F10: ='Revenue Drivers'!F11 | G10: ='Revenue Drivers'!G11 | H10: ='Revenue Drivers'!H11 | I10: ='Revenue Drivers'!I11 | J10: ='Revenue Drivers'!J11 | ... W10: ='Revenue Drivers'!W11 | X10: =SUM(D10:G10) | Y10: =SUM(H10:K10) | Z10: =SUM(L10:O10) | AA10: =SUM(P10:S10) | AB10: =SUM(T10:W10)
A11: Primary line of business / Monthly IV membership - Capacity | B11: Revenue Drivers schedule | C11: ='Revenue Drivers'!C14 | D11: ='Revenue Drivers'!D14 | E11: ='Revenue Drivers'!E14 | F11: ='Revenue Drivers'!F14 | G11: ='Revenue Drivers'!G14 | H11: ='Revenue Drivers'!H14 | I11: ='Revenue Drivers'!I14 | J11: ='Revenue Drivers'!J14 | ... W11: ='Revenue Drivers'!W14 | X11: =SUM(D11:G11) | Y11: =SUM(H11:K11) | Z11: =SUM(L11:O11) | AA11: =SUM(P11:S11) | AB11: =SUM(T11:W11)
A12: Primary line of business / Monthly IV membership - Unit Price | B12: Revenue Drivers schedule | C12: ='Revenue Drivers'!C15 | D12: ='Revenue Drivers'!D15 | E12: ='Revenue Drivers'!E15 | F12: ='Revenue Drivers'!F15 | G12: ='Revenue Drivers'!G15 | H12: ='Revenue Drivers'!H15 | I12: ='Revenue Drivers'!I15 | J12: ='Revenue Drivers'!J15 | ... W12: ='Revenue Drivers'!W15 | X12: =SUM(D12:G12) | Y12: =SUM(H12:K12) | Z12: =SUM(L12:O12) | AA12: =SUM(P12:S12) | AB12: =SUM(T12:W12)
A13: Primary line of business / Monthly IV membership - Utilization | B13: Revenue Drivers schedule | C13: ='Revenue Drivers'!C16 | D13: ='Revenue Drivers'!D16 | E13: ='Revenue Drivers'!E16 | F13: ='Revenue Drivers'!F16 | G13: ='Revenue Drivers'!G16 | H13: ='Revenue Drivers'!H16 | I13: ='Revenue Drivers'!I16 | J13: ='Revenue Drivers'!J16 | ... W13: ='Revenue Drivers'!W16 | X13: =SUM(D13:G13) | Y13: =SUM(H13:K13) | Z13: =SUM(L13:O13) | AA13: =SUM(P13:S13) | AB13: =SUM(T13:W13)
A14: Primary line of business / Monthly IV membership - Revenue | B14: Revenue Drivers schedule | C14: ='Revenue Drivers'!C17 | D14: ='Revenue Drivers'!D17 | E14: ='Revenue Drivers'!E17 | F14: ='Revenue Drivers'!F17 | G14: ='Revenue Drivers'!G17 | H14: ='Revenue Drivers'!H17 | I14: ='Revenue Drivers'!I17 | J14: ='Revenue Drivers'!J17 | ... W14: ='Revenue Drivers'!W17 | X14: =SUM(D14:G14) | Y14: =SUM(H14:K14) | Z14: =SUM(L14:O14) | AA14: =SUM(P14:S14) | AB14: =SUM(T14:W14)
A15: Primary line of business / Retail wellness products - Capacity | B15: Revenue Drivers schedule | C15: ='Revenue Drivers'!C20 | D15: ='Revenue Drivers'!D20 | E15: ='Revenue Drivers'!E20 | F15: ='Revenue Drivers'!F20 | G15: ='Revenue Drivers'!G20 | H15: ='Revenue Drivers'!H20 | I15: ='Revenue Drivers'!I20 | J15: ='Revenue Drivers'!J20 | ... W15: ='Revenue Drivers'!W20 | X15: =SUM(D15:G15) | Y15: =SUM(H15:K15) | Z15: =SUM(L15:O15) | AA15: =SUM(P15:S15) | AB15: =SUM(T15:W15)
A16: Primary line of business / Retail wellness products - Unit Price | B16: Revenue Drivers schedule | C16: ='Revenue Drivers'!C21 | D16: ='Revenue Drivers'!D21 | E16: ='Revenue Drivers'!E21 | F16: ='Revenue Drivers'!F21 | G16: ='Revenue Drivers'!G21 | H16: ='Revenue Drivers'!H21 | I16: ='Revenue Drivers'!I21 | J16: ='Revenue Drivers'!J21 | ... W16: ='Revenue Drivers'!W21 | X16: =SUM(D16:G16) | Y16: =SUM(H16:K16) | Z16: =SUM(L16:O16) | AA16: =SUM(P16:S16) | AB16: =SUM(T16:W16)
A17: Primary line of business / Retail wellness products - Utilization | B17: Revenue Drivers schedule | C17: ='Revenue Drivers'!C22 | D17: ='Revenue Drivers'!D22 | E17: ='Revenue Drivers'!E22 | F17: ='Revenue Drivers'!F22 | G17: ='Revenue Drivers'!G22 | H17: ='Revenue Drivers'!H22 | I17: ='Revenue Drivers'!I22 | J17: ='Revenue Drivers'!J22 | ... W17: ='Revenue Drivers'!W22 | X17: =SUM(D17:G17) | Y17: =SUM(H17:K17) | Z17: =SUM(L17:O17) | AA17: =SUM(P17:S17) | AB17: =SUM(T17:W17)
A18: Primary line of business / Retail wellness products - Revenue | B18: Revenue Drivers schedule | C18: ='Revenue Drivers'!C23 | D18: ='Revenue Drivers'!D23 | E18: ='Revenue Drivers'!E23 | F18: ='Revenue Drivers'!F23 | G18: ='Revenue Drivers'!G23 | H18: ='Revenue Drivers'!H23 | I18: ='Revenue Drivers'!I23 | J18: ='Revenue Drivers'!J23 | ... W18: ='Revenue Drivers'!W23 | X18: =SUM(D18:G18) | Y18: =SUM(H18:K18) | Z18: =SUM(L18:O18) | AA18: =SUM(P18:S18) | AB18: =SUM(T18:W18)
A19: Revenue | B19: Revenue Drivers schedule | C19: ='Revenue Drivers'!C26 | D19: ='Revenue Drivers'!D26 | E19: ='Revenue Drivers'!E26 | F19: ='Revenue Drivers'!F26 | G19: ='Revenue Drivers'!G26 | H19: ='Revenue Drivers'!H26 | I19: ='Revenue Drivers'!I26 | J19: ='Revenue Drivers'!J26 | ... W19: ='Revenue Drivers'!W26 | X19: =SUM(D19:G19) | Y19: =SUM(H19:K19) | Z19: =SUM(L19:O19) | AA19: =SUM(P19:S19) | AB19: =SUM(T19:W19)
A20: Cost of Goods Sold | B20: Direct model driver | C20: 0.32 | D20: 0.48 | E20: 0.474 | F20: 0.468 | G20: 0.462 | H20: 0.456 | I20: 0.45 | J20: 0.444 | K20: 0.438 | L20: 0.432 | M20: 0.426 | N20: 0.42 | O20: 0.41777778 | P20: 0.41555556 | Q20: 0.41333333 | R20: 0.41111111 | S20: 0.40888889 | T20: 0.40666667 | U20: 0.40444444 | V20: 0.40222222 | W20: 0.4 | X20: =SUM(D20:G20) | Y20: =SUM(H20:K20) | Z20: =SUM(L20:O20) | AA20: =SUM(P20:S20) | AB20: =SUM(T20:W20)
A21: Marketing | B21: Direct model driver | C21: 0.22 | D21: 0.24 | E21: 0.228 | F21: 0.216 | G21: 0.204 | H21: 0.192 | I21: 0.18 | J21: 0.168 | K21: 0.156 | L21: 0.144 | M21: 0.132 | N21: 0.12 | O21: 0.11555556 | P21: 0.11111111 | Q21: 0.10666667 | R21: 0.10222222 | S21: 0.097777778 | T21: 0.093333333 | U21: 0.088888889 | V21: 0.084444444 | W21: 0.08 | X21: =SUM(D21:G21) | Y21: =SUM(H21:K21) | Z21: =SUM(L21:O21) | AA21: =SUM(P21:S21) | AB21: =SUM(T21:W21)
A22: Research & Development | B22: Direct model driver | C22: 0 | D22: 0 | E22: 0 | F22: 0 | G22: 0 | H22: 0 | I22: 0 | J22: 0 | K22: 0 | L22: 0 | M22: 0 | N22: 0 | O22: 0 | P22: 0 | Q22: 0 | R22: 0 | S22: 0 | T22: 0 | U22: 0 | V22: 0 | W22: 0 | X22: =SUM(D22:G22) | Y22: =SUM(H22:K22) | Z22: =SUM(L22:O22) | AA22: =SUM(P22:S22) | AB22: =SUM(T22:W22)
A23: Lease | B23: Cash Equity Schedule output | C23: ='Cash Equity Schedule'!C12 | D23: ='Cash Equity Schedule'!D12 | E23: ='Cash Equity Schedule'!E12 | F23: ='Cash Equity Schedule'!F12 | G23: ='Cash Equity Schedule'!G12 | H23: ='Cash Equity Schedule'!H12 | I23: ='Cash Equity Schedule'!I12 | J23: ='Cash Equity Schedule'!J12 | ... W23: ='Cash Equity Schedule'!W12 | X23: =SUM(D23:G23) | Y23: =SUM(H23:K23) | Z23: =SUM(L23:O23) | AA23: =SUM(P23:S23) | AB23: =SUM(T23:W23)
A24: Payroll | B24: Payroll Schedule output | C24: 27200 | D24: ='Payroll Schedule'!D17 | E24: ='Payroll Schedule'!E17 | F24: ='Payroll Schedule'!F17 | G24: ='Payroll Schedule'!G17 | H24: ='Payroll Schedule'!H17 | I24: ='Payroll Schedule'!I17 | J24: ='Payroll Schedule'!J17 | K24: ='Payroll Schedule'!K17 | ... W24: ='Payroll Schedule'!W17 | X24: =SUM(D24:G24) | Y24: =SUM(H24:K24) | Z24: =SUM(L24:O24) | AA24: =SUM(P24:S24) | AB24: =SUM(T24:W24)
A25: General & Administrative | B25: Direct model driver | C25: 0.005407 | D25: 0.24 | E25: 0.228 | F25: 0.216 | G25: 0.204 | H25: 0.192 | I25: 0.18 | J25: 0.168 | K25: 0.156 | L25: 0.144 | M25: 0.132 | N25: 0.12 | O25: 0.11555556 | P25: 0.11111111 | Q25: 0.10666667 | R25: 0.10222222 | S25: 0.097777778 | T25: 0.093333333 | U25: 0.088888889 | V25: 0.084444444 | W25: 0.08 | X25: =SUM(D25:G25) | Y25: =SUM(H25:K25) | Z25: =SUM(L25:O25) | AA25: =SUM(P25:S25) | AB25: =SUM(T25:W25)
A26: Interest Rate | B26: Debt Schedule output | C26: ='Debt Schedule'!C12 | D26: ='Debt Schedule'!D12 | E26: ='Debt Schedule'!E12 | F26: ='Debt Schedule'!F12 | G26: ='Debt Schedule'!G12 | H26: ='Debt Schedule'!H12 | I26: ='Debt Schedule'!I12 | J26: ='Debt Schedule'!J12 | ... W26: ='Debt Schedule'!W12 | X26: =SUM(D26:G26) | Y26: =SUM(H26:K26) | Z26: =SUM(L26:O26) | AA26: =SUM(P26:S26) | AB26: =SUM(T26:W26)
A27: Interest Expense | B27: Debt Schedule output | C27: 0 | D27: ='Debt Schedule'!D13 | E27: ='Debt Schedule'!E13 | F27: ='Debt Schedule'!F13 | G27: ='Debt Schedule'!G13 | H27: ='Debt Schedule'!H13 | I27: ='Debt Schedule'!I13 | J27: ='Debt Schedule'!J13 | K27: ='Debt Schedule'!K13 | ... W27: ='Debt Schedule'!W13 | X27: =SUM(D27:G27) | Y27: =SUM(H27:K27) | Z27: =SUM(L27:O27) | AA27: =SUM(P27:S27) | AB27: =SUM(T27:W27)
A28: Depreciation | B28: CapEx Depreciation output | C28: ='CapEx Depreciation'!C10 | D28: ='CapEx Depreciation'!D10 | E28: ='CapEx Depreciation'!E10 | F28: ='CapEx Depreciation'!F10 | G28: ='CapEx Depreciation'!G10 | H28: ='CapEx Depreciation'!H10 | I28: ='CapEx Depreciation'!I10 | J28: ='CapEx Depreciation'!J10 | ... W28: ='CapEx Depreciation'!W10 | X28: =SUM(D28:G28) | Y28: =SUM(H28:K28) | Z28: =SUM(L28:O28) | AA28: =SUM(P28:S28) | AB28: =SUM(T28:W28)
A29: Depreciation Expense | B29: CapEx Depreciation output | C29: ='CapEx Depreciation'!C11 | D29: ='CapEx Depreciation'!D11 | E29: ='CapEx Depreciation'!E11 | F29: ='CapEx Depreciation'!F11 | G29: ='CapEx Depreciation'!G11 | H29: ='CapEx Depreciation'!H11 | I29: ='CapEx Depreciation'!I11 | J29: ='CapEx Depreciation'!J11 | ... W29: ='CapEx Depreciation'!W11 | X29: =SUM(D29:G29) | Y29: =SUM(H29:K29) | Z29: =SUM(L29:O29) | AA29: =SUM(P29:S29) | AB29: =SUM(T29:W29)
A30: Taxes | B30: Direct model driver | C30: 0.189164 | D30: 0.189164 | E30: 0.189164 | F30: 0.189164 | G30: 0.189164 | H30: 0.189164 | I30: 0.189164 | J30: 0.189164 | K30: 0.189164 | L30: 0.189164 | M30: 0.189164 | N30: 0.189164 | O30: 0.189164 | P30: 0.189164 | Q30: 0.189164 | R30: 0.189164 | S30: 0.189164 | T30: 0.189164 | U30: 0.189164 | V30: 0.189164 | W30: 0.189164 | X30: =SUM(D30:G30) | Y30: =SUM(H30:K30) | Z30: =SUM(L30:O30) | AA30: =SUM(P30:S30) | AB30: =SUM(T30:W30)
A32: Balance Sheet Inputs
A33: Accounts Receivable Days | B33: Working Capital schedule | C33: ='Working Capital'!C7 | D33: ='Working Capital'!D7 | E33: ='Working Capital'!E7 | F33: ='Working Capital'!F7 | G33: ='Working Capital'!G7 | H33: ='Working Capital'!H7 | I33: ='Working Capital'!I7 | J33: ='Working Capital'!J7 | ... W33: ='Working Capital'!W7 | X33: =SUM(D33:G33) | Y33: =SUM(H33:K33) | Z33: =SUM(L33:O33) | AA33: =SUM(P33:S33) | AB33: =SUM(T33:W33)
A34: Inventory Days | B34: Working Capital schedule | C34: ='Working Capital'!C8 | D34: ='Working Capital'!D8 | E34: ='Working Capital'!E8 | F34: ='Working Capital'!F8 | G34: ='Working Capital'!G8 | H34: ='Working Capital'!H8 | I34: ='Working Capital'!I8 | J34: ='Working Capital'!J8 | ... W34: ='Working Capital'!W8 | X34: =SUM(D34:G34) | Y34: =SUM(H34:K34) | Z34: =SUM(L34:O34) | AA34: =SUM(P34:S34) | AB34: =SUM(T34:W34)
A35: Accounts Payable Days | B35: Working Capital schedule | C35: ='Working Capital'!C9 | D35: ='Working Capital'!D9 | E35: ='Working Capital'!E9 | F35: ='Working Capital'!F9 | G35: ='Working Capital'!G9 | H35: ='Working Capital'!H9 | I35: ='Working Capital'!I9 | J35: ='Working Capital'!J9 | ... W35: ='Working Capital'!W9 | X35: =SUM(D35:G35) | Y35: =SUM(H35:K35) | Z35: =SUM(L35:O35) | AA35: =SUM(P35:S35) | AB35: =SUM(T35:W35)
A36: Prepaid Expenses (% of Revenue) | B36: Working Capital schedule | C36: ='Working Capital'!C10 | D36: ='Working Capital'!D10 | E36: ='Working Capital'!E10 | F36: ='Working Capital'!F10 | G36: ='Working Capital'!G10 | H36: ='Working Capital'!H10 | I36: ='Working Capital'!I10 | J36: ='Working Capital'!J10 | ... W36: ='Working Capital'!W10 | X36: =SUM(D36:G36) | Y36: =SUM(H36:K36) | Z36: =SUM(L36:O36) | AA36: =SUM(P36:S36) | AB36: =SUM(T36:W36)
A37: Deferred Revenue (% of Revenue) | B37: Working Capital schedule | C37: ='Working Capital'!C11 | D37: ='Working Capital'!D11 | E37: ='Working Capital'!E11 | F37: ='Working Capital'!F11 | G37: ='Working Capital'!G11 | H37: ='Working Capital'!H11 | I37: ='Working Capital'!I11 | J37: ='Working Capital'!J11 | ... W37: ='Working Capital'!W11 | X37: =SUM(D37:G37) | Y37: =SUM(H37:K37) | Z37: =SUM(L37:O37) | AA37: =SUM(P37:S37) | AB37: =SUM(T37:W37)
A38: Short Term Debt (% of LTD) | B38: Working Capital schedule | C38: ='Working Capital'!C12 | D38: ='Working Capital'!D12 | E38: ='Working Capital'!E12 | F38: ='Working Capital'!F12 | G38: ='Working Capital'!G12 | H38: ='Working Capital'!H12 | I38: ='Working Capital'!I12 | J38: ='Working Capital'!J12 | ... W38: ='Working Capital'!W12 | X38: =SUM(D38:G38) | Y38: =SUM(H38:K38) | Z38: =SUM(L38:O38) | AA38: =SUM(P38:S38) | AB38: =SUM(T38:W38)
A39: Owner's Capital | B39: Cash Equity Schedule schedule | C39: ='Cash Equity Schedule'!C7 | D39: ='Cash Equity Schedule'!D7 | E39: ='Cash Equity Schedule'!E7 | F39: ='Cash Equity Schedule'!F7 | G39: ='Cash Equity Schedule'!G7 | H39: ='Cash Equity Schedule'!H7 | I39: ='Cash Equity Schedule'!I7 | J39: ='Cash Equity Schedule'!J7 | ... W39: ='Cash Equity Schedule'!W7 | X39: =G39 | Y39: =K39 | Z39: =O39 | AA39: =S39 | AB39: =W39
A40: Other Equity | B40: Cash Equity Schedule schedule | C40: ='Cash Equity Schedule'!C8 | D40: ='Cash Equity Schedule'!D8 | E40: ='Cash Equity Schedule'!E8 | F40: ='Cash Equity Schedule'!F8 | G40: ='Cash Equity Schedule'!G8 | H40: ='Cash Equity Schedule'!H8 | I40: ='Cash Equity Schedule'!I8 | J40: ='Cash Equity Schedule'!J8 | ... W40: ='Cash Equity Schedule'!W8 | X40: =G40 | Y40: =K40 | Z40: =O40 | AA40: =S40 | AB40: =W40
A41: Distributions | B41: Cash Equity Schedule schedule | C41: ='Cash Equity Schedule'!C9 | D41: ='Cash Equity Schedule'!D9 | E41: ='Cash Equity Schedule'!E9 | F41: ='Cash Equity Schedule'!F9 | G41: ='Cash Equity Schedule'!G9 | H41: ='Cash Equity Schedule'!H9 | I41: ='Cash Equity Schedule'!I9 | J41: ='Cash Equity Schedule'!J9 | ... W41: ='Cash Equity Schedule'!W9 | X41: =G41 | Y41: =K41 | Z41: =O41 | AA41: =S41 | AB41: =W41
A43: Cash Flow and Schedule Inputs
...

Sheet FINMO
A1: FINMO
A2: Three-statement financial model. All formulas reference Model Inputs and in-sheet statement rows.
C4: Stub | D4: Q1 | E4: Q2 | F4: Q3 | G4: Q4 | H4: Q5 | I4: Q6 | J4: Q7 | K4: Q8 | L4: Q9 | M4: Q10 | N4: Q11 | O4: Q12 | P4: Q13 | Q4: Q14 | R4: Q15 | S4: Q16 | T4: Q17 | U4: Q18 | V4: Q19 | W4: Q20 | X4: Y1 | Y4: Y2 | Z4: Y3 | AA4: Y4 | AB4: Y5
C5: 46162 | D5: 46295 | E5: 46387 | F5: 46477 | G5: 46568 | H5: 46660 | I5: 46752 | J5: 46843 | K5: 46934 | L5: 47026 | M5: 47118 | N5: 47208 | O5: 47299 | P5: 47391 | Q5: 47483 | R5: 47573 | S5: 47664 | T5: 47756 | U5: 47848 | V5: 47938 | W5: 48029 | X5: Annual | Y5: Annual | Z5: Annual | AA5: Annual | AB5: Annual
A6: Days in Quarter | C6: 0 | D6: 92 | E6: 92 | F6: 90 | G6: 91 | H6: 92 | I6: 92 | J6: 91 | K6: 91 | L6: 92 | M6: 92 | N6: 90 | O6: 91 | P6: 92 | Q6: 92 | R6: 90 | S6: 91 | T6: 92 | U6: 92 | V6: 90 | W6: 91
A7: Income Statement
A8: Revenue | B8: Formula | C8: ='Model Inputs'!C19 | D8: ='Model Inputs'!D19 | E8: ='Model Inputs'!E19 | F8: ='Model Inputs'!F19 | G8: ='Model Inputs'!G19 | H8: ='Model Inputs'!H19 | I8: ='Model Inputs'!I19 | J8: ='Model Inputs'!J19 | ... W8: ='Model Inputs'!W19 | X8: =SUM(D8:G8) | Y8: =SUM(H8:K8) | Z8: =SUM(L8:O8) | AA8: =SUM(P8:S8) | AB8: =SUM(T8:W8)
A9: Cost of Goods Sold | B9: Formula | C9: =C8*'Model Inputs'!C20 | D9: =D8*'Model Inputs'!D20 | E9: =E8*'Model Inputs'!E20 | F9: =F8*'Model Inputs'!F20 | G9: =G8*'Model Inputs'!G20 | H9: =H8*'Model Inputs'!H20 | I9: =I8*'Model Inputs'!I20 | J9: =J8*'Model Inputs'!J20 | ... W9: =W8*'Model Inputs'!W20 | X9: =SUM(D9:G9) | Y9: =SUM(H9:K9) | Z9: =SUM(L9:O9) | AA9: =SUM(P9:S9) | AB9: =SUM(T9:W9)
A10: Gross Profit | B10: Formula | C10: =C8-C9 | D10: =D8-D9 | E10: =E8-E9 | F10: =F8-F9 | G10: =G8-G9 | H10: =H8-H9 | I10: =I8-I9 | J10: =J8-J9 | ... W10: =W8-W9 | X10: =SUM(D10:G10) | Y10: =SUM(H10:K10) | Z10: =SUM(L10:O10) | AA10: =SUM(P10:S10) | AB10: =SUM(T10:W10)
A11: Marketing | B11: Formula | C11: =C8*'Model Inputs'!C21 | D11: =D8*'Model Inputs'!D21 | E11: =E8*'Model Inputs'!E21 | F11: =F8*'Model Inputs'!F21 | G11: =G8*'Model Inputs'!G21 | H11: =H8*'Model Inputs'!H21 | I11: =I8*'Model Inputs'!I21 | J11: =J8*'Model Inputs'!J21 | ... W11: =W8*'Model Inputs'!W21 | X11: =SUM(D11:G11) | Y11: =SUM(H11:K11) | Z11: =SUM(L11:O11) | AA11: =SUM(P11:S11) | AB11: =SUM(T11:W11)
A12: Research & Development | B12: Formula | C12: =C8*'Model Inputs'!C22 | D12: =D8*'Model Inputs'!D22 | E12: =E8*'Model Inputs'!E22 | F12: =F8*'Model Inputs'!F22 | G12: =G8*'Model Inputs'!G22 | H12: =H8*'Model Inputs'!H22 | I12: =I8*'Model Inputs'!I22 | J12: =J8*'Model Inputs'!J22 | ... W12: =W8*'Model Inputs'!W22 | X12: =SUM(D12:G12) | Y12: =SUM(H12:K12) | Z12: =SUM(L12:O12) | AA12: =SUM(P12:S12) | AB12: =SUM(T12:W12)
A13: Lease/Rent | B13: Formula | C13: ='Model Inputs'!C23 | D13: ='Model Inputs'!D23 | E13: ='Model Inputs'!E23 | F13: ='Model Inputs'!F23 | G13: ='Model Inputs'!G23 | H13: ='Model Inputs'!H23 | I13: ='Model Inputs'!I23 | J13: ='Model Inputs'!J23 | ... W13: ='Model Inputs'!W23 | X13: =SUM(D13:G13) | Y13: =SUM(H13:K13) | Z13: =SUM(L13:O13) | AA13: =SUM(P13:S13) | AB13: =SUM(T13:W13)
A14: Payroll | B14: Formula | C14: ='Model Inputs'!C24 | D14: ='Model Inputs'!D24 | E14: ='Model Inputs'!E24 | F14: ='Model Inputs'!F24 | G14: ='Model Inputs'!G24 | H14: ='Model Inputs'!H24 | I14: ='Model Inputs'!I24 | J14: ='Model Inputs'!J24 | ... W14: ='Model Inputs'!W24 | X14: =SUM(D14:G14) | Y14: =SUM(H14:K14) | Z14: =SUM(L14:O14) | AA14: =SUM(P14:S14) | AB14: =SUM(T14:W14)
A15: General & Administrative | B15: Formula | C15: =C8*'Model Inputs'!C25 | D15: =D8*'Model Inputs'!D25 | E15: =E8*'Model Inputs'!E25 | F15: =F8*'Model Inputs'!F25 | G15: =G8*'Model Inputs'!G25 | H15: =H8*'Model Inputs'!H25 | I15: =I8*'Model Inputs'!I25 | J15: =J8*'Model Inputs'!J25 | ... W15: =W8*'Model Inputs'!W25 | X15: =SUM(D15:G15) | Y15: =SUM(H15:K15) | Z15: =SUM(L15:O15) | AA15: =SUM(P15:S15) | AB15: =SUM(T15:W15)
A16: EBITDA | B16: Formula | C16: =C10-SUM(C11:C15) | D16: =D10-SUM(D11:D15) | E16: =E10-SUM(E11:E15) | F16: =F10-SUM(F11:F15) | G16: =G10-SUM(G11:G15) | H16: =H10-SUM(H11:H15) | I16: =I10-SUM(I11:I15) | J16: =J10-SUM(J11:J15) | ... W16: =W10-SUM(W11:W15) | X16: =SUM(D16:G16) | Y16: =SUM(H16:K16) | Z16: =SUM(L16:O16) | AA16: =SUM(P16:S16) | AB16: =SUM(T16:W16)
A17: Interest | B17: Formula | C17: ='Model Inputs'!C27+'Model Inputs'!C56 | D17: ='Model Inputs'!D27+'Model Inputs'!D56 | E17: ='Model Inputs'!E27+'Model Inputs'!E56 | F17: ='Model Inputs'!F27+'Model Inputs'!F56 | G17: ='Model Inputs'!G27+'Model Inputs'!G56 | H17: ='Model Inputs'!H27+'Model Inputs'!H56 | I17: ='Model Inputs'!I27+'Model Inputs'!I56 | J17: ='Model Inputs'!J27+'Model Inputs'!J56 | ... W17: ='Model Inputs'!W27+'Model Inputs'!W56 | X17: =SUM(D17:G17) | Y17: =SUM(H17:K17) | Z17: =SUM(L17:O17) | AA17: =SUM(P17:S17) | AB17: =SUM(T17:W17)
A18: Depreciation | B18: Formula | C18: ='Model Inputs'!C29+'Model Inputs'!C59 | D18: ='Model Inputs'!D29+'Model Inputs'!D59 | E18: ='Model Inputs'!E29+'Model Inputs'!E59 | F18: ='Model Inputs'!F29+'Model Inputs'!F59 | G18: ='Model Inputs'!G29+'Model Inputs'!G59 | H18: ='Model Inputs'!H29+'Model Inputs'!H59 | I18: ='Model Inputs'!I29+'Model Inputs'!I59 | J18: ='Model Inputs'!J29+'Model Inputs'!J59 | ... W18: ='Model Inputs'!W29+'Model Inputs'!W59 | X18: =SUM(D18:G18) | Y18: =SUM(H18:K18) | Z18: =SUM(L18:O18) | AA18: =SUM(P18:S18) | AB18: =SUM(T18:W18)
A19: Taxes | B19: Formula | C19: =MAX(0,C16-C17-C18)*'Model Inputs'!C30 | D19: =MAX(0,D16-D17-D18)*'Model Inputs'!D30 | E19: =MAX(0,E16-E17-E18)*'Model Inputs'!E30 | F19: =MAX(0,F16-F17-F18)*'Model Inputs'!F30 | G19: =MAX(0,G16-G17-G18)*'Model Inputs'!G30 | H19: =MAX(0,H16-H17-H18)*'Model Inputs'!H30 | I19: =MAX(0,I16-I17-I18)*'Model Inputs'!I30 | J19: =MAX(0,J16-J17-J18)*'Model Inputs'!J30 | ... W19: =MAX(0,W16-W17-W18)*'Model Inputs'!W30 | X19: =SUM(D19:G19) | Y19: =SUM(H19:K19) | Z19: =SUM(L19:O19) | AA19: =SUM(P19:S19) | AB19: =SUM(T19:W19)
A20: Net Income | B20: Formula | C20: =C16-SUM(C17:C19) | D20: =D16-SUM(D17:D19) | E20: =E16-SUM(E17:E19) | F20: =F16-SUM(F17:F19) | G20: =G16-SUM(G17:G19) | H20: =H16-SUM(H17:H19) | I20: =I16-SUM(I17:I19) | J20: =J16-SUM(J17:J19) | ... W20: =W16-SUM(W17:W19) | X20: =SUM(D20:G20) | Y20: =SUM(H20:K20) | Z20: =SUM(L20:O20) | AA20: =SUM(P20:S20) | AB20: =SUM(T20:W20)
A22: Balance Sheet
A23: Cash | B23: Formula | C23: =C61 | D23: =D61 | E23: =E61 | F23: =F61 | G23: =G61 | H23: =H61 | I23: =I61 | J23: =J61 | ... W23: =W61 | X23: =G23 | Y23: =K23 | Z23: =O23 | AA23: =S23 | AB23: =W23
