Workbook

Sheet Revenue Drivers
A1: Revenue Drivers
A2: Source operating drivers. Model Inputs links to these rows.
C4: Stub | D4: Q1 | E4: Q2 | F4: Q3 | G4: Q4 | H4: Q5 | I4: Q6 | J4: Q7 | K4: Q8 | L4: Q9 | M4: Q10 | N4: Q11 | O4: Q12 | P4: Q13 | Q4: Q14 | R4: Q15 | S4: Q16 | T4: Q17 | U4: Q18 | V4: Q19 | W4: Q20 | X4: Y1 | Y4: Y2 | Z4: Y3 | AA4: Y4 | AB4: Y5
C5: 46162 | D5: 46295 | E5: 46387 | F5: 46477 | G5: 46568 | H5: 46660 | I5: 46752 | J5: 46843 | K5: 46934 | L5: 47026 | M5: 47118 | N5: 47208 | O5: 47299 | P5: 47391 | Q5: 47483 | R5: 47573 | S5: 47664 | T5: 47756 | U5: 47848 | V5: 47938 | W5: 48029 | X5: Annual | Y5: Annual | Z5: Annual | AA5: Annual | AB5: Annual
A6: Revenue Driver Source Rows
A7: Corporate Legal Services / Corporate legal matter/engagement
A8: Corporate Legal Services / Corporate legal matter/engagement - Capacity | B8: Source driver | C8: 130 | D8: 57.266667 | E8: 57.266667 | F8: 57.266667 | G8: 57.266667 | H8: 57.266667 | I8: 57.266667 | J8: 57.266667 | K8: 57.266667 | L8: 57.266667 | M8: 57.266667 | N8: 57.266667 | O8: 57.266667 | P8: 57.266667 | Q8: 57.266667 | R8: 57.266667 | S8: 57.266667 | T8: 57.266667 | U8: 57.266667 | V8: 57.266667 | W8: 57.266667
A9: Corporate Legal Services / Corporate legal matter/engagement - Unit Price | B9: Source driver | C9: 12000 | D9: 3228.0648 | E9: 4687.3753 | F9: 5633.9904 | G9: 6458.0668 | H9: 7175.4669 | I9: 7800 | J9: 8343.6876 | K9: 8816.9952 | L9: 9229.0334 | M9: 9587.7335 | N9: 9900 | O9: 10171.844 | P9: 10408.498 | Q9: 10614.517 | R9: 10793.867 | S9: 10950 | T9: 11085.922 | U9: 11204.249 | V9: 11307.258 | W9: 11396.933
A10: Corporate Legal Services / Corporate legal matter/engagement - Utilization | B10: Source driver | C10: 0.7 | D10: 0.826081 | E10: 0.737694 | F10: 0.62412 | G10: 0.552413 | H10: 0.517806 | I10: 0.479663 | J10: 0.456714 | K10: 0.439438 | L10: 0.435679 | M10: 0.426566 | N10: 0.503357 | O10: 0.586577 | P10: 0.641591 | Q10: 0.671911 | R10: 0.686967 | S10: 0.694057 | T10: 0.697312 | U10: 0.698788 | V10: 0.699455 | W10: 0.699755
A11: Corporate Legal Services / Corporate legal matter/engagement - Revenue | B11: Capacity x Unit Price x Utilization | C11: =C8*C9*C10 -> 1092000 | D11: =D8*D9*D10 -> 152709.76 | E11: =E8*E9*E10 -> 198019.46 | F11: =F8*F9*F10 -> 201365.99 | G11: =G8*G9*G10 -> 204299.98 | H11: =H8*H9*H10 -> 212774.29 | I11: =I8*I9*I10 -> 214255.87 | J11: =J8*J9*J10 -> 218224.88 | ... W11: =W8*W9*W10 -> 456705.17 | X11: =SUM(D11:G11) -> 756395.19 | Y11: =SUM(H11:K11) -> 867136.05 | Z11: =SUM(L11:O11) -> 1091531.4 | AA11: =SUM(P11:S11) -> 1650709.6 | AB11: =SUM(T11:W11) -> 1800677.1
A13: Individual Legal Services / Family/estate legal matter
A14: Individual Legal Services / Family/estate legal matter - Capacity | B14: Source driver | C14: 104 | D14: 45.813333 | E14: 45.813333 | F14: 45.813333 | G14: 45.813333 | H14: 45.813333 | I14: 45.813333 | J14: 45.813333 | K14: 45.813333 | L14: 45.813333 | M14: 45.813333 | N14: 45.813333 | O14: 45.813333 | P14: 45.813333 | Q14: 45.813333 | R14: 45.813333 | S14: 45.813333 | T14: 45.813333 | U14: 45.813333 | V14: 45.813333 | W14: 45.813333
A15: Individual Legal Services / Family/estate legal matter - Unit Price | B15: Source driver | C15: 6000 | D15: 3228.0648 | E15: 2343.6876 | F15: 2816.9952 | G15: 3229.0334 | H15: 3587.7335 | I15: 3900 | J15: 4171.8438 | K15: 4408.4976 | L15: 4614.5167 | M15: 4793.8667 | N15: 4950 | O15: 5085.9219 | P15: 5204.2488 | Q15: 5307.2583 | R15: 5396.9334 | S15: 5475 | T15: 5542.961 | U15: 5602.1244 | V15: 5653.6292 | W15: 5698.4667
A16: Individual Legal Services / Family/estate legal matter - Utilization | B16: Source driver | C16: 0.7 | D16: 0.826081 | E16: 0.737694 | F16: 0.62412 | G16: 0.552413 | H16: 0.517806 | I16: 0.479663 | J16: 0.456714 | K16: 0.439438 | L16: 0.435679 | M16: 0.426566 | N16: 0.503357 | O16: 0.586577 | P16: 0.641591 | Q16: 0.671911 | R16: 0.686967 | S16: 0.694057 | T16: 0.697312 | U16: 0.698788 | V16: 0.699455 | W16: 0.699755
A17: Individual Legal Services / Family/estate legal matter - Revenue | B17: Capacity x Unit Price x Utilization | C17: =C14*C15*C16 -> 436800 | D17: =D14*D15*D16 -> 122167.8 | E17: =E14*E15*E16 -> 79207.785 | F17: =F14*F15*F16 -> 80546.393 | G17: =G14*G15*G16 -> 81719.992 | H17: =H14*H15*H16 -> 85109.715 | I17: =I14*I15*I16 -> 85702.347 | J17: =J14*J15*J16 -> 87289.952 | ... W17: =W14*W15*W16 -> 182682.07 | X17: =SUM(D17:G17) -> 363641.97 | Y17: =SUM(H17:K17) -> 346854.41 | Z17: =SUM(L17:O17) -> 436612.54 | AA17: =SUM(P17:S17) -> 660283.82 | AB17: =SUM(T17:W17) -> 720270.82
A19: Total Capacity Units | B19: All revenue driver capacity units | C19: =SUM(C8,C14) -> 234 | D19: =SUM(D8,D14) -> 103.08 | E19: =SUM(E8,E14) -> 103.08 | F19: =SUM(F8,F14) -> 103.08 | G19: =SUM(G8,G14) -> 103.08 | H19: =SUM(H8,H14) -> 103.08 | I19: =SUM(I8,I14) -> 103.08 | J19: =SUM(J8,J14) -> 103.08 | ... W19: =SUM(W8,W14) -> 103.08 | X19: =SUM(D19:G19) -> 412.32 | Y19: =SUM(H19:K19) -> 412.32 | Z19: =SUM(L19:O19) -> 412.32 | AA19: =SUM(P19:S19) -> 412.32 | AB19: =SUM(T19:W19) -> 412.32
A20: Total Revenue | B20: All revenue products | C20: =SUM(C11,C17) -> 1528800 | D20: =SUM(D11,D17) -> 274877.56 | E20: =SUM(E11,E17) -> 277227.25 | F20: =SUM(F11,F17) -> 281912.38 | G20: =SUM(G11,G17) -> 286019.97 | H20: =SUM(H11,H17) -> 297884.01 | I20: =SUM(I11,I17) -> 299958.22 | J20: =SUM(J11,J17) -> 305514.83 | ... W20: =SUM(W11,W17) -> 639387.23 | X20: =SUM(D20:G20) -> 1120037.2 | Y20: =SUM(H20:K20) -> 1213990.5 | Z20: =SUM(L20:O20) -> 1528143.9 | AA20: =SUM(P20:S20) -> 2310993.4 | AB20: =SUM(T20:W20) -> 2520947.9
A22: Stage Ramp Contract
A23: Actual Revenue QoQ Growth | B23: Total revenue growth from modeled revenue drivers | C23: =0 -> 0 | D23: =IFERROR(D20/C20-1,0) -> -0.82020044 | E23: =IFERROR(E20/D20-1,0) -> 0.0085481301 | F23: =IFERROR(F20/E20-1,0) -> 0.016899956 | G23: =IFERROR(G20/F20-1,0) -> 0.01457047 | H23: =IFERROR(H20/G20-1,0) -> 0.041479733 | I23: =IFERROR(I20/H20-1,0) -> 0.0069631497 | J23: =IFERROR(J20/I20-1,0) -> 0.018524639 | K23: =IFERROR(K20/J20-1,0) -> 0.016753914 | ... W23: =IFERROR(W20/V20-1,0) -> 0.008363055 | X23: =AVERAGE(D23:G23) -> -0.19504547 | Y23: =AVERAGE(H23:K23) -> 0.020930359 | Z23: =AVERAGE(L23:O23) -> 0.11767446 | AA23: =AVERAGE(P23:S23) -> 0.062960027 | AB23: =AVERAGE(T23:W23) -> 0.012123509
A24: Stage Ramp Revenue QoQ Target | B24: GPT-selected stage ramp contract | C24: 0 | D24: 0.5 | E24: 0.5 | F24: 0.5 | G24: 0.5 | H24: 0.5 | I24: 0.5 | J24: 0.5 | K24: 0.5 | L24: 0.5 | M24: 0.5 | N24: 0.5 | O24: 0.5 | P24: 0.5 | Q24: 0.5 | R24: 0.5 | S24: 0.5 | T24: 0.5 | U24: 0.5 | V24: 0.5 | W24: 0.5 | X24: =AVERAGE(D24:G24) -> 0.5 | Y24: =AVERAGE(H24:K24) -> 0.5 | Z24: =AVERAGE(L24:O24) -> 0.5 | AA24: =AVERAGE(P24:S24) -> 0.5 | AB24: =AVERAGE(T24:W24) -> 0.5
A25: Stage Ramp Revenue QoQ Max | B25: GPT-selected stage ramp contract | C25: 0 | D25: 0.75 | E25: 0.75 | F25: 0.75 | G25: 0.75 | H25: 0.75 | I25: 0.75 | J25: 0.75 | K25: 0.75 | L25: 0.75 | M25: 0.75 | N25: 0.75 | O25: 0.75 | P25: 0.75 | Q25: 0.75 | R25: 0.75 | S25: 0.75 | T25: 0.75 | U25: 0.75 | V25: 0.75 | W25: 0.75 | X25: =AVERAGE(D25:G25) -> 0.75 | Y25: =AVERAGE(H25:K25) -> 0.75 | Z25: =AVERAGE(L25:O25) -> 0.75 | AA25: =AVERAGE(P25:S25) -> 0.75 | AB25: =AVERAGE(T25:W25) -> 0.75
A26: Stage Ramp Revenue QoQ Spike Max | B26: GPT-selected stage ramp contract | C26: 0 | D26: 0.75 | E26: 0.75 | F26: 0.75 | G26: 0.75 | H26: 0.75 | I26: 0.75 | J26: 0.75 | K26: 0.75 | L26: 0.75 | M26: 0.75 | N26: 0.75 | O26: 0.75 | P26: 0.75 | Q26: 0.75 | R26: 0.75 | S26: 0.75 | T26: 0.75 | U26: 0.75 | V26: 0.75 | W26: 0.75 | X26: =AVERAGE(D26:G26) -> 0.75 | Y26: =AVERAGE(H26:K26) -> 0.75 | Z26: =AVERAGE(L26:O26) -> 0.75 | AA26: =AVERAGE(P26:S26) -> 0.75 | AB26: =AVERAGE(T26:W26) -> 0.75
A27: Stage Ramp Utilization Cap | B27: GPT-selected stage ramp contract | C27: 0 | D27: 0.25 | E27: 0.31 | F27: 0.37 | G27: 0.43 | H27: 0.49 | I27: 0.55 | J27: 0.61 | K27: 0.67 | L27: 0.73 | M27: 0.79 | N27: 0.85 | O27: 0.85 | P27: 0.85 | Q27: 0.85 | R27: 0.85 | S27: 0.85 | T27: 0.85 | U27: 0.85 | V27: 0.85 | W27: 0.85 | X27: =AVERAGE(D27:G27) -> 0.34 | Y27: =AVERAGE(H27:K27) -> 0.58 | Z27: =AVERAGE(L27:O27) -> 0.805 | AA27: =AVERAGE(P27:S27) -> 0.85 | AB27: =AVERAGE(T27:W27) -> 0.85
A28: Stage Ramp COGS % Revenue Target | B28: GPT-selected stage ramp contract | C28: 0 | D28: 0.48 | E28: 0.48 | F28: 0.48 | G28: 0.48 | H28: 0.48 | I28: 0.48 | J28: 0.48 | K28: 0.48 | L28: 0.48 | M28: 0.48 | N28: 0.48 | O28: 0.48 | P28: 0.48 | Q28: 0.48 | R28: 0.48 | S28: 0.48 | T28: 0.48 | U28: 0.48 | V28: 0.48 | W28: 0.48 | X28: =AVERAGE(D28:G28) -> 0.48 | Y28: =AVERAGE(H28:K28) -> 0.48 | Z28: =AVERAGE(L28:O28) -> 0.48 | AA28: =AVERAGE(P28:S28) -> 0.48 | AB28: =AVERAGE(T28:W28) -> 0.48
A29: Stage Ramp COGS % Revenue Max | B29: GPT-selected stage ramp contract | C29: 0 | D29: 0.71 | E29: 0.71 | F29: 0.71 | G29: 0.71 | H29: 0.71 | I29: 0.71 | J29: 0.71 | K29: 0.71 | L29: 0.71 | M29: 0.71 | N29: 0.71 | O29: 0.71 | P29: 0.71 | Q29: 0.71 | R29: 0.71 | S29: 0.71 | T29: 0.71 | U29: 0.71 | V29: 0.71 | W29: 0.71 | X29: =AVERAGE(D29:G29) -> 0.71 | Y29: =AVERAGE(H29:K29) -> 0.71 | Z29: =AVERAGE(L29:O29) -> 0.71 | AA29: =AVERAGE(P29:S29) -> 0.71 | AB29: =AVERAGE(T29:W29) -> 0.71
A30: Stage Ramp Marketing % Revenue Max | B30: GPT-selected stage ramp contract | C30: 0 | D30: 0.4 | E30: 0.4 | F30: 0.4 | G30: 0.4 | H30: 0.4 | I30: 0.4 | J30: 0.4 | K30: 0.4 | L30: 0.4 | M30: 0.4 | N30: 0.4 | O30: 0.4 | P30: 0.4 | Q30: 0.4 | R30: 0.4 | S30: 0.4 | T30: 0.4 | U30: 0.4 | V30: 0.4 | W30: 0.4 | X30: =AVERAGE(D30:G30) -> 0.4 | Y30: =AVERAGE(H30:K30) -> 0.4 | Z30: =AVERAGE(L30:O30) -> 0.4 | AA30: =AVERAGE(P30:S30) -> 0.4 | AB30: =AVERAGE(T30:W30) -> 0.4
A31: Stage Ramp R&D % Revenue Max | B31: GPT-selected stage ramp contract | C31: 0 | D31: 0.5 | E31: 0.5 | F31: 0.5 | G31: 0.5 | H31: 0.5 | I31: 0.5 | J31: 0.5 | K31: 0.5 | L31: 0.5 | M31: 0.5 | N31: 0.5 | O31: 0.5 | P31: 0.5 | Q31: 0.5 | R31: 0.5 | S31: 0.5 | T31: 0.5 | U31: 0.5 | V31: 0.5 | W31: 0.5 | X31: =AVERAGE(D31:G31) -> 0.5 | Y31: =AVERAGE(H31:K31) -> 0.5 | Z31: =AVERAGE(L31:O31) -> 0.5 | AA31: =AVERAGE(P31:S31) -> 0.5 | AB31: =AVERAGE(T31:W31) -> 0.5
A32: Stage Ramp G&A % Revenue Max | B32: GPT-selected stage ramp contract | C32: 0 | D32: 0.53 | E32: 0.53 | F32: 0.53 | G32: 0.53 | H32: 0.53 | I32: 0.53 | J32: 0.53 | K32: 0.53 | L32: 0.53 | M32: 0.53 | N32: 0.53 | O32: 0.53 | P32: 0.53 | Q32: 0.53 | R32: 0.53 | S32: 0.53 | T32: 0.53 | U32: 0.53 | V32: 0.53 | W32: 0.53 | X32: =AVERAGE(D32:G32) -> 0.53 | Y32: =AVERAGE(H32:K32) -> 0.53 | Z32: =AVERAGE(L32:O32) -> 0.53 | AA32: =AVERAGE(P32:S32) -> 0.53 | AB32: =AVERAGE(T32:W32) -> 0.53
A33: Stage Ramp Lease % Revenue Max | B33: GPT-selected stage ramp contract | C33: 0 | D33: 0.13 | E33: 0.13 | F33: 0.13 | G33: 0.13 | H33: 0.13 | I33: 0.13 | J33: 0.13 | K33: 0.13 | L33: 0.13 | M33: 0.13 | N33: 0.13 | O33: 0.13 | P33: 0.13 | Q33: 0.13 | R33: 0.13 | S33: 0.13 | T33: 0.13 | U33: 0.13 | V33: 0.13 | W33: 0.13 | X33: =AVERAGE(D33:G33) -> 0.13 | Y33: =AVERAGE(H33:K33) -> 0.13 | Z33: =AVERAGE(L33:O33) -> 0.13 | AA33: =AVERAGE(P33:S33) -> 0.13 | AB33: =AVERAGE(T33:W33) -> 0.13
A34: Stage Ramp Net Income Margin Floor | B34: GPT-selected stage ramp contract | C34: 0 | D34: -0.1 | E34: -0.1 | F34: -0.1 | G34: -0.1 | H34: 0 | I34: 0 | J34: 0 | K34: 0 | L34: 0 | M34: 0 | N34: 0.02 | O34: 0.03 | P34: 0.03 | Q34: 0.04 | R34: 0.04 | S34: 0.05 | T34: 0.05 | U34: 0.06 | V34: 0.06 | W34: 0.07 | X34: =AVERAGE(D34:G34) -> -0.1 | Y34: =AVERAGE(H34:K34) -> 0 | Z34: =AVERAGE(L34:O34) -> 0.0125 | AA34: =AVERAGE(P34:S34) -> 0.04 | AB34: =AVERAGE(T34:W34) -> 0.06

Sheet Payroll Schedule
A1: Payroll Schedule
A2: OEWS-title, capacity/utilization-driven payroll source. Model Inputs links to Total Payroll.
C4: Stub | D4: Q1 | E4: Q2 | F4: Q3 | G4: Q4 | H4: Q5 | I4: Q6 | J4: Q7 | K4: Q8 | L4: Q9 | M4: Q10 | N4: Q11 | O4: Q12 | P4: Q13 | Q4: Q14 | R4: Q15 | S4: Q16 | T4: Q17 | U4: Q18 | V4: Q19 | W4: Q20 | X4: Y1 | Y4: Y2 | Z4: Y3 | AA4: Y4 | AB4: Y5
C5: 46162 | D5: 46295 | E5: 46387 | F5: 46477 | G5: 46568 | H5: 46660 | I5: 46752 | J5: 46843 | K5: 46934 | L5: 47026 | M5: 47118 | N5: 47208 | O5: 47299 | P5: 47391 | Q5: 47483 | R5: 47573 | S5: 47664 | T5: 47756 | U5: 47848 | V5: 47938 | W5: 48029 | X5: Annual | Y5: Annual | Z5: Annual | AA5: Annual | AB5: Annual
A6: Payroll Assumptions
A7: Capacity Labor Model | B7: labor_driven
A8: Labor Intensity Class | B8: expert
A9: Wage Positioning Tier | B9: premium
A10: Wage Positioning Multiplier | B10: 1.5
A11: Capacity Units per Supporting FTE | B11: 34.36
A12: Target Payroll % of Revenue | B12: 0.45
A14: Quarter Summary
A15: Total Ending FTE | B15: Formula output from payroll detail | C15: =SUMIFS($G$27:$G$86,$A$27:$A$86,0) -> 0 | D15: =SUMIFS($G$27:$G$86,$A$27:$A$86,1) -> 3 | E15: =SUMIFS($G$27:$G$86,$A$27:$A$86,2) -> 3 | F15: =SUMIFS($G$27:$G$86,$A$27:$A$86,3) -> 3 | G15: =SUMIFS($G$27:$G$86,$A$27:$A$86,4) -> 3 | H15: =SUMIFS($G$27:$G$86,$A$27:$A$86,5) -> 3 | I15: =SUMIFS($G$27:$G$86,$A$27:$A$86,6) -> 3 | J15: =SUMIFS($G$27:$G$86,$A$27:$A$86,7) -> 3 | K15: =SUMIFS($G$27:$G$86,$A$27:$A$86,8) -> 3 | L15: =SUMIFS($G$27:$G$86,$A$27:$A$86,9) -> 3 | M15: =SUMIFS($G$27:$G$86,$A$27:$A$86,10) -> 3 | N15: =SUMIFS($G$27:$G$86,$A$27:$A$86,11) -> 3 | O15: =SUMIFS($G$27:$G$86,$A$27:$A$86,12) -> 3 | P15: =SUMIFS($G$27:$G$86,$A$27:$A$86,13) -> 3 | Q15: =SUMIFS($G$27:$G$86,$A$27:$A$86,14) -> 3 | R15: =SUMIFS($G$27:$G$86,$A$27:$A$86,15) -> 3 | S15: =SUMIFS($G$27:$G$86,$A$27:$A$86,16) -> 3 | T15: =SUMIFS($G$27:$G$86,$A$27:$A$86,17) -> 3 | U15: =SUMIFS($G$27:$G$86,$A$27:$A$86,18) -> 3 | V15: =SUMIFS($G$27:$G$86,$A$27:$A$86,19) -> 3 | W15: =SUMIFS($G$27:$G$86,$A$27:$A$86,20) -> 3 | X15: =G15 -> 3 | Y15: =K15 -> 3 | Z15: =O15 -> 3 | AA15: =S15 -> 3 | AB15: =W15 -> 3
A16: Total Average FTE | B16: Formula output from payroll detail | C16: =SUMIFS($H$27:$H$86,$A$27:$A$86,0) -> 0 | D16: =SUMIFS($H$27:$H$86,$A$27:$A$86,1) -> 3 | E16: =SUMIFS($H$27:$H$86,$A$27:$A$86,2) -> 3 | F16: =SUMIFS($H$27:$H$86,$A$27:$A$86,3) -> 3 | G16: =SUMIFS($H$27:$H$86,$A$27:$A$86,4) -> 3 | H16: =SUMIFS($H$27:$H$86,$A$27:$A$86,5) -> 3 | I16: =SUMIFS($H$27:$H$86,$A$27:$A$86,6) -> 3 | J16: =SUMIFS($H$27:$H$86,$A$27:$A$86,7) -> 3 | K16: =SUMIFS($H$27:$H$86,$A$27:$A$86,8) -> 3 | L16: =SUMIFS($H$27:$H$86,$A$27:$A$86,9) -> 3 | M16: =SUMIFS($H$27:$H$86,$A$27:$A$86,10) -> 3 | N16: =SUMIFS($H$27:$H$86,$A$27:$A$86,11) -> 3 | O16: =SUMIFS($H$27:$H$86,$A$27:$A$86,12) -> 3 | P16: =SUMIFS($H$27:$H$86,$A$27:$A$86,13) -> 3 | Q16: =SUMIFS($H$27:$H$86,$A$27:$A$86,14) -> 3 | R16: =SUMIFS($H$27:$H$86,$A$27:$A$86,15) -> 3 | S16: =SUMIFS($H$27:$H$86,$A$27:$A$86,16) -> 3 | T16: =SUMIFS($H$27:$H$86,$A$27:$A$86,17) -> 3 | U16: =SUMIFS($H$27:$H$86,$A$27:$A$86,18) -> 3 | V16: =SUMIFS($H$27:$H$86,$A$27:$A$86,19) -> 3 | W16: =SUMIFS($H$27:$H$86,$A$27:$A$86,20) -> 3 | X16: =AVERAGE(D16:G16) -> 3 | Y16: =AVERAGE(H16:K16) -> 3 | Z16: =AVERAGE(L16:O16) -> 3 | AA16: =AVERAGE(P16:S16) -> 3 | AB16: =AVERAGE(T16:W16) -> 3
A17: Total Payroll | B17: Formula output from payroll detail | C17: =SUMIFS($M$27:$M$86,$A$27:$A$86,0) -> 0 | D17: =SUMIFS($M$27:$M$86,$A$27:$A$86,1) -> 115547.95 | E17: =SUMIFS($M$27:$M$86,$A$27:$A$86,2) -> 115547.95 | F17: =SUMIFS($M$27:$M$86,$A$27:$A$86,3) -> 115547.95 | G17: =SUMIFS($M$27:$M$86,$A$27:$A$86,4) -> 115547.95 | H17: =SUMIFS($M$27:$M$86,$A$27:$A$86,5) -> 119014.33 | I17: =SUMIFS($M$27:$M$86,$A$27:$A$86,6) -> 119014.33 | J17: =SUMIFS($M$27:$M$86,$A$27:$A$86,7) -> 119014.33 | K17: =SUMIFS($M$27:$M$86,$A$27:$A$86,8) -> 119014.33 | L17: =SUMIFS($M$27:$M$86,$A$27:$A$86,9) -> 122584.71 | M17: =SUMIFS($M$27:$M$86,$A$27:$A$86,10) -> 122584.71 | N17: =SUMIFS($M$27:$M$86,$A$27:$A$86,11) -> 122584.71 | O17: =SUMIFS($M$27:$M$86,$A$27:$A$86,12) -> 122584.71 | P17: =SUMIFS($M$27:$M$86,$A$27:$A$86,13) -> 126262.76 | Q17: =SUMIFS($M$27:$M$86,$A$27:$A$86,14) -> 126262.76 | R17: =SUMIFS($M$27:$M$86,$A$27:$A$86,15) -> 126262.76 | S17: =SUMIFS($M$27:$M$86,$A$27:$A$86,16) -> 126262.76 | T17: =SUMIFS($M$27:$M$86,$A$27:$A$86,17) -> 130050.35 | U17: =SUMIFS($M$27:$M$86,$A$27:$A$86,18) -> 130050.35 | V17: =SUMIFS($M$27:$M$86,$A$27:$A$86,19) -> 130050.35 | W17: =SUMIFS($M$27:$M$86,$A$27:$A$86,20) -> 130050.35 | X17: =SUM(D17:G17) -> 462191.8 | Y17: =SUM(H17:K17) -> 476057.31 | Z17: =SUM(L17:O17) -> 490338.83 | AA17: =SUM(P17:S17) -> 505051.06 | AB17: =SUM(T17:W17) -> 520201.38
A18: Total Revenue | B18: Linked from Revenue Drivers | C18: ='Revenue Drivers'!C20 -> 1528800 | D18: ='Revenue Drivers'!D20 -> 274877.56 | E18: ='Revenue Drivers'!E20 -> 277227.25 | F18: ='Revenue Drivers'!F20 -> 281912.38 | G18: ='Revenue Drivers'!G20 -> 286019.97 | H18: ='Revenue Drivers'!H20 -> 297884.01 | I18: ='Revenue Drivers'!I20 -> 299958.22 | J18: ='Revenue Drivers'!J20 -> 305514.83 | ... W18: ='Revenue Drivers'!W20 -> 639387.23 | X18: =SUM(D18:G18) -> 1120037.2 | Y18: =SUM(H18:K18) -> 1213990.5 | Z18: =SUM(L18:O18) -> 1528143.9 | AA18: =SUM(P18:S18) -> 2310993.4 | AB18: =SUM(T18:W18) -> 2520947.9
A19: Total Capacity Units | B19: Linked from Revenue Drivers | C19: ='Revenue Drivers'!C19 -> 234 | D19: ='Revenue Drivers'!D19 -> 103.08 | E19: ='Revenue Drivers'!E19 -> 103.08 | F19: ='Revenue Drivers'!F19 -> 103.08 | G19: ='Revenue Drivers'!G19 -> 103.08 | H19: ='Revenue Drivers'!H19 -> 103.08 | I19: ='Revenue Drivers'!I19 -> 103.08 | J19: ='Revenue Drivers'!J19 -> 103.08 | ... W19: ='Revenue Drivers'!W19 -> 103.08 | X19: =SUM(D19:G19) -> 412.32 | Y19: =SUM(H19:K19) -> 412.32 | Z19: =SUM(L19:O19) -> 412.32 | AA19: =SUM(P19:S19) -> 412.32 | AB19: =SUM(T19:W19) -> 412.32
A20: Revenue per Employee | B20: Python-built productivity formula | C20: =IFERROR(C18/C16,0) -> 0 | D20: =IFERROR(D18/D16,0) -> 91625.854 | E20: =IFERROR(E18/E16,0) -> 92409.083 | F20: =IFERROR(F18/F16,0) -> 93970.793 | G20: =IFERROR(G18/G16,0) -> 95339.991 | H20: =IFERROR(H18/H16,0) -> 99294.669 | I20: =IFERROR(I18/I16,0) -> 99986.072 | J20: =IFERROR(J18/J16,0) -> 101838.28 | ... AB20: =IFERROR(AB18/AB16,0) -> 840315.96
A21: Units per Employee | B21: Python-built productivity formula | C21: =IFERROR(C19/C16,0) -> 0 | D21: =IFERROR(D19/D16,0) -> 34.36 | E21: =IFERROR(E19/E16,0) -> 34.36 | F21: =IFERROR(F19/F16,0) -> 34.36 | G21: =IFERROR(G19/G16,0) -> 34.36 | H21: =IFERROR(H19/H16,0) -> 34.36 | I21: =IFERROR(I19/I16,0) -> 34.36 | J21: =IFERROR(J19/J16,0) -> 34.36 | ... AB21: =IFERROR(AB19/AB16,0) -> 137.44
A22: Payroll % of Revenue | B22: Python-built productivity formula | C22: =IFERROR(C17/C18,0) -> 0 | D22: =IFERROR(D17/D18,0) -> 0.42036152 | E22: =IFERROR(E17/E18,0) -> 0.41679867 | F22: =IFERROR(F17/F18,0) -> 0.40987186 | G22: =IFERROR(G17/G18,0) -> 0.4039856 | H22: =IFERROR(H17/H18,0) -> 0.39953245 | I22: =IFERROR(I17/I18,0) -> 0.39676969 | J22: =IFERROR(J17/J18,0) -> 0.38955335 | ... AB22: =IFERROR(AB17/AB18,0) -> 0.2063515
A25: Payroll Detail
A26: Quarter | B26: Staffing Class | C26: Title / Person | D26: OEWS Title | E26: Starting FTE | F26: Hires | G26: Ending FTE | H26: Average FTE | I26: Annual Wage | J26: Benefits % | K26: Wage Cost | L26: Taxes & Benefits | M26: Total Payroll | N26: Wage Source
A27: 1 | B27: key_person | C27: Managing Partner | E27: 1 | F27: 0 | G27: =E27+F27 -> 1 | H27: =(E27+G27)/2 -> 1 | I27: 143470 | J27: 0.22 | K27: =H27*I27/4 -> 35867.5 | L27: =K27*J27 -> 7890.85 | M27: =K27+L27 -> 43758.35 | N27: oews_median
A28: 2 | B28: key_person | C28: Managing Partner | E28: 1 | F28: 0 | G28: =E28+F28 -> 1 | H28: =(E28+G28)/2 -> 1 | I28: 143470 | J28: 0.22 | K28: =H28*I28/4 -> 35867.5 | L28: =K28*J28 -> 7890.85 | M28: =K28+L28 -> 43758.35 | N28: oews_median
A29: 3 | B29: key_person | C29: Managing Partner | E29: 1 | F29: 0 | G29: =E29+F29 -> 1 | H29: =(E29+G29)/2 -> 1 | I29: 143470 | J29: 0.22 | K29: =H29*I29/4 -> 35867.5 | L29: =K29*J29 -> 7890.85 | M29: =K29+L29 -> 43758.35 | N29: oews_median
A30: 4 | B30: key_person | C30: Managing Partner | E30: 1 | F30: 0 | G30: =E30+F30 -> 1 | H30: =(E30+G30)/2 -> 1 | I30: 143470 | J30: 0.22 | K30: =H30*I30/4 -> 35867.5 | L30: =K30*J30 -> 7890.85 | M30: =K30+L30 -> 43758.35 | N30: oews_median
A31: 5 | B31: key_person | C31: Managing Partner | E31: 1 | F31: 0 | G31: =E31+F31 -> 1 | H31: =(E31+G31)/2 -> 1 | I31: 147774 | J31: 0.22 | K31: =H31*I31/4 -> 36943.5 | L31: =K31*J31 -> 8127.57 | M31: =K31+L31 -> 45071.07 | N31: oews_median
A32: 6 | B32: key_person | C32: Managing Partner | E32: 1 | F32: 0 | G32: =E32+F32 -> 1 | H32: =(E32+G32)/2 -> 1 | I32: 147774 | J32: 0.22 | K32: =H32*I32/4 -> 36943.5 | L32: =K32*J32 -> 8127.57 | M32: =K32+L32 -> 45071.07 | N32: oews_median
A33: 7 | B33: key_person | C33: Managing Partner | E33: 1 | F33: 0 | G33: =E33+F33 -> 1 | H33: =(E33+G33)/2 -> 1 | I33: 147774 | J33: 0.22 | K33: =H33*I33/4 -> 36943.5 | L33: =K33*J33 -> 8127.57 | M33: =K33+L33 -> 45071.07 | N33: oews_median
A34: 8 | B34: key_person | C34: Managing Partner | E34: 1 | F34: 0 | G34: =E34+F34 -> 1 | H34: =(E34+G34)/2 -> 1 | I34: 147774 | J34: 0.22 | K34: =H34*I34/4 -> 36943.5 | L34: =K34*J34 -> 8127.57 | M34: =K34+L34 -> 45071.07 | N34: oews_median
A35: 9 | B35: key_person | C35: Managing Partner | E35: 1 | F35: 0 | G35: =E35+F35 -> 1 | H35: =(E35+G35)/2 -> 1 | I35: 152207 | J35: 0.22 | K35: =H35*I35/4 -> 38051.75 | L35: =K35*J35 -> 8371.385 | M35: =K35+L35 -> 46423.135 | N35: oews_median
A36: 10 | B36: key_person | C36: Managing Partner | E36: 1 | F36: 0 | G36: =E36+F36 -> 1 | H36: =(E36+G36)/2 -> 1 | I36: 152207 | J36: 0.22 | K36: =H36*I36/4 -> 38051.75 | L36: =K36*J36 -> 8371.385 | M36: =K36+L36 -> 46423.135 | N36: oews_median
A37: 11 | B37: key_person | C37: Managing Partner | E37: 1 | F37: 0 | G37: =E37+F37 -> 1 | H37: =(E37+G37)/2 -> 1 | I37: 152207 | J37: 0.22 | K37: =H37*I37/4 -> 38051.75 | L37: =K37*J37 -> 8371.385 | M37: =K37+L37 -> 46423.135 | N37: oews_median
A38: 12 | B38: key_person | C38: Managing Partner | E38: 1 | F38: 0 | G38: =E38+F38 -> 1 | H38: =(E38+G38)/2 -> 1 | I38: 152207 | J38: 0.22 | K38: =H38*I38/4 -> 38051.75 | L38: =K38*J38 -> 8371.385 | M38: =K38+L38 -> 46423.135 | N38: oews_median
... A66: 20 | B66: key_person | C66: Partner | E66: 1 | F66: 0 | G66: =E66+F66 -> 1 | H66: =(E66+G66)/2 -> 1 | I66: 161477 | J66: 0.22 | K66: =H66*I66/4 -> 40369.25 | L66: =K66*J66 -> 8881.235 | M66: =K66+L66 -> 49250.485 | N66: oews_median
A67: 1 | B67: supporting_staff | C67: Paralegals and Legal Assistants | D67: Paralegals and Legal Assistants | E67: 1 | F67: 0 | G67: =E67+F67 -> 1 | H67: =(E67+G67)/2 -> 1 | I67: 89700 | J67: 0.25 | K67: =H67*I67/4 -> 22425 | L67: =K67*J67 -> 5606.25 | M67: =K67+L67 -> 28031.25 | N67: oews_title_catalog:oews_median
A68: 2 | B68: supporting_staff | C68: Paralegals and Legal Assistants | D68: Paralegals and Legal Assistants | E68: 1 | F68: 0 | G68: =E68+F68 -> 1 | H68: =(E68+G68)/2 -> 1 | I68: 89700 | J68: 0.25 | K68: =H68*I68/4 -> 22425 | L68: =K68*J68 -> 5606.25 | M68: =K68+L68 -> 28031.25 | N68: oews_title_catalog:oews_median
A69: 3 | B69: supporting_staff | C69: Paralegals and Legal Assistants | D69: Paralegals and Legal Assistants | E69: 1 | F69: 0 | G69: =E69+F69 -> 1 | H69: =(E69+G69)/2 -> 1 | I69: 89700 | J69: 0.25 | K69: =H69*I69/4 -> 22425 | L69: =K69*J69 -> 5606.25 | M69: =K69+L69 -> 28031.25 | N69: oews_title_catalog:oews_median
A70: 4 | B70: supporting_staff | C70: Paralegals and Legal Assistants | D70: Paralegals and Legal Assistants | E70: 1 | F70: 0 | G70: =E70+F70 -> 1 | H70: =(E70+G70)/2 -> 1 | I70: 89700 | J70: 0.25 | K70: =H70*I70/4 -> 22425 | L70: =K70*J70 -> 5606.25 | M70: =K70+L70 -> 28031.25 | N70: oews_title_catalog:oews_median
A71: 5 | B71: supporting_staff | C71: Paralegals and Legal Assistants | D71: Paralegals and Legal Assistants | E71: 1 | F71: 0 | G71: =E71+F71 -> 1 | H71: =(E71+G71)/2 -> 1 | I71: 92391 | J71: 0.25 | K71: =H71*I71/4 -> 23097.75 | L71: =K71*J71 -> 5774.4375 | M71: =K71+L71 -> 28872.188 | N71: oews_title_catalog:oews_median
...

Sheet Debt Schedule
A1: Debt Schedule
A2: Debt, interest, and capital lease mechanics. Model Inputs links to calculated outputs.
C4: Stub | D4: Q1 | E4: Q2 | F4: Q3 | G4: Q4 | H4: Q5 | I4: Q6 | J4: Q7 | K4: Q8 | L4: Q9 | M4: Q10 | N4: Q11 | O4: Q12 | P4: Q13 | Q4: Q14 | R4: Q15 | S4: Q16 | T4: Q17 | U4: Q18 | V4: Q19 | W4: Q20 | X4: Y1 | Y4: Y2 | Z4: Y3 | AA4: Y4 | AB4: Y5
C5: 46162 | D5: 46295 | E5: 46387 | F5: 46477 | G5: 46568 | H5: 46660 | I5: 46752 | J5: 46843 | K5: 46934 | L5: 47026 | M5: 47118 | N5: 47208 | O5: 47299 | P5: 47391 | Q5: 47483 | R5: 47573 | S5: 47664 | T5: 47756 | U5: 47848 | V5: 47938 | W5: 48029 | X5: Annual | Y5: Annual | Z5: Annual | AA5: Annual | AB5: Annual
A6: Debt Amortization
A7: Opening Debt | B7: Calculated | C7: 0 | D7: =C11 -> 0 | E7: =D11 -> 0 | F7: =E11 -> 0 | G7: =F11 -> 0 | H7: =G11 -> 0 | I7: =H11 -> 0 | J7: =I11 -> 0 | K7: =J11 -> 0 | ... W7: =V11 -> 0 | X7: =G7 -> 0 | Y7: =K7 -> 0 | Z7: =O7 -> 0 | AA7: =S7 -> 0 | AB7: =W7 -> 0
A8: Debt Issuance | B8: Source borrowing | C8: 0 | D8: 0 | E8: 0 | F8: 0 | G8: 0 | H8: 0 | I8: 0 | J8: 0 | K8: 0 | L8: 0 | M8: 0 | N8: 0 | O8: 0 | P8: 0 | Q8: 0 | R8: 0 | S8: 0 | T8: 0 | U8: 0 | V8: 0 | W8: 0 | X8: =SUM(D8:G8) -> 0 | Y8: =SUM(H8:K8) -> 0 | Z8: =SUM(L8:O8) -> 0 | AA8: =SUM(P8:S8) -> 0 | AB8: =SUM(T8:W8) -> 0
A9: Requested Debt Repayment | B9: Source scheduled repayment | C9: 0 | D9: 0 | E9: 0 | F9: 0 | G9: 0 | H9: 0 | I9: 0 | J9: 0 | K9: 0 | L9: 0 | M9: 0 | N9: 0 | O9: 0 | P9: 0 | Q9: 0 | R9: 0 | S9: 0 | T9: 0 | U9: 0 | V9: 0 | W9: 0 | X9: =SUM(D9:G9) -> 0 | Y9: =SUM(H9:K9) -> 0 | Z9: =SUM(L9:O9) -> 0 | AA9: =SUM(P9:S9) -> 0 | AB9: =SUM(T9:W9) -> 0
A10: Actual Debt Repayment | B10: MIN(requested repayment, opening debt + issuance) | C10: =MIN(C9,C7+C8) -> 0 | D10: =MIN(D9,D7+D8) -> 0 | E10: =MIN(E9,E7+E8) -> 0 | F10: =MIN(F9,F7+F8) -> 0 | G10: =MIN(G9,G7+G8) -> 0 | H10: =MIN(H9,H7+H8) -> 0 | I10: =MIN(I9,I7+I8) -> 0 | J10: =MIN(J9,J7+J8) -> 0 | ... W10: =MIN(W9,W7+W8) -> 0 | X10: =SUM(D10:G10) -> 0 | Y10: =SUM(H10:K10) -> 0 | Z10: =SUM(L10:O10) -> 0 | AA10: =SUM(P10:S10) -> 0 | AB10: =SUM(T10:W10) -> 0
A11: Closing Debt | B11: Calculated | C11: =MAX(0,C7+C8-C10) -> 0 | D11: =MAX(0,D7+D8-D10) -> 0 | E11: =MAX(0,E7+E8-E10) -> 0 | F11: =MAX(0,F7+F8-F10) -> 0 | G11: =MAX(0,G7+G8-G10) -> 0 | H11: =MAX(0,H7+H8-H10) -> 0 | I11: =MAX(0,I7+I8-I10) -> 0 | J11: =MAX(0,J7+J8-J10) -> 0 | ... W11: =MAX(0,W7+W8-W10) -> 0 | X11: =G11 -> 0 | Y11: =K11 -> 0 | Z11: =O11 -> 0 | AA11: =S11 -> 0 | AB11: =W11 -> 0
A12: Interest Rate | B12: Source rate | C12: 0 | D12: 0.023813 | E12: 0.023813 | F12: 0.023813 | G12: 0.023813 | H12: 0.023813 | I12: 0.023813 | J12: 0.023813 | K12: 0.023813 | L12: 0.023813 | M12: 0.023813 | N12: 0.023813 | O12: 0.023813 | P12: 0.023813 | Q12: 0.023813 | R12: 0.023813 | S12: 0.023813 | T12: 0.023813 | U12: 0.023813 | V12: 0.023813 | W12: 0.023813 | X12: =SUM(D12:G12) -> 0.095252 | Y12: =SUM(H12:K12) -> 0.095252 | Z12: =SUM(L12:O12) -> 0.095252 | AA12: =SUM(P12:S12) -> 0.095252 | AB12: =SUM(T12:W12) -> 0.095252
A13: Interest Expense | B13: Average debt balance x rate | C13: =((C7+C11)/2)*C12 -> 0 | D13: =((D7+D11)/2)*D12 -> 0 | E13: =((E7+E11)/2)*E12 -> 0 | F13: =((F7+F11)/2)*F12 -> 0 | G13: =((G7+G11)/2)*G12 -> 0 | H13: =((H7+H11)/2)*H12 -> 0 | I13: =((I7+I11)/2)*I12 -> 0 | J13: =((J7+J11)/2)*J12 -> 0 | ... W13: =((W7+W11)/2)*W12 -> 0 | X13: =SUM(D13:G13) -> 0 | Y13: =SUM(H13:K13) -> 0 | Z13: =SUM(L13:O13) -> 0 | AA13: =SUM(P13:S13) -> 0 | AB13: =SUM(T13:W13) -> 0
A14: Total Debt Service | B14: Interest + actual repayment | C14: =C13+C10 -> 0 | D14: =D13+D10 -> 0 | E14: =E13+E10 -> 0 | F14: =F13+F10 -> 0 | G14: =G13+G10 -> 0 | H14: =H13+H10 -> 0 | I14: =I13+I10 -> 0 | J14: =J13+J10 -> 0 | ... W14: =W13+W10 -> 0 | X14: =SUM(D14:G14) -> 0 | Y14: =SUM(H14:K14) -> 0 | Z14: =SUM(L14:O14) -> 0 | AA14: =SUM(P14:S14) -> 0 | AB14: =SUM(T14:W14) -> 0
A17: Capital Lease Schedule
A18: Lease Opening Balance | B18: Capital leases | C18: 0 | D18: =C23 -> 0 | E18: =D23 -> 0 | F18: =E23 -> 0 | G18: =F23 -> 0 | H18: =G23 -> 0 | I18: =H23 -> 0 | J18: =I23 -> 0 | K18: =J23 -> 0 | ... W18: =V23 -> 0 | X18: =G18 -> 0 | Y18: =K18 -> 0 | Z18: =O18 -> 0 | AA18: =S18 -> 0 | AB18: =W18 -> 0
A19: Requested Lease Principal Repayments | B19: Capital leases | C19: 0 | D19: 0 | E19: 0 | F19: 0 | G19: 0 | H19: 0 | I19: 0 | J19: 0 | K19: 0 | L19: 0 | M19: 0 | N19: 0 | O19: 0 | P19: 0 | Q19: 0 | R19: 0 | S19: 0 | T19: 0 | U19: 0 | V19: 0 | W19: 0 | X19: =SUM(D19:G19) -> 0 | Y19: =SUM(H19:K19) -> 0 | Z19: =SUM(L19:O19) -> 0 | AA19: =SUM(P19:S19) -> 0 | AB19: =SUM(T19:W19) -> 0
A20: Lease Principal Repayments | B20: Capital leases | C20: =MIN(C19,C18+C21) -> 0 | D20: =MIN(D19,D18+D21) -> 0 | E20: =MIN(E19,E18+E21) -> 0 | F20: =MIN(F19,F18+F21) -> 0 | G20: =MIN(G19,G18+G21) -> 0 | H20: =MIN(H19,H18+H21) -> 0 | I20: =MIN(I19,I18+I21) -> 0 | J20: =MIN(J19,J18+J21) -> 0 | ... W20: =MIN(W19,W18+W21) -> 0 | X20: =SUM(D20:G20) -> 0 | Y20: =SUM(H20:K20) -> 0 | Z20: =SUM(L20:O20) -> 0 | AA20: =SUM(P20:S20) -> 0 | AB20: =SUM(T20:W20) -> 0
A21: Lease Net Additions | B21: Capital leases | C21: 0 | D21: 0 | E21: 0 | F21: 0 | G21: 0 | H21: 0 | I21: 0 | J21: 0 | K21: 0 | L21: 0 | M21: 0 | N21: 0 | O21: 0 | P21: 0 | Q21: 0 | R21: 0 | S21: 0 | T21: 0 | U21: 0 | V21: 0 | W21: 0 | X21: =SUM(D21:G21) -> 0 | Y21: =SUM(H21:K21) -> 0 | Z21: =SUM(L21:O21) -> 0 | AA21: =SUM(P21:S21) -> 0 | AB21: =SUM(T21:W21) -> 0
A22: Lease Interest Expense | B22: Capital leases | C22: 0 | D22: =D18*D12 -> 0 | E22: =E18*E12 -> 0 | F22: =F18*F12 -> 0 | G22: =G18*G12 -> 0 | H22: =H18*H12 -> 0 | I22: =I18*I12 -> 0 | J22: =J18*J12 -> 0 | K22: =K18*K12 -> 0 | ... W22: =W18*W12 -> 0 | X22: =SUM(D22:G22) -> 0 | Y22: =SUM(H22:K22) -> 0 | Z22: =SUM(L22:O22) -> 0 | AA22: =SUM(P22:S22) -> 0 | AB22: =SUM(T22:W22) -> 0
A23: Lease Closing Balance | B23: Capital leases | C23: =MAX(0,C18+C21-C20) -> 0 | D23: =MAX(0,D18+D21-D20) -> 0 | E23: =MAX(0,E18+E21-E20) -> 0 | F23: =MAX(0,F18+F21-F20) -> 0 | G23: =MAX(0,G18+G21-G20) -> 0 | H23: =MAX(0,H18+H21-H20) -> 0 | I23: =MAX(0,I18+I21-I20) -> 0 | J23: =MAX(0,J18+J21-J20) -> 0 | ... W23: =MAX(0,W18+W21-W20) -> 0 | X23: =G23 -> 0 | Y23: =K23 -> 0 | Z23: =O23 -> 0 | AA23: =S23 -> 0 | AB23: =W23 -> 0
A24: Right-of-Use Asset Opening | B24: Capital leases | C24: 0 | D24: =C26 -> 0 | E24: =D26 -> 0 | F24: =E26 -> 0 | G24: =F26 -> 0 | H24: =G26 -> 0 | I24: =H26 -> 0 | J24: =I26 -> 0 | K24: =J26 -> 0 | ... W24: =V26 -> 0 | X24: =G24 -> 0 | Y24: =K24 -> 0 | Z24: =O24 -> 0 | AA24: =S24 -> 0 | AB24: =W24 -> 0
A25: Lease Asset Depreciation | B25: Capital leases | C25: 0 | D25: =MIN((C18/20),D24) -> 0 | E25: =MIN((C18/20),E24) -> 0 | F25: =MIN((C18/20),F24) -> 0 | G25: =MIN((C18/20),G24) -> 0 | H25: =MIN((C18/20),H24) -> 0 | I25: =MIN((C18/20),I24) -> 0 | J25: =MIN((C18/20),J24) -> 0 | K25: =MIN((C18/20),K24) -> 0 | L25: =MIN((C18/20),L24) -> 0 | M25: =MIN((C18/20),M24) -> 0 | N25: =MIN((C18/20),N24) -> 0 | O25: =MIN((C18/20),O24) -> 0 | P25: =MIN((C18/20),P24) -> 0 | Q25: =MIN((C18/20),Q24) -> 0 | R25: =MIN((C18/20),R24) -> 0 | S25: =MIN((C18/20),S24) -> 0 | T25: =MIN((C18/20),T24) -> 0 | U25: =MIN((C18/20),U24) -> 0 | V25: =MIN((C18/20),V24) -> 0 | W25: =MIN((C18/20),W24) -> 0 | X25: =SUM(D25:G25) -> 0 | Y25: =SUM(H25:K25) -> 0 | Z25: =SUM(L25:O25) -> 0 | AA25: =SUM(P25:S25) -> 0 | AB25: =SUM(T25:W25) -> 0
A26: Right-of-Use Asset Closing | B26: Capital leases | C26: =MAX(0,C24-C25) -> 0 | D26: =MAX(0,D24-D25) -> 0 | E26: =MAX(0,E24-E25) -> 0 | F26: =MAX(0,F24-F25) -> 0 | G26: =MAX(0,G24-G25) -> 0 | H26: =MAX(0,H24-H25) -> 0 | I26: =MAX(0,I24-I25) -> 0 | J26: =MAX(0,J24-J25) -> 0 | ... W26: =MAX(0,W24-W25) -> 0 | X26: =G26 -> 0 | Y26: =K26 -> 0 | Z26: =O26 -> 0 | AA26: =S26 -> 0 | AB26: =W26 -> 0

Sheet CapEx Depreciation
A1: CapEx & Depreciation Schedule
A2: Capital expenditure and depreciation mechanics. Model Inputs links to calculated outputs.
C4: Stub | D4: Q1 | E4: Q2 | F4: Q3 | G4: Q4 | H4: Q5 | I4: Q6 | J4: Q7 | K4: Q8 | L4: Q9 | M4: Q10 | N4: Q11 | O4: Q12 | P4: Q13 | Q4: Q14 | R4: Q15 | S4: Q16 | T4: Q17 | U4: Q18 | V4: Q19 | W4: Q20 | X4: Y1 | Y4: Y2 | Z4: Y3 | AA4: Y4 | AB4: Y5
C5: 46162 | D5: 46295 | E5: 46387 | F5: 46477 | G5: 46568 | H5: 46660 | I5: 46752 | J5: 46843 | K5: 46934 | L5: 47026 | M5: 47118 | N5: 47208 | O5: 47299 | P5: 47391 | Q5: 47483 | R5: 47573 | S5: 47664 | T5: 47756 | U5: 47848 | V5: 47938 | W5: 48029 | X5: Annual | Y5: Annual | Z5: Annual | AA5: Annual | AB5: Annual
A6: PPE and Depreciation
A7: Opening PPE | B7: Calculated | C7: 40000 | D7: =C12 -> 40000 | E7: =D12 -> 40190 | F7: =E12 -> 40370.895 | G7: =F12 -> 40542.593 | H7: =G12 -> 40705.047 | I7: =H12 -> 40858.138 | J7: =I12 -> 41001.755 | K7: =J12 -> 41135.831 | ... W7: =V12 -> 41973.955 | X7: =G7 -> 40542.593 | Y7: =K7 -> 41135.831 | Z7: =O7 -> 41575.259 | AA7: =S7 -> 41856.096 | AB7: =W7 -> 41973.955
A8: Capital Expenditures | B8: Schedule source | C8: 0 | D8: 200 | E8: 200.95 | F8: 201.85448 | G8: 202.71296 | H8: 203.52523 | I8: 204.29069 | J8: 205.00877 | K8: 205.67915 | L8: 206.30154 | M8: 206.87547 | N8: 207.40052 | O8: 207.87629 | P8: 208.30265 | Q8: 208.67905 | R8: 209.00501 | S8: 209.28048 | T8: 209.50504 | U8: 209.6783 | V8: 209.79991 | W8: 209.86977 | X8: =SUM(D8:G8) -> 805.51744 | Y8: =SUM(H8:K8) -> 818.50385 | Z8: =SUM(L8:O8) -> 828.45382 | AA8: =SUM(P8:S8) -> 835.26719 | AB8: =SUM(T8:W8) -> 838.85302
A9: Lease Additions | B9: Schedule source | C9: 0 | D9: ='Debt Schedule'!D21 -> 0 | E9: ='Debt Schedule'!E21 -> 0 | F9: ='Debt Schedule'!F21 -> 0 | G9: ='Debt Schedule'!G21 -> 0 | H9: ='Debt Schedule'!H21 -> 0 | I9: ='Debt Schedule'!I21 -> 0 | J9: ='Debt Schedule'!J21 -> 0 | K9: ='Debt Schedule'!K21 -> 0 | ... W9: ='Debt Schedule'!W21 -> 0 | X9: =SUM(D9:G9) -> 0 | Y9: =SUM(H9:K9) -> 0 | Z9: =SUM(L9:O9) -> 0 | AA9: =SUM(P9:S9) -> 0 | AB9: =SUM(T9:W9) -> 0
A10: Depreciation Rate | B10: Schedule source | C10: 0 | D10: 0.00025 | E10: 0.000499 | F10: 0.000747 | G10: 0.000993 | H10: 0.001239 | I10: 0.001485 | J10: 0.00173 | K10: 0.001974 | L10: 0.002218 | M10: 0.002462 | N10: 0.002706 | O10: 0.002949 | P10: 0.003193 | Q10: 0.003438 | R10: 0.003682 | S10: 0.003927 | T10: 0.004173 | U10: 0.00442 | V10: 0.004667 | W10: 0.004916 | X10: =SUM(D10:G10) -> 0.002489 | Y10: =SUM(H10:K10) -> 0.006428 | Z10: =SUM(L10:O10) -> 0.010335 | AA10: =SUM(P10:S10) -> 0.01424 | AB10: =SUM(T10:W10) -> 0.018176
A11: Depreciation Expense | B11: Calculated | C11: =MIN(C7*C10,C7) -> 0 | D11: =MIN(D7*D10,D7) -> 10 | E11: =MIN(E7*E10,E7) -> 20.05481 | F11: =MIN(F7*F10,F7) -> 30.157059 | G11: =MIN(G7*G10,G7) -> 40.258794 | H11: =MIN(H7*H10,H7) -> 50.433553 | I11: =MIN(I7*I10,I7) -> 60.674336 | J11: =MIN(J7*J10,J7) -> 70.933036 | ... W11: =MIN(W7*W10,W7) -> 206.34396 | X11: =SUM(D11:G11) -> 100.47066 | Y11: =SUM(H11:K11) -> 263.24305 | Z11: =SUM(L11:O11) -> 428.23144 | AA11: =SUM(P11:S11) -> 594.78996 | AB11: =SUM(T11:W11) -> 762.37971
A12: Closing PPE | B12: Calculated | C12: =MAX(0,C7+C8+C9-C11) -> 40000 | D12: =MAX(0,D7+D8+D9-D11) -> 40190 | E12: =MAX(0,E7+E8+E9-E11) -> 40370.895 | F12: =MAX(0,F7+F8+F9-F11) -> 40542.593 | G12: =MAX(0,G7+G8+G9-G11) -> 40705.047 | H12: =MAX(0,H7+H8+H9-H11) -> 40858.138 | I12: =MAX(0,I7+I8+I9-I11) -> 41001.755 | J12: =MAX(0,J7+J8+J9-J11) -> 41135.831 | ... W12: =MAX(0,W7+W8+W9-W11) -> 41977.48 | X12: =G12 -> 40705.047 | Y12: =K12 -> 41260.308 | Z12: =O12 -> 41660.53 | AA12: =S12 -> 41901.007 | AB12: =W12 -> 41977.48
A13: Opening Accumulated Depreciation | B13: Calculated | C13: 0 | D13: =C14 -> 0 | E13: =D14 -> -10 | F13: =E14 -> -30.05481 | G13: =F14 -> -60.211869 | H13: =G14 -> -100.47066 | I13: =H14 -> -150.90422 | J13: =I14 -> -211.57855 | K13: =J14 -> -282.51159 | ... W13: =V14 -> -1942.7709 | X13: =G13 -> -60.211869 | Y13: =K13 -> -282.51159 | Z13: =O13 -> -669.33972 | AA13: =S13 -> -1222.3662 | AB13: =W13 -> -1942.7709
A14: Accumulated Depreciation | B14: Calculated | C14: =C13-C11 -> 0 | D14: =D13-D11 -> -10 | E14: =E13-E11 -> -30.05481 | F14: =F13-F11 -> -60.211869 | G14: =G13-G11 -> -100.47066 | H14: =H13-H11 -> -150.90422 | I14: =I13-I11 -> -211.57855 | J14: =J13-J11 -> -282.51159 | ... W14: =W13-W11 -> -2149.1148 | X14: =G14 -> -100.47066 | Y14: =K14 -> -363.71372 | Z14: =O14 -> -791.94516 | AA14: =S14 -> -1386.7351 | AB14: =W14 -> -2149.1148

Sheet Working Capital
A1: Working Capital Schedule
A2: Working-capital drivers. Model Inputs links to these source rows.
C4: Stub | D4: Q1 | E4: Q2 | F4: Q3 | G4: Q4 | H4: Q5 | I4: Q6 | J4: Q7 | K4: Q8 | L4: Q9 | M4: Q10 | N4: Q11 | O4: Q12 | P4: Q13 | Q4: Q14 | R4: Q15 | S4: Q16 | T4: Q17 | U4: Q18 | V4: Q19 | W4: Q20 | X4: Y1 | Y4: Y2 | Z4: Y3 | AA4: Y4 | AB4: Y5
C5: 46162 | D5: 46295 | E5: 46387 | F5: 46477 | G5: 46568 | H5: 46660 | I5: 46752 | J5: 46843 | K5: 46934 | L5: 47026 | M5: 47118 | N5: 47208 | O5: 47299 | P5: 47391 | Q5: 47483 | R5: 47573 | S5: 47664 | T5: 47756 | U5: 47848 | V5: 47938 | W5: 48029 | X5: Annual | Y5: Annual | Z5: Annual | AA5: Annual | AB5: Annual
A6: Working Capital Drivers
A7: Accounts Receivable Days | B7: Working capital driver | C7: 0 | D7: 30 | E7: 40.918175 | F7: 40.918175 | G7: 40.918175 | H7: 40.918175 | I7: 40.918175 | J7: 40.918175 | K7: 40.918175 | L7: 40.918175 | M7: 40.918175 | N7: 40.918175 | O7: 40.918175 | P7: 40.918175 | Q7: 40.918175 | R7: 40.918175 | S7: 40.918175 | T7: 40.918175 | U7: 40.918175 | V7: 40.918175 | W7: 40.918175
A8: Inventory Days | B8: Working capital driver | C8: 0 | D8: 87.338516 | E8: 38.363792 | F8: 36.246985 | G8: 43.193839 | H8: 50.091365 | I8: 54.001195 | J8: 54.914438 | K8: 58.653383 | L8: 65.001325 | M8: 68.472739 | N8: 57.859672 | O8: 57.220096 | P8: 60.092872 | Q8: 61.160118 | R8: 58.232636 | S8: 62.555872 | T8: 67.389344 | U8: 69.496631 | V8: 67.333483 | W8: 71.66529
A9: Accounts Payable Days | B9: Working capital driver | C9: 0 | D9: 41.7 | E9: 45.544202 | F9: 43.522382 | G9: 43.306918 | H9: 44.763831 | I9: 44.676717 | J9: 43.861467 | K9: 45.768117 | L9: 54.123774 | M9: 59.769253 | N9: 72.201373 | O9: 78.849582 | P9: 82.052104 | Q9: 84.986986 | R9: 84.986986 | S9: 84.986986 | T9: 84.986986 | U9: 84.986986 | V9: 84.986986 | W9: 84.986986
A10: Prepaid Expenses (% of Revenue) | B10: Working capital driver | C10: 0 | D10: 0.02 | E10: 0.028269 | F10: 0.028269 | G10: 0.028269 | H10: 0.028269 | I10: 0.028269 | J10: 0.028269 | K10: 0.028673 | L10: 0.030024 | M10: 0.03108 | N10: 0.028269 | O10: 0.028269 | P10: 0.028269 | Q10: 0.028269 | R10: 0.028269 | S10: 0.028864 | T10: 0.030454 | U10: 0.031405 | V10: 0.031116 | W10: 0.032856
A11: Deferred Revenue (% of Revenue) | B11: Working capital driver | C11: 0 | D11: 0.15 | E11: 0.108048 | F11: 0.092136 | G11: 0.090163 | H11: 0.095003 | I11: 0.094688 | J11: 0.09191 | K11: 0.098403 | L11: 0.126861 | M11: 0.146088 | N11: 0.18843 | O11: 0.211072 | P11: 0.221979 | Q11: 0.231975 | R11: 0.231975 | S11: 0.231975 | T11: 0.231975 | U11: 0.231975 | V11: 0.231975 | W11: 0.231975
A12: Short Term Debt (% of LTD) | B12: Working capital driver | C12: 0 | D12: 0 | E12: 0 | F12: 0 | G12: 0 | H12: 0 | I12: 0 | J12: 0 | K12: 0 | L12: 0 | M12: 0 | N12: 0 | O12: 0 | P12: 0 | Q12: 0 | R12: 0 | S12: 0 | T12: 0 | U12: 0 | V12: 0 | W12: 0
A14: Opening Working Capital Seeds
A15: Cash Opening Balance | B15: Opening balance seed | C15: 80000 | D15: 0 | E15: 0 | F15: 0 | G15: 0 | H15: 0 | I15: 0 | J15: 0 | K15: 0 | L15: 0 | M15: 0 | N15: 0 | O15: 0 | P15: 0 | Q15: 0 | R15: 0 | S15: 0 | T15: 0 | U15: 0 | V15: 0 | W15: 0
A16: Accounts Receivable Opening Balance | B16: Opening balance seed | C16: 12000 | D16: 0 | E16: 0 | F16: 0 | G16: 0 | H16: 0 | I16: 0 | J16: 0 | K16: 0 | L16: 0 | M16: 0 | N16: 0 | O16: 0 | P16: 0 | Q16: 0 | R16: 0 | S16: 0 | T16: 0 | U16: 0 | V16: 0 | W16: 0
A17: Inventory Opening Balance | B17: Opening balance seed | C17: 0 | D17: 0 | E17: 0 | F17: 0 | G17: 0 | H17: 0 | I17: 0 | J17: 0 | K17: 0 | L17: 0 | M17: 0 | N17: 0 | O17: 0 | P17: 0 | Q17: 0 | R17: 0 | S17: 0 | T17: 0 | U17: 0 | V17: 0 | W17: 0
A18: Accounts Payable Opening Balance | B18: Opening balance seed | C18: 0 | D18: 0 | E18: 0 | F18: 0 | G18: 0 | H18: 0 | I18: 0 | J18: 0 | K18: 0 | L18: 0 | M18: 0 | N18: 0 | O18: 0 | P18: 0 | Q18: 0 | R18: 0 | S18: 0 | T18: 0 | U18: 0 | V18: 0 | W18: 0
A19: Short Term Debt Opening Balance | B19: Opening balance seed | C19: 0 | D19: 0 | E19: 0 | F19: 0 | G19: 0 | H19: 0 | I19: 0 | J19: 0 | K19: 0 | L19: 0 | M19: 0 | N19: 0 | O19: 0 | P19: 0 | Q19: 0 | R19: 0 | S19: 0 | T19: 0 | U19: 0 | V19: 0 | W19: 0

Sheet Cash Equity Schedule
A1: Cash & Equity Schedule
A2: Equity, distributions, lease/rent, and opening cash seeds. Model Inputs links to these rows.
C4: Stub | D4: Q1 | E4: Q2 | F4: Q3 | G4: Q4 | H4: Q5 | I4: Q6 | J4: Q7 | K4: Q8 | L4: Q9 | M4: Q10 | N4: Q11 | O4: Q12 | P4: Q13 | Q4: Q14 | R4: Q15 | S4: Q16 | T4: Q17 | U4: Q18 | V4: Q19 | W4: Q20 | X4: Y1 | Y4: Y2 | Z4: Y3 | AA4: Y4 | AB4: Y5
C5: 46162 | D5: 46295 | E5: 46387 | F5: 46477 | G5: 46568 | H5: 46660 | I5: 46752 | J5: 46843 | K5: 46934 | L5: 47026 | M5: 47118 | N5: 47208 | O5: 47299 | P5: 47391 | Q5: 47483 | R5: 47573 | S5: 47664 | T5: 47756 | U5: 47848 | V5: 47938 | W5: 48029 | X5: Annual | Y5: Annual | Z5: Annual | AA5: Annual | AB5: Annual
A6: Equity and Distributions
A7: Owner's Capital | B7: Equity / distribution input | C7: 100000 | D7: 157098 | E7: 162529 | F7: 170541 | G7: 173163 | H7: 173163 | I7: 173163 | J7: 173163 | K7: 173163 | L7: 173163 | M7: 173163 | N7: 173163 | O7: 173163 | P7: 173163 | Q7: 173163 | R7: 173163 | S7: 173163 | T7: 173163 | U7: 173163 | V7: 173163 | W7: 173163
A8: Other Equity | B8: Equity / distribution input | C8: 0 | D8: 0 | E8: 0 | F8: 0 | G8: 0 | H8: 0 | I8: 0 | J8: 0 | K8: 0 | L8: 0 | M8: 0 | N8: 0 | O8: 0 | P8: 0 | Q8: 0 | R8: 0 | S8: 0 | T8: 0 | U8: 0 | V8: 0 | W8: 0
A9: Distributions | B9: Equity / distribution input | C9: 0 | D9: 0 | E9: 0 | F9: 0 | G9: 0 | H9: 0 | I9: 0 | J9: 0 | K9: 0 | L9: 0 | M9: 27903 | N9: 20347 | O9: 0 | P9: 0 | Q9: 19113 | R9: 20352 | S9: 12743 | T9: 17757 | U9: 21932 | V9: 31847 | W9: 19557
A11: Operating Fixed Cash Items
A12: Lease | B12: Operating lease/rent input | C12: 12600 | D12: 12600 | E12: 12600 | F12: 12600 | G12: 12600 | H12: 12600 | I12: 12600 | J12: 12600 | K12: 12600 | L12: 12600 | M12: 12600 | N12: 12600 | O12: 12600 | P12: 12600 | Q12: 12600 | R12: 12600 | S12: 12600 | T12: 12600 | U12: 12600 | V12: 12600 | W12: 12600

Sheet Model Inputs
A1: Model Inputs
A2: Formula-driven bridge from schedules into FINMO. FINMO references this sheet only.
C4: Stub | D4: Q1 | E4: Q2 | F4: Q3 | G4: Q4 | H4: Q5 | I4: Q6 | J4: Q7 | K4: Q8 | L4: Q9 | M4: Q10 | N4: Q11 | O4: Q12 | P4: Q13 | Q4: Q14 | R4: Q15 | S4: Q16 | T4: Q17 | U4: Q18 | V4: Q19 | W4: Q20 | X4: Y1 | Y4: Y2 | Z4: Y3 | AA4: Y4 | AB4: Y5
C5: 46162 | D5: 46295 | E5: 46387 | F5: 46477 | G5: 46568 | H5: 46660 | I5: 46752 | J5: 46843 | K5: 46934 | L5: 47026 | M5: 47118 | N5: 47208 | O5: 47299 | P5: 47391 | Q5: 47483 | R5: 47573 | S5: 47664 | T5: 47756 | U5: 47848 | V5: 47938 | W5: 48029 | X5: Annual | Y5: Annual | Z5: Annual | AA5: Annual | AB5: Annual
A6: Income Statement Inputs
A7: Corporate Legal Services / Corporate legal matter/engagement - Capacity | B7: Revenue Drivers schedule | C7: ='Revenue Drivers'!C8 -> 130 | D7: ='Revenue Drivers'!D8 -> 57.266667 | E7: ='Revenue Drivers'!E8 -> 57.266667 | F7: ='Revenue Drivers'!F8 -> 57.266667 | G7: ='Revenue Drivers'!G8 -> 57.266667 | H7: ='Revenue Drivers'!H8 -> 57.266667 | I7: ='Revenue Drivers'!I8 -> 57.266667 | J7: ='Revenue Drivers'!J8 -> 57.266667 | ... W7: ='Revenue Drivers'!W8 -> 57.266667 | X7: =SUM(D7:G7) -> 229.06667 | Y7: =SUM(H7:K7) -> 229.06667 | Z7: =SUM(L7:O7) -> 229.06667 | AA7: =SUM(P7:S7) -> 229.06667 | AB7: =SUM(T7:W7) -> 229.06667
A8: Corporate Legal Services / Corporate legal matter/engagement - Unit Price | B8: Revenue Drivers schedule | C8: ='Revenue Drivers'!C9 -> 12000 | D8: ='Revenue Drivers'!D9 -> 3228.0648 | E8: ='Revenue Drivers'!E9 -> 4687.3753 | F8: ='Revenue Drivers'!F9 -> 5633.9904 | G8: ='Revenue Drivers'!G9 -> 6458.0668 | H8: ='Revenue Drivers'!H9 -> 7175.4669 | I8: ='Revenue Drivers'!I9 -> 7800 | J8: ='Revenue Drivers'!J9 -> 8343.6876 | ... W8: ='Revenue Drivers'!W9 -> 11396.933 | X8: =SUM(D8:G8) -> 20007.497 | Y8: =SUM(H8:K8) -> 32136.15 | Z8: =SUM(L8:O8) -> 38888.611 | AA8: =SUM(P8:S8) -> 42766.881 | AB8: =SUM(T8:W8) -> 44994.362
A9: Corporate Legal Services / Corporate legal matter/engagement - Utilization | B9: Revenue Drivers schedule | C9: ='Revenue Drivers'!C10 -> 0.7 | D9: ='Revenue Drivers'!D10 -> 0.826081 | E9: ='Revenue Drivers'!E10 -> 0.737694 | F9: ='Revenue Drivers'!F10 -> 0.62412 | G9: ='Revenue Drivers'!G10 -> 0.552413 | H9: ='Revenue Drivers'!H10 -> 0.517806 | I9: ='Revenue Drivers'!I10 -> 0.479663 | J9: ='Revenue Drivers'!J10 -> 0.456714 | ... W9: ='Revenue Drivers'!W10 -> 0.699755 | X9: =SUM(D9:G9) -> 2.740308 | Y9: =SUM(H9:K9) -> 1.893621 | Z9: =SUM(L9:O9) -> 1.952179 | AA9: =SUM(P9:S9) -> 2.694526 | AB9: =SUM(T9:W9) -> 2.79531
A10: Corporate Legal Services / Corporate legal matter/engagement - Revenue | B10: Revenue Drivers schedule | C10: ='Revenue Drivers'!C11 -> 1092000 | D10: ='Revenue Drivers'!D11 -> 152709.76 | E10: ='Revenue Drivers'!E11 -> 198019.46 | F10: ='Revenue Drivers'!F11 -> 201365.99 | G10: ='Revenue Drivers'!G11 -> 204299.98 | H10: ='Revenue Drivers'!H11 -> 212774.29 | I10: ='Revenue Drivers'!I11 -> 214255.87 | J10: ='Revenue Drivers'!J11 -> 218224.88 | ... W10: ='Revenue Drivers'!W11 -> 456705.17 | X10: =SUM(D10:G10) -> 756395.19 | Y10: =SUM(H10:K10) -> 867136.05 | Z10: =SUM(L10:O10) -> 1091531.4 | AA10: =SUM(P10:S10) -> 1650709.6 | AB10: =SUM(T10:W10) -> 1800677.1
A11: Individual Legal Services / Family/estate legal matter - Capacity | B11: Revenue Drivers schedule | C11: ='Revenue Drivers'!C14 -> 104 | D11: ='Revenue Drivers'!D14 -> 45.813333 | E11: ='Revenue Drivers'!E14 -> 45.813333 | F11: ='Revenue Drivers'!F14 -> 45.813333 | G11: ='Revenue Drivers'!G14 -> 45.813333 | H11: ='Revenue Drivers'!H14 -> 45.813333 | I11: ='Revenue Drivers'!I14 -> 45.813333 | J11: ='Revenue Drivers'!J14 -> 45.813333 | ... W11: ='Revenue Drivers'!W14 -> 45.813333 | X11: =SUM(D11:G11) -> 183.25333 | Y11: =SUM(H11:K11) -> 183.25333 | Z11: =SUM(L11:O11) -> 183.25333 | AA11: =SUM(P11:S11) -> 183.25333 | AB11: =SUM(T11:W11) -> 183.25333
A12: Individual Legal Services / Family/estate legal matter - Unit Price | B12: Revenue Drivers schedule | C12: ='Revenue Drivers'!C15 -> 6000 | D12: ='Revenue Drivers'!D15 -> 3228.0648 | E12: ='Revenue Drivers'!E15 -> 2343.6876 | F12: ='Revenue Drivers'!F15 -> 2816.9952 | G12: ='Revenue Drivers'!G15 -> 3229.0334 | H12: ='Revenue Drivers'!H15 -> 3587.7335 | I12: ='Revenue Drivers'!I15 -> 3900 | J12: ='Revenue Drivers'!J15 -> 4171.8438 | ... W12: ='Revenue Drivers'!W15 -> 5698.4667 | X12: =SUM(D12:G12) -> 11617.781 | Y12: =SUM(H12:K12) -> 16068.075 | Z12: =SUM(L12:O12) -> 19444.305 | AA12: =SUM(P12:S12) -> 21383.441 | AB12: =SUM(T12:W12) -> 22497.181
A13: Individual Legal Services / Family/estate legal matter - Utilization | B13: Revenue Drivers schedule | C13: ='Revenue Drivers'!C16 -> 0.7 | D13: ='Revenue Drivers'!D16 -> 0.826081 | E13: ='Revenue Drivers'!E16 -> 0.737694 | F13: ='Revenue Drivers'!F16 -> 0.62412 | G13: ='Revenue Drivers'!G16 -> 0.552413 | H13: ='Revenue Drivers'!H16 -> 0.517806 | I13: ='Revenue Drivers'!I16 -> 0.479663 | J13: ='Revenue Drivers'!J16 -> 0.456714 | ... W13: ='Revenue Drivers'!W16 -> 0.699755 | X13: =SUM(D13:G13) -> 2.740308 | Y13: =SUM(H13:K13) -> 1.893621 | Z13: =SUM(L13:O13) -> 1.952179 | AA13: =SUM(P13:S13) -> 2.694526 | AB13: =SUM(T13:W13) -> 2.79531
A14: Individual Legal Services / Family/estate legal matter - Revenue | B14: Revenue Drivers schedule | C14: ='Revenue Drivers'!C17 -> 436800 | D14: ='Revenue Drivers'!D17 -> 122167.8 | E14: ='Revenue Drivers'!E17 -> 79207.785 | F14: ='Revenue Drivers'!F17 -> 80546.393 | G14: ='Revenue Drivers'!G17 -> 81719.992 | H14: ='Revenue Drivers'!H17 -> 85109.715 | I14: ='Revenue Drivers'!I17 -> 85702.347 | J14: ='Revenue Drivers'!J17 -> 87289.952 | ... W14: ='Revenue Drivers'!W17 -> 182682.07 | X14: =SUM(D14:G14) -> 363641.97 | Y14: =SUM(H14:K14) -> 346854.41 | Z14: =SUM(L14:O14) -> 436612.54 | AA14: =SUM(P14:S14) -> 660283.82 | AB14: =SUM(T14:W14) -> 720270.82
A15: Revenue | B15: Revenue Drivers schedule | C15: ='Revenue Drivers'!C20 -> 1528800 | D15: ='Revenue Drivers'!D20 -> 274877.56 | E15: ='Revenue Drivers'!E20 -> 277227.25 | F15: ='Revenue Drivers'!F20 -> 281912.38 | G15: ='Revenue Drivers'!G20 -> 286019.97 | H15: ='Revenue Drivers'!H20 -> 297884.01 | I15: ='Revenue Drivers'!I20 -> 299958.22 | J15: ='Revenue Drivers'!J20 -> 305514.83 | ... W15: ='Revenue Drivers'!W20 -> 639387.23 | X15: =SUM(D15:G15) -> 1120037.2 | Y15: =SUM(H15:K15) -> 1213990.5 | Z15: =SUM(L15:O15) -> 1528143.9 | AA15: =SUM(P15:S15) -> 2310993.4 | AB15: =SUM(T15:W15) -> 2520947.9
A16: Cost of Goods Sold | B16: Direct model driver | C16: 0.16 | D16: 0.2160425 | E16: 0.2160425 | F16: 0.2160425 | G16: 0.2160425 | H16: 0.2160425 | I16: 0.2160425 | J16: 0.2160425 | K16: 0.2160425 | L16: 0.2160425 | M16: 0.2160425 | N16: 0.25195658 | O16: 0.28193058 | P16: 0.29441938 | Q16: 0.303294 | R16: 0.30827632 | S16: 0.31133082 | T16: 0.31011409 | U16: 0.31167919 | V16: 0.3129074 | W16: 0.31391029 | X16: =SUM(D16:G16) -> 0.86417 | Y16: =SUM(H16:K16) -> 0.86417 | Z16: =SUM(L16:O16) -> 0.96597216 | AA16: =SUM(P16:S16) -> 1.2173205 | AB16: =SUM(T16:W16) -> 1.248611
A17: Marketing | B17: Direct model driver | C17: 0.12 | D17: 0.15641125 | E17: 0.15641125 | F17: 0.15641125 | G17: 0.15641125 | H17: 0.15641125 | I17: 0.15641125 | J17: 0.15641125 | K17: 0.15641125 | L17: 0.15641125 | M17: 0.15641125 | N17: 0.1718625 | O17: 0.18475816 | P17: 0.1901312 | Q17: 0.19394931 | R17: 0.19609284 | S17: 0.19740698 | T17: 0.1968835 | U17: 0.19755685 | V17: 0.19808526 | W17: 0.19851674 | X17: =SUM(D17:G17) -> 0.625645 | Y17: =SUM(H17:K17) -> 0.625645 | Z17: =SUM(L17:O17) -> 0.66944316 | AA17: =SUM(P17:S17) -> 0.77758032 | AB17: =SUM(T17:W17) -> 0.79104235
A18: Research & Development | B18: Direct model driver | C18: 0 | D18: 0 | E18: 0 | F18: 0 | G18: 0 | H18: 0 | I18: 0 | J18: 0 | K18: 0 | L18: 0 | M18: 0 | N18: 0 | O18: 0 | P18: 0 | Q18: 0 | R18: 0 | S18: 0 | T18: 0 | U18: 0 | V18: 0 | W18: 0 | X18: =SUM(D18:G18) -> 0 | Y18: =SUM(H18:K18) -> 0 | Z18: =SUM(L18:O18) -> 0 | AA18: =SUM(P18:S18) -> 0 | AB18: =SUM(T18:W18) -> 0
A19: Lease | B19: Cash Equity Schedule output | C19: ='Cash Equity Schedule'!C12 -> 12600 | D19: ='Cash Equity Schedule'!D12 -> 12600 | E19: ='Cash Equity Schedule'!E12 -> 12600 | F19: ='Cash Equity Schedule'!F12 -> 12600 | G19: ='Cash Equity Schedule'!G12 -> 12600 | H19: ='Cash Equity Schedule'!H12 -> 12600 | I19: ='Cash Equity Schedule'!I12 -> 12600 | J19: ='Cash Equity Schedule'!J12 -> 12600 | ... W19: ='Cash Equity Schedule'!W12 -> 12600 | X19: =SUM(D19:G19) -> 50400 | Y19: =SUM(H19:K19) -> 50400 | Z19: =SUM(L19:O19) -> 50400 | AA19: =SUM(P19:S19) -> 50400 | AB19: =SUM(T19:W19) -> 50400
A20: Payroll | B20: Payroll Schedule output | C20: 134521.88 | D20: ='Payroll Schedule'!D17 -> 115547.95 | E20: ='Payroll Schedule'!E17 -> 115547.95 | F20: ='Payroll Schedule'!F17 -> 115547.95 | G20: ='Payroll Schedule'!G17 -> 115547.95 | H20: ='Payroll Schedule'!H17 -> 119014.33 | I20: ='Payroll Schedule'!I17 -> 119014.33 | J20: ='Payroll Schedule'!J17 -> 119014.33 | K20: ='Payroll Schedule'!K17 -> 119014.33 | ... W20: ='Payroll Schedule'!W17 -> 130050.35 | X20: =SUM(D20:G20) -> 462191.8 | Y20: =SUM(H20:K20) -> 476057.31 | Z20: =SUM(L20:O20) -> 490338.83 | AA20: =SUM(P20:S20) -> 505051.06 | AB20: =SUM(T20:W20) -> 520201.38
A21: General & Administrative | B21: Direct model driver | C21: 0.000458 | D21: 0.15641125 | E21: 0.15641125 | F21: 0.15641125 | G21: 0.15641125 | H21: 0.15641125 | I21: 0.15641125 | J21: 0.15641125 | K21: 0.15641125 | L21: 0.15641125 | M21: 0.15641125 | N21: 0.1718625 | O21: 0.18475816 | P21: 0.1901312 | Q21: 0.19394931 | R21: 0.19609284 | S21: 0.19740698 | T21: 0.1968835 | U21: 0.19755685 | V21: 0.19808526 | W21: 0.19851674 | X21: =SUM(D21:G21) -> 0.625645 | Y21: =SUM(H21:K21) -> 0.625645 | Z21: =SUM(L21:O21) -> 0.66944316 | AA21: =SUM(P21:S21) -> 0.77758032 | AB21: =SUM(T21:W21) -> 0.79104235
A22: Interest Rate | B22: Debt Schedule output | C22: ='Debt Schedule'!C12 -> 0 | D22: ='Debt Schedule'!D12 -> 0.023813 | E22: ='Debt Schedule'!E12 -> 0.023813 | F22: ='Debt Schedule'!F12 -> 0.023813 | G22: ='Debt Schedule'!G12 -> 0.023813 | H22: ='Debt Schedule'!H12 -> 0.023813 | I22: ='Debt Schedule'!I12 -> 0.023813 | J22: ='Debt Schedule'!J12 -> 0.023813 | ... W22: ='Debt Schedule'!W12 -> 0.023813 | X22: =SUM(D22:G22) -> 0.095252 | Y22: =SUM(H22:K22) -> 0.095252 | Z22: =SUM(L22:O22) -> 0.095252 | AA22: =SUM(P22:S22) -> 0.095252 | AB22: =SUM(T22:W22) -> 0.095252
A23: Interest Expense | B23: Debt Schedule output | C23: 0 | D23: ='Debt Schedule'!D13 -> 0 | E23: ='Debt Schedule'!E13 -> 0 | F23: ='Debt Schedule'!F13 -> 0 | G23: ='Debt Schedule'!G13 -> 0 | H23: ='Debt Schedule'!H13 -> 0 | I23: ='Debt Schedule'!I13 -> 0 | J23: ='Debt Schedule'!J13 -> 0 | K23: ='Debt Schedule'!K13 -> 0 | ... W23: ='Debt Schedule'!W13 -> 0 | X23: =SUM(D23:G23) -> 0 | Y23: =SUM(H23:K23) -> 0 | Z23: =SUM(L23:O23) -> 0 | AA23: =SUM(P23:S23) -> 0 | AB23: =SUM(T23:W23) -> 0
A24: Depreciation | B24: CapEx Depreciation output | C24: ='CapEx Depreciation'!C10 -> 0 | D24: ='CapEx Depreciation'!D10 -> 0.00025 | E24: ='CapEx Depreciation'!E10 -> 0.000499 | F24: ='CapEx Depreciation'!F10 -> 0.000747 | G24: ='CapEx Depreciation'!G10 -> 0.000993 | H24: ='CapEx Depreciation'!H10 -> 0.001239 | I24: ='CapEx Depreciation'!I10 -> 0.001485 | J24: ='CapEx Depreciation'!J10 -> 0.00173 | ... W24: ='CapEx Depreciation'!W10 -> 0.004916 | X24: =SUM(D24:G24) -> 0.002489 | Y24: =SUM(H24:K24) -> 0.006428 | Z24: =SUM(L24:O24) -> 0.010335 | AA24: =SUM(P24:S24) -> 0.01424 | AB24: =SUM(T24:W24) -> 0.018176
A25: Depreciation Expense | B25: CapEx Depreciation output | C25: ='CapEx Depreciation'!C11 -> 0 | D25: ='CapEx Depreciation'!D11 -> 10 | E25: ='CapEx Depreciation'!E11 -> 20.05481 | F25: ='CapEx Depreciation'!F11 -> 30.157059 | G25: ='CapEx Depreciation'!G11 -> 40.258794 | H25: ='CapEx Depreciation'!H11 -> 50.433553 | I25: ='CapEx Depreciation'!I11 -> 60.674336 | J25: ='CapEx Depreciation'!J11 -> 70.933036 | ... W25: ='CapEx Depreciation'!W11 -> 206.34396 | X25: =SUM(D25:G25) -> 100.47066 | Y25: =SUM(H25:K25) -> 263.24305 | Z25: =SUM(L25:O25) -> 428.23144 | AA25: =SUM(P25:S25) -> 594.78996 | AB25: =SUM(T25:W25) -> 762.37971
A26: Taxes | B26: Direct model driver | C26: 0.204976 | D26: 0.204976 | E26: 0.204976 | F26: 0.204976 | G26: 0.204976 | H26: 0.204976 | I26: 0.204976 | J26: 0.204976 | K26: 0.204976 | L26: 0.204976 | M26: 0.204976 | N26: 0.204976 | O26: 0.204976 | P26: 0.204976 | Q26: 0.204976 | R26: 0.204976 | S26: 0.204976 | T26: 0.204976 | U26: 0.204976 | V26: 0.204976 | W26: 0.204976 | X26: =SUM(D26:G26) -> 0.819904 | Y26: =SUM(H26:K26) -> 0.819904 | Z26: =SUM(L26:O26) -> 0.819904 | AA26: =SUM(P26:S26) -> 0.819904 | AB26: =SUM(T26:W26) -> 0.819904
A28: Balance Sheet Inputs
A29: Accounts Receivable Days | B29: Working Capital schedule | C29: ='Working Capital'!C7 -> 0 | D29: ='Working Capital'!D7 -> 30 | E29: ='Working Capital'!E7 -> 40.918175 | F29: ='Working Capital'!F7 -> 40.918175 | G29: ='Working Capital'!G7 -> 40.918175 | H29: ='Working Capital'!H7 -> 40.918175 | I29: ='Working Capital'!I7 -> 40.918175 | J29: ='Working Capital'!J7 -> 40.918175 | ... W29: ='Working Capital'!W7 -> 40.918175 | X29: =SUM(D29:G29) -> 152.75452 | Y29: =SUM(H29:K29) -> 163.6727 | Z29: =SUM(L29:O29) -> 163.6727 | AA29: =SUM(P29:S29) -> 163.6727 | AB29: =SUM(T29:W29) -> 163.6727
A30: Inventory Days | B30: Working Capital schedule | C30: ='Working Capital'!C8 -> 0 | D30: ='Working Capital'!D8 -> 87.338516 | E30: ='Working Capital'!E8 -> 38.363792 | F30: ='Working Capital'!F8 -> 36.246985 | G30: ='Working Capital'!G8 -> 43.193839 | H30: ='Working Capital'!H8 -> 50.091365 | I30: ='Working Capital'!I8 -> 54.001195 | J30: ='Working Capital'!J8 -> 54.914438 | ... W30: ='Working Capital'!W8 -> 71.66529 | X30: =SUM(D30:G30) -> 205.14313 | Y30: =SUM(H30:K30) -> 217.66038 | Z30: =SUM(L30:O30) -> 248.55383 | AA30: =SUM(P30:S30) -> 242.0415 | AB30: =SUM(T30:W30) -> 275.88475
A31: Accounts Payable Days | B31: Working Capital schedule | C31: ='Working Capital'!C9 -> 0 | D31: ='Working Capital'!D9 -> 41.7 | E31: ='Working Capital'!E9 -> 45.544202 | F31: ='Working Capital'!F9 -> 43.522382 | G31: ='Working Capital'!G9 -> 43.306918 | H31: ='Working Capital'!H9 -> 44.763831 | I31: ='Working Capital'!I9 -> 44.676717 | J31: ='Working Capital'!J9 -> 43.861467 | ... W31: ='Working Capital'!W9 -> 84.986986 | X31: =SUM(D31:G31) -> 174.0735 | Y31: =SUM(H31:K31) -> 179.07013 | Z31: =SUM(L31:O31) -> 264.94398 | AA31: =SUM(P31:S31) -> 337.01306 | AB31: =SUM(T31:W31) -> 339.94794
A32: Prepaid Expenses (% of Revenue) | B32: Working Capital schedule | C32: ='Working Capital'!C10 -> 0 | D32: ='Working Capital'!D10 -> 0.02 | E32: ='Working Capital'!E10 -> 0.028269 | F32: ='Working Capital'!F10 -> 0.028269 | G32: ='Working Capital'!G10 -> 0.028269 | H32: ='Working Capital'!H10 -> 0.028269 | I32: ='Working Capital'!I10 -> 0.028269 | J32: ='Working Capital'!J10 -> 0.028269 | ... W32: ='Working Capital'!W10 -> 0.032856 | X32: =SUM(D32:G32) -> 0.104807 | Y32: =SUM(H32:K32) -> 0.11348 | Z32: =SUM(L32:O32) -> 0.117642 | AA32: =SUM(P32:S32) -> 0.113671 | AB32: =SUM(T32:W32) -> 0.125831
A33: Deferred Revenue (% of Revenue) | B33: Working Capital schedule | C33: ='Working Capital'!C11 -> 0 | D33: ='Working Capital'!D11 -> 0.15 | E33: ='Working Capital'!E11 -> 0.108048 | F33: ='Working Capital'!F11 -> 0.092136 | G33: ='Working Capital'!G11 -> 0.090163 | H33: ='Working Capital'!H11 -> 0.095003 | I33: ='Working Capital'!I11 -> 0.094688 | J33: ='Working Capital'!J11 -> 0.09191 | ... W33: ='Working Capital'!W11 -> 0.231975 | X33: =SUM(D33:G33) -> 0.440347 | Y33: =SUM(H33:K33) -> 0.380004 | Z33: =SUM(L33:O33) -> 0.672451 | AA33: =SUM(P33:S33) -> 0.917904 | AB33: =SUM(T33:W33) -> 0.9279
A34: Short Term Debt (% of LTD) | B34: Working Capital schedule | C34: ='Working Capital'!C12 -> 0 | D34: ='Working Capital'!D12 -> 0 | E34: ='Working Capital'!E12 -> 0 | F34: ='Working Capital'!F12 -> 0 | G34: ='Working Capital'!G12 -> 0 | H34: ='Working Capital'!H12 -> 0 | I34: ='Working Capital'!I12 -> 0 | J34: ='Working Capital'!J12 -> 0 | ... W34: ='Working Capital'!W12 -> 0 | X34: =SUM(D34:G34) -> 0 | Y34: =SUM(H34:K34) -> 0 | Z34: =SUM(L34:O34) -> 0 | AA34: =SUM(P34:S34) -> 0 | AB34: =SUM(T34:W34) -> 0
A35: Owner's Capital | B35: Cash Equity Schedule schedule | C35: ='Cash Equity Schedule'!C7 -> 100000 | D35: ='Cash Equity Schedule'!D7 -> 157098 | E35: ='Cash Equity Schedule'!E7 -> 162529 | F35: ='Cash Equity Schedule'!F7 -> 170541 | G35: ='Cash Equity Schedule'!G7 -> 173163 | H35: ='Cash Equity Schedule'!H7 -> 173163 | I35: ='Cash Equity Schedule'!I7 -> 173163 | J35: ='Cash Equity Schedule'!J7 -> 173163 | ... W35: ='Cash Equity Schedule'!W7 -> 173163 | X35: =G35 -> 173163 | Y35: =K35 -> 173163 | Z35: =O35 -> 173163 | AA35: =S35 -> 173163 | AB35: =W35 -> 173163
A36: Other Equity | B36: Cash Equity Schedule schedule | C36: ='Cash Equity Schedule'!C8 -> 0 | D36: ='Cash Equity Schedule'!D8 -> 0 | E36: ='Cash Equity Schedule'!E8 -> 0 | F36: ='Cash Equity Schedule'!F8 -> 0 | G36: ='Cash Equity Schedule'!G8 -> 0 | H36: ='Cash Equity Schedule'!H8 -> 0 | I36: ='Cash Equity Schedule'!I8 -> 0 | J36: ='Cash Equity Schedule'!J8 -> 0 | ... W36: ='Cash Equity Schedule'!W8 -> 0 | X36: =G36 -> 0 | Y36: =K36 -> 0 | Z36: =O36 -> 0 | AA36: =S36 -> 0 | AB36: =W36 -> 0
