Workbook

Sheet Revenue Drivers
A1: Revenue Drivers
A2: Source operating drivers. Model Inputs links to these rows.
C4: Stub | D4: Q1 | E4: Q2 | F4: Q3 | G4: Q4 | H4: Q5 | I4: Q6 | J4: Q7 | K4: Q8 | L4: Q9 | M4: Q10 | N4: Q11 | O4: Q12 | P4: Q13 | Q4: Q14 | R4: Q15 | S4: Q16 | T4: Q17 | U4: Q18 | V4: Q19 | W4: Q20 | X4: Y1 | Y4: Y2 | Z4: Y3 | AA4: Y4 | AB4: Y5
C5: 46162 | D5: 46295 | E5: 46387 | F5: 46477 | G5: 46568 | H5: 46660 | I5: 46752 | J5: 46843 | K5: 46934 | L5: 47026 | M5: 47118 | N5: 47208 | O5: 47299 | P5: 47391 | Q5: 47483 | R5: 47573 | S5: 47664 | T5: 47756 | U5: 47848 | V5: 47938 | W5: 48029 | X5: Annual | Y5: Annual | Z5: Annual | AA5: Annual | AB5: Annual
A6: Revenue Driver Source Rows
A7: Primary line of business / Billable home visit
A8: Primary line of business / Billable home visit - Capacity | B8: Source driver | C8: 1040 | D8: 2364.03 | E8: 2364.03 | F8: 2364.03 | G8: 2364.03 | H8: 2364.03 | I8: 2364.03 | J8: 2364.03 | K8: 2364.03 | L8: 2364.03 | M8: 2364.03 | N8: 2364.03 | O8: 2364.03 | P8: 2364.03 | Q8: 2364.03 | R8: 2364.03 | S8: 2364.03 | T8: 2364.03 | U8: 2364.03 | V8: 2364.03 | W8: 2364.03
A9: Primary line of business / Billable home visit - Unit Price | B9: Source driver | C9: 150 | D9: 150 | E9: 158 | F9: 166 | G9: 174 | H9: 182 | I9: 190 | J9: 198 | K9: 206 | L9: 214 | M9: 222 | N9: 230 | O9: 231.11111 | P9: 232.22222 | Q9: 233.33333 | R9: 234.44444 | S9: 235.55556 | T9: 236.66667 | U9: 237.77778 | V9: 238.88889 | W9: 240
A10: Primary line of business / Billable home visit - Utilization | B10: Source driver | C10: 0.75 | D10: 0.75 | E10: 0.759 | F10: 0.768 | G10: 0.777 | H10: 0.786 | I10: 0.795 | J10: 0.804 | K10: 0.813 | L10: 0.822 | M10: 0.831 | N10: 0.84 | O10: 0.84 | P10: 0.84 | Q10: 0.84 | R10: 0.84 | S10: 0.84 | T10: 0.84 | U10: 0.84 | V10: 0.84 | W10: 0.84
A11: Primary line of business / Billable home visit - Revenue | B11: Capacity x Unit Price x Utilization | C11: =C8*C9*C10 -> 117000 | D11: =D8*D9*D10 -> 265953.38 | E11: =E8*E9*E10 -> 283499.21 | F11: =F8*F9*F10 -> 301385.46 | G11: =G8*G9*G10 -> 319612.13 | H11: =H8*H9*H10 -> 338179.22 | I11: =I8*I9*I10 -> 357086.73 | J11: =J8*J9*J10 -> 376334.66 | ... W11: =W8*W9*W10 -> 476588.45 | X11: =SUM(D11:G11) -> 1170450.2 | Y11: =SUM(H11:K11) -> 1467523.6 | Z11: =SUM(L11:O11) -> 1767640.4 | AA11: =SUM(P11:S11) -> 1857812.4 | AB11: =SUM(T11:W11) -> 1893115.2
A13: Total Capacity Units | B13: All revenue driver capacity units | C13: =SUM(C8) -> 1040 | D13: =SUM(D8) -> 2364.03 | E13: =SUM(E8) -> 2364.03 | F13: =SUM(F8) -> 2364.03 | G13: =SUM(G8) -> 2364.03 | H13: =SUM(H8) -> 2364.03 | I13: =SUM(I8) -> 2364.03 | J13: =SUM(J8) -> 2364.03 | ... W13: =SUM(W8) -> 2364.03 | X13: =SUM(D13:G13) -> 9456.12 | Y13: =SUM(H13:K13) -> 9456.12 | Z13: =SUM(L13:O13) -> 9456.12 | AA13: =SUM(P13:S13) -> 9456.12 | AB13: =SUM(T13:W13) -> 9456.12
A14: Total Revenue | B14: All revenue products | C14: =SUM(C11) -> 117000 | D14: =SUM(D11) -> 265953.38 | E14: =SUM(E11) -> 283499.21 | F14: =SUM(F11) -> 301385.46 | G14: =SUM(G11) -> 319612.13 | H14: =SUM(H11) -> 338179.22 | I14: =SUM(I11) -> 357086.73 | J14: =SUM(J11) -> 376334.66 | ... W14: =SUM(W11) -> 476588.45 | X14: =SUM(D14:G14) -> 1170450.2 | Y14: =SUM(H14:K14) -> 1467523.6 | Z14: =SUM(L14:O14) -> 1767640.4 | AA14: =SUM(P14:S14) -> 1857812.4 | AB14: =SUM(T14:W14) -> 1893115.2
A16: Stage Ramp Contract
A17: Actual Revenue QoQ Growth | B17: Total revenue growth from modeled revenue drivers | C17: =0 -> 0 | D17: =IFERROR(D14/C14-1,0) -> 1.2731058 | E17: =IFERROR(E14/D14-1,0) -> 0.065973333 | F17: =IFERROR(F14/E14-1,0) -> 0.063091009 | G17: =IFERROR(G14/F14-1,0) -> 0.06047628 | H17: =IFERROR(H14/G14-1,0) -> 0.058092575 | I17: =IFERROR(I14/H14-1,0) -> 0.055909739 | J17: =IFERROR(J14/I14-1,0) -> 0.053902681 | K17: =IFERROR(K14/J14-1,0) -> 0.052050354 | ... W17: =IFERROR(W14/V14-1,0) -> 0.0046511623 | X17: =AVERAGE(D17:G17) -> 0.3656616 | Y17: =AVERAGE(H17:K17) -> 0.054988837 | Z17: =AVERAGE(L17:O17) -> 0.037790979 | AA17: =AVERAGE(P17:S17) -> 0.0047734062 | AB17: =AVERAGE(T17:W17) -> 0.0046839687
A18: Stage Ramp Revenue QoQ Target | B18: GPT-selected stage ramp contract | C18: 0 | D18: 0.5 | E18: 0.5 | F18: 0.5 | G18: 0.5 | H18: 0.5 | I18: 0.5 | J18: 0.5 | K18: 0.5 | L18: 0.5 | M18: 0.5 | N18: 0.5 | O18: 0.5 | P18: 0.5 | Q18: 0.5 | R18: 0.5 | S18: 0.5 | T18: 0.5 | U18: 0.5 | V18: 0.5 | W18: 0.5 | X18: =AVERAGE(D18:G18) -> 0.5 | Y18: =AVERAGE(H18:K18) -> 0.5 | Z18: =AVERAGE(L18:O18) -> 0.5 | AA18: =AVERAGE(P18:S18) -> 0.5 | AB18: =AVERAGE(T18:W18) -> 0.5
A19: Stage Ramp Revenue QoQ Max | B19: GPT-selected stage ramp contract | C19: 0 | D19: 0.75 | E19: 0.75 | F19: 0.75 | G19: 0.75 | H19: 0.75 | I19: 0.75 | J19: 0.75 | K19: 0.75 | L19: 0.75 | M19: 0.75 | N19: 0.75 | O19: 0.75 | P19: 0.75 | Q19: 0.75 | R19: 0.75 | S19: 0.75 | T19: 0.75 | U19: 0.75 | V19: 0.75 | W19: 0.75 | X19: =AVERAGE(D19:G19) -> 0.75 | Y19: =AVERAGE(H19:K19) -> 0.75 | Z19: =AVERAGE(L19:O19) -> 0.75 | AA19: =AVERAGE(P19:S19) -> 0.75 | AB19: =AVERAGE(T19:W19) -> 0.75
A20: Stage Ramp Revenue QoQ Spike Max | B20: GPT-selected stage ramp contract | C20: 0 | D20: 0.75 | E20: 0.75 | F20: 0.75 | G20: 0.75 | H20: 0.75 | I20: 0.75 | J20: 0.75 | K20: 0.75 | L20: 0.75 | M20: 0.75 | N20: 0.75 | O20: 0.75 | P20: 0.75 | Q20: 0.75 | R20: 0.75 | S20: 0.75 | T20: 0.75 | U20: 0.75 | V20: 0.75 | W20: 0.75 | X20: =AVERAGE(D20:G20) -> 0.75 | Y20: =AVERAGE(H20:K20) -> 0.75 | Z20: =AVERAGE(L20:O20) -> 0.75 | AA20: =AVERAGE(P20:S20) -> 0.75 | AB20: =AVERAGE(T20:W20) -> 0.75
A21: Stage Ramp Utilization Cap | B21: GPT-selected stage ramp contract | C21: 0 | D21: 0.25 | E21: 0.31 | F21: 0.37 | G21: 0.43 | H21: 0.49 | I21: 0.55 | J21: 0.61 | K21: 0.67 | L21: 0.73 | M21: 0.79 | N21: 0.85 | O21: 0.85 | P21: 0.85 | Q21: 0.85 | R21: 0.85 | S21: 0.85 | T21: 0.85 | U21: 0.85 | V21: 0.85 | W21: 0.85 | X21: =AVERAGE(D21:G21) -> 0.34 | Y21: =AVERAGE(H21:K21) -> 0.58 | Z21: =AVERAGE(L21:O21) -> 0.805 | AA21: =AVERAGE(P21:S21) -> 0.85 | AB21: =AVERAGE(T21:W21) -> 0.85
A22: Stage Ramp COGS % Revenue Target | B22: GPT-selected stage ramp contract | C22: 0 | D22: 0.69 | E22: 0.69 | F22: 0.69 | G22: 0.69 | H22: 0.69 | I22: 0.69 | J22: 0.69 | K22: 0.69 | L22: 0.69 | M22: 0.69 | N22: 0.69 | O22: 0.69 | P22: 0.69 | Q22: 0.69 | R22: 0.69 | S22: 0.69 | T22: 0.69 | U22: 0.69 | V22: 0.69 | W22: 0.69 | X22: =AVERAGE(D22:G22) -> 0.69 | Y22: =AVERAGE(H22:K22) -> 0.69 | Z22: =AVERAGE(L22:O22) -> 0.69 | AA22: =AVERAGE(P22:S22) -> 0.69 | AB22: =AVERAGE(T22:W22) -> 0.69
A23: Stage Ramp COGS % Revenue Max | B23: GPT-selected stage ramp contract | C23: 0 | D23: 0.75 | E23: 0.75 | F23: 0.75 | G23: 0.75 | H23: 0.75 | I23: 0.75 | J23: 0.75 | K23: 0.75 | L23: 0.75 | M23: 0.75 | N23: 0.75 | O23: 0.75 | P23: 0.75 | Q23: 0.75 | R23: 0.75 | S23: 0.75 | T23: 0.75 | U23: 0.75 | V23: 0.75 | W23: 0.75 | X23: =AVERAGE(D23:G23) -> 0.75 | Y23: =AVERAGE(H23:K23) -> 0.75 | Z23: =AVERAGE(L23:O23) -> 0.75 | AA23: =AVERAGE(P23:S23) -> 0.75 | AB23: =AVERAGE(T23:W23) -> 0.75
A24: Stage Ramp Marketing % Revenue Max | B24: GPT-selected stage ramp contract | C24: 0 | D24: 0.28 | E24: 0.28 | F24: 0.28 | G24: 0.28 | H24: 0.28 | I24: 0.28 | J24: 0.28 | K24: 0.28 | L24: 0.28 | M24: 0.28 | N24: 0.28 | O24: 0.28 | P24: 0.28 | Q24: 0.28 | R24: 0.28 | S24: 0.28 | T24: 0.28 | U24: 0.28 | V24: 0.28 | W24: 0.28 | X24: =AVERAGE(D24:G24) -> 0.28 | Y24: =AVERAGE(H24:K24) -> 0.28 | Z24: =AVERAGE(L24:O24) -> 0.28 | AA24: =AVERAGE(P24:S24) -> 0.28 | AB24: =AVERAGE(T24:W24) -> 0.28
A25: Stage Ramp R&D % Revenue Max | B25: GPT-selected stage ramp contract | C25: 0 | D25: 0.02 | E25: 0.02 | F25: 0.02 | G25: 0.02 | H25: 0.02 | I25: 0.02 | J25: 0.02 | K25: 0.02 | L25: 0.02 | M25: 0.02 | N25: 0.02 | O25: 0.02 | P25: 0.02 | Q25: 0.02 | R25: 0.02 | S25: 0.02 | T25: 0.02 | U25: 0.02 | V25: 0.02 | W25: 0.02 | X25: =AVERAGE(D25:G25) -> 0.02 | Y25: =AVERAGE(H25:K25) -> 0.02 | Z25: =AVERAGE(L25:O25) -> 0.02 | AA25: =AVERAGE(P25:S25) -> 0.02 | AB25: =AVERAGE(T25:W25) -> 0.02
A26: Stage Ramp G&A % Revenue Max | B26: GPT-selected stage ramp contract | C26: 0 | D26: 0.28 | E26: 0.28 | F26: 0.28 | G26: 0.28 | H26: 0.28 | I26: 0.28 | J26: 0.28 | K26: 0.28 | L26: 0.28 | M26: 0.28 | N26: 0.28 | O26: 0.28 | P26: 0.28 | Q26: 0.28 | R26: 0.28 | S26: 0.28 | T26: 0.28 | U26: 0.28 | V26: 0.28 | W26: 0.28 | X26: =AVERAGE(D26:G26) -> 0.28 | Y26: =AVERAGE(H26:K26) -> 0.28 | Z26: =AVERAGE(L26:O26) -> 0.28 | AA26: =AVERAGE(P26:S26) -> 0.28 | AB26: =AVERAGE(T26:W26) -> 0.28
A27: Stage Ramp Lease % Revenue Max | B27: GPT-selected stage ramp contract | C27: 0 | D27: 0.04 | E27: 0.04 | F27: 0.04 | G27: 0.04 | H27: 0.04 | I27: 0.04 | J27: 0.04 | K27: 0.04 | L27: 0.04 | M27: 0.04 | N27: 0.04 | O27: 0.04 | P27: 0.04 | Q27: 0.04 | R27: 0.04 | S27: 0.04 | T27: 0.04 | U27: 0.04 | V27: 0.04 | W27: 0.04 | X27: =AVERAGE(D27:G27) -> 0.04 | Y27: =AVERAGE(H27:K27) -> 0.04 | Z27: =AVERAGE(L27:O27) -> 0.04 | AA27: =AVERAGE(P27:S27) -> 0.04 | AB27: =AVERAGE(T27:W27) -> 0.04
A28: Stage Ramp Net Income Margin Floor | B28: GPT-selected stage ramp contract | C28: 0 | D28: -0.1 | E28: -0.1 | F28: -0.1 | G28: -0.1 | H28: -0.09 | I28: -0.07 | J28: -0.06 | K28: -0.05 | L28: -0.03 | M28: -0.02 | N28: 0 | O28: 0.01 | P28: 0.01 | Q28: 0.02 | R28: 0.02 | S28: 0.03 | T28: 0.03 | U28: 0.04 | V28: 0.04 | W28: 0.05 | X28: =AVERAGE(D28:G28) -> -0.1 | Y28: =AVERAGE(H28:K28) -> -0.0675 | Z28: =AVERAGE(L28:O28) -> -0.01 | AA28: =AVERAGE(P28:S28) -> 0.02 | AB28: =AVERAGE(T28:W28) -> 0.04

Sheet Payroll Schedule
A1: Payroll Schedule
A2: OEWS-title, capacity/utilization-driven payroll source. Model Inputs links to Total Payroll.
C4: Stub | D4: Q1 | E4: Q2 | F4: Q3 | G4: Q4 | H4: Q5 | I4: Q6 | J4: Q7 | K4: Q8 | L4: Q9 | M4: Q10 | N4: Q11 | O4: Q12 | P4: Q13 | Q4: Q14 | R4: Q15 | S4: Q16 | T4: Q17 | U4: Q18 | V4: Q19 | W4: Q20 | X4: Y1 | Y4: Y2 | Z4: Y3 | AA4: Y4 | AB4: Y5
C5: 46162 | D5: 46295 | E5: 46387 | F5: 46477 | G5: 46568 | H5: 46660 | I5: 46752 | J5: 46843 | K5: 46934 | L5: 47026 | M5: 47118 | N5: 47208 | O5: 47299 | P5: 47391 | Q5: 47483 | R5: 47573 | S5: 47664 | T5: 47756 | U5: 47848 | V5: 47938 | W5: 48029 | X5: Annual | Y5: Annual | Z5: Annual | AA5: Annual | AB5: Annual
A6: Payroll Assumptions
A7: Capacity Labor Model | B7: labor_driven
A8: Labor Intensity Class | B8: medium
A9: Wage Positioning Tier | B9: market
A10: Wage Positioning Multiplier | B10: 1.2
A11: Capacity Units per Supporting FTE | B11: 606.21
A12: Target Payroll % of Revenue | B12: 0.45
A14: Quarter Summary
A15: Total Ending FTE | B15: Formula output from payroll detail | C15: =SUMIFS($G$27:$G$86,$A$27:$A$86,0) -> 0 | D15: =SUMIFS($G$27:$G$86,$A$27:$A$86,1) -> 3 | E15: =SUMIFS($G$27:$G$86,$A$27:$A$86,2) -> 3 | F15: =SUMIFS($G$27:$G$86,$A$27:$A$86,3) -> 3 | G15: =SUMIFS($G$27:$G$86,$A$27:$A$86,4) -> 3 | H15: =SUMIFS($G$27:$G$86,$A$27:$A$86,5) -> 3 | I15: =SUMIFS($G$27:$G$86,$A$27:$A$86,6) -> 3 | J15: =SUMIFS($G$27:$G$86,$A$27:$A$86,7) -> 3 | K15: =SUMIFS($G$27:$G$86,$A$27:$A$86,8) -> 3 | L15: =SUMIFS($G$27:$G$86,$A$27:$A$86,9) -> 3 | M15: =SUMIFS($G$27:$G$86,$A$27:$A$86,10) -> 3 | N15: =SUMIFS($G$27:$G$86,$A$27:$A$86,11) -> 3 | O15: =SUMIFS($G$27:$G$86,$A$27:$A$86,12) -> 3 | P15: =SUMIFS($G$27:$G$86,$A$27:$A$86,13) -> 3 | Q15: =SUMIFS($G$27:$G$86,$A$27:$A$86,14) -> 3 | R15: =SUMIFS($G$27:$G$86,$A$27:$A$86,15) -> 3 | S15: =SUMIFS($G$27:$G$86,$A$27:$A$86,16) -> 3 | T15: =SUMIFS($G$27:$G$86,$A$27:$A$86,17) -> 3 | U15: =SUMIFS($G$27:$G$86,$A$27:$A$86,18) -> 3 | V15: =SUMIFS($G$27:$G$86,$A$27:$A$86,19) -> 3 | W15: =SUMIFS($G$27:$G$86,$A$27:$A$86,20) -> 3 | X15: =G15 -> 3 | Y15: =K15 -> 3 | Z15: =O15 -> 3 | AA15: =S15 -> 3 | AB15: =W15 -> 3
A16: Total Average FTE | B16: Formula output from payroll detail | C16: =SUMIFS($H$27:$H$86,$A$27:$A$86,0) -> 0 | D16: =SUMIFS($H$27:$H$86,$A$27:$A$86,1) -> 3 | E16: =SUMIFS($H$27:$H$86,$A$27:$A$86,2) -> 3 | F16: =SUMIFS($H$27:$H$86,$A$27:$A$86,3) -> 3 | G16: =SUMIFS($H$27:$H$86,$A$27:$A$86,4) -> 3 | H16: =SUMIFS($H$27:$H$86,$A$27:$A$86,5) -> 3 | I16: =SUMIFS($H$27:$H$86,$A$27:$A$86,6) -> 3 | J16: =SUMIFS($H$27:$H$86,$A$27:$A$86,7) -> 3 | K16: =SUMIFS($H$27:$H$86,$A$27:$A$86,8) -> 3 | L16: =SUMIFS($H$27:$H$86,$A$27:$A$86,9) -> 3 | M16: =SUMIFS($H$27:$H$86,$A$27:$A$86,10) -> 3 | N16: =SUMIFS($H$27:$H$86,$A$27:$A$86,11) -> 3 | O16: =SUMIFS($H$27:$H$86,$A$27:$A$86,12) -> 3 | P16: =SUMIFS($H$27:$H$86,$A$27:$A$86,13) -> 3 | Q16: =SUMIFS($H$27:$H$86,$A$27:$A$86,14) -> 3 | R16: =SUMIFS($H$27:$H$86,$A$27:$A$86,15) -> 3 | S16: =SUMIFS($H$27:$H$86,$A$27:$A$86,16) -> 3 | T16: =SUMIFS($H$27:$H$86,$A$27:$A$86,17) -> 3 | U16: =SUMIFS($H$27:$H$86,$A$27:$A$86,18) -> 3 | V16: =SUMIFS($H$27:$H$86,$A$27:$A$86,19) -> 3 | W16: =SUMIFS($H$27:$H$86,$A$27:$A$86,20) -> 3 | X16: =AVERAGE(D16:G16) -> 3 | Y16: =AVERAGE(H16:K16) -> 3 | Z16: =AVERAGE(L16:O16) -> 3 | AA16: =AVERAGE(P16:S16) -> 3 | AB16: =AVERAGE(T16:W16) -> 3
A17: Total Payroll | B17: Formula output from payroll detail | C17: =SUMIFS($M$27:$M$86,$A$27:$A$86,0) -> 0 | D17: =SUMIFS($M$27:$M$86,$A$27:$A$86,1) -> 106929.45 | E17: =SUMIFS($M$27:$M$86,$A$27:$A$86,2) -> 106929.45 | F17: =SUMIFS($M$27:$M$86,$A$27:$A$86,3) -> 106929.45 | G17: =SUMIFS($M$27:$M$86,$A$27:$A$86,4) -> 106929.45 | H17: =SUMIFS($M$27:$M$86,$A$27:$A$86,5) -> 110137.57 | I17: =SUMIFS($M$27:$M$86,$A$27:$A$86,6) -> 110137.57 | J17: =SUMIFS($M$27:$M$86,$A$27:$A$86,7) -> 110137.57 | K17: =SUMIFS($M$27:$M$86,$A$27:$A$86,8) -> 110137.57 | L17: =SUMIFS($M$27:$M$86,$A$27:$A$86,9) -> 113441.21 | M17: =SUMIFS($M$27:$M$86,$A$27:$A$86,10) -> 113441.21 | N17: =SUMIFS($M$27:$M$86,$A$27:$A$86,11) -> 113441.21 | O17: =SUMIFS($M$27:$M$86,$A$27:$A$86,12) -> 113441.21 | P17: =SUMIFS($M$27:$M$86,$A$27:$A$86,13) -> 116844.65 | Q17: =SUMIFS($M$27:$M$86,$A$27:$A$86,14) -> 116844.65 | R17: =SUMIFS($M$27:$M$86,$A$27:$A$86,15) -> 116844.65 | S17: =SUMIFS($M$27:$M$86,$A$27:$A$86,16) -> 116844.65 | T17: =SUMIFS($M$27:$M$86,$A$27:$A$86,17) -> 120350.07 | U17: =SUMIFS($M$27:$M$86,$A$27:$A$86,18) -> 120350.07 | V17: =SUMIFS($M$27:$M$86,$A$27:$A$86,19) -> 120350.07 | W17: =SUMIFS($M$27:$M$86,$A$27:$A$86,20) -> 120350.07 | X17: =SUM(D17:G17) -> 427717.8 | Y17: =SUM(H17:K17) -> 440550.3 | Z17: =SUM(L17:O17) -> 453764.83 | AA17: =SUM(P17:S17) -> 467378.62 | AB17: =SUM(T17:W17) -> 481400.27
A18: Total Revenue | B18: Linked from Revenue Drivers | C18: ='Revenue Drivers'!C14 -> 117000 | D18: ='Revenue Drivers'!D14 -> 265953.38 | E18: ='Revenue Drivers'!E14 -> 283499.21 | F18: ='Revenue Drivers'!F14 -> 301385.46 | G18: ='Revenue Drivers'!G14 -> 319612.13 | H18: ='Revenue Drivers'!H14 -> 338179.22 | I18: ='Revenue Drivers'!I14 -> 357086.73 | J18: ='Revenue Drivers'!J14 -> 376334.66 | ... W18: ='Revenue Drivers'!W14 -> 476588.45 | X18: =SUM(D18:G18) -> 1170450.2 | Y18: =SUM(H18:K18) -> 1467523.6 | Z18: =SUM(L18:O18) -> 1767640.4 | AA18: =SUM(P18:S18) -> 1857812.4 | AB18: =SUM(T18:W18) -> 1893115.2
A19: Total Capacity Units | B19: Linked from Revenue Drivers | C19: ='Revenue Drivers'!C13 -> 1040 | D19: ='Revenue Drivers'!D13 -> 2364.03 | E19: ='Revenue Drivers'!E13 -> 2364.03 | F19: ='Revenue Drivers'!F13 -> 2364.03 | G19: ='Revenue Drivers'!G13 -> 2364.03 | H19: ='Revenue Drivers'!H13 -> 2364.03 | I19: ='Revenue Drivers'!I13 -> 2364.03 | J19: ='Revenue Drivers'!J13 -> 2364.03 | ... W19: ='Revenue Drivers'!W13 -> 2364.03 | X19: =SUM(D19:G19) -> 9456.12 | Y19: =SUM(H19:K19) -> 9456.12 | Z19: =SUM(L19:O19) -> 9456.12 | AA19: =SUM(P19:S19) -> 9456.12 | AB19: =SUM(T19:W19) -> 9456.12
A20: Revenue per Employee | B20: Python-built productivity formula | C20: =IFERROR(C18/C16,0) -> 0 | D20: =IFERROR(D18/D16,0) -> 88651.125 | E20: =IFERROR(E18/E16,0) -> 94499.735 | F20: =IFERROR(F18/F16,0) -> 100461.82 | G20: =IFERROR(G18/G16,0) -> 106537.38 | H20: =IFERROR(H18/H16,0) -> 112726.41 | I20: =IFERROR(I18/I16,0) -> 119028.91 | J20: =IFERROR(J18/J16,0) -> 125444.89 | ... AB20: =IFERROR(AB18/AB16,0) -> 631038.41
A21: Units per Employee | B21: Python-built productivity formula | C21: =IFERROR(C19/C16,0) -> 0 | D21: =IFERROR(D19/D16,0) -> 788.01 | E21: =IFERROR(E19/E16,0) -> 788.01 | F21: =IFERROR(F19/F16,0) -> 788.01 | G21: =IFERROR(G19/G16,0) -> 788.01 | H21: =IFERROR(H19/H16,0) -> 788.01 | I21: =IFERROR(I19/I16,0) -> 788.01 | J21: =IFERROR(J19/J16,0) -> 788.01 | ... AB21: =IFERROR(AB19/AB16,0) -> 3152.04
A22: Payroll % of Revenue | B22: Python-built productivity formula | C22: =IFERROR(C17/C18,0) -> 0 | D22: =IFERROR(D17/D18,0) -> 0.40206089 | E22: =IFERROR(E17/E18,0) -> 0.37717725 | F22: =IFERROR(F17/F18,0) -> 0.354793 | G22: =IFERROR(G17/G18,0) -> 0.33456005 | H22: =IFERROR(H17/H18,0) -> 0.32567813 | I22: =IFERROR(I17/I18,0) -> 0.30843368 | J22: =IFERROR(J17/J18,0) -> 0.2926586 | ... AB22: =IFERROR(AB17/AB18,0) -> 0.25429
A25: Payroll Detail
A26: Quarter | B26: Staffing Class | C26: Title / Person | D26: OEWS Title | E26: Starting FTE | F26: Hires | G26: Ending FTE | H26: Average FTE | I26: Annual Wage | J26: Benefits % | K26: Wage Cost | L26: Taxes & Benefits | M26: Total Payroll | N26: Wage Source
A27: 1 | B27: key_person | C27: Chief Executive Officer (CEO) | E27: 1 | F27: 0 | G27: =E27+F27 -> 1 | H27: =(E27+G27)/2 -> 1 | I27: 149770 | J27: 0.22 | K27: =H27*I27/4 -> 37442.5 | L27: =K27*J27 -> 8237.35 | M27: =K27+L27 -> 45679.85 | N27: oews_median
A28: 2 | B28: key_person | C28: Chief Executive Officer (CEO) | E28: 1 | F28: 0 | G28: =E28+F28 -> 1 | H28: =(E28+G28)/2 -> 1 | I28: 149770 | J28: 0.22 | K28: =H28*I28/4 -> 37442.5 | L28: =K28*J28 -> 8237.35 | M28: =K28+L28 -> 45679.85 | N28: oews_median
A29: 3 | B29: key_person | C29: Chief Executive Officer (CEO) | E29: 1 | F29: 0 | G29: =E29+F29 -> 1 | H29: =(E29+G29)/2 -> 1 | I29: 149770 | J29: 0.22 | K29: =H29*I29/4 -> 37442.5 | L29: =K29*J29 -> 8237.35 | M29: =K29+L29 -> 45679.85 | N29: oews_median
A30: 4 | B30: key_person | C30: Chief Executive Officer (CEO) | E30: 1 | F30: 0 | G30: =E30+F30 -> 1 | H30: =(E30+G30)/2 -> 1 | I30: 149770 | J30: 0.22 | K30: =H30*I30/4 -> 37442.5 | L30: =K30*J30 -> 8237.35 | M30: =K30+L30 -> 45679.85 | N30: oews_median
A31: 5 | B31: key_person | C31: Chief Executive Officer (CEO) | E31: 1 | F31: 0 | G31: =E31+F31 -> 1 | H31: =(E31+G31)/2 -> 1 | I31: 154263 | J31: 0.22 | K31: =H31*I31/4 -> 38565.75 | L31: =K31*J31 -> 8484.465 | M31: =K31+L31 -> 47050.215 | N31: oews_median
A32: 6 | B32: key_person | C32: Chief Executive Officer (CEO) | E32: 1 | F32: 0 | G32: =E32+F32 -> 1 | H32: =(E32+G32)/2 -> 1 | I32: 154263 | J32: 0.22 | K32: =H32*I32/4 -> 38565.75 | L32: =K32*J32 -> 8484.465 | M32: =K32+L32 -> 47050.215 | N32: oews_median
A33: 7 | B33: key_person | C33: Chief Executive Officer (CEO) | E33: 1 | F33: 0 | G33: =E33+F33 -> 1 | H33: =(E33+G33)/2 -> 1 | I33: 154263 | J33: 0.22 | K33: =H33*I33/4 -> 38565.75 | L33: =K33*J33 -> 8484.465 | M33: =K33+L33 -> 47050.215 | N33: oews_median
A34: 8 | B34: key_person | C34: Chief Executive Officer (CEO) | E34: 1 | F34: 0 | G34: =E34+F34 -> 1 | H34: =(E34+G34)/2 -> 1 | I34: 154263 | J34: 0.22 | K34: =H34*I34/4 -> 38565.75 | L34: =K34*J34 -> 8484.465 | M34: =K34+L34 -> 47050.215 | N34: oews_median
A35: 9 | B35: key_person | C35: Chief Executive Officer (CEO) | E35: 1 | F35: 0 | G35: =E35+F35 -> 1 | H35: =(E35+G35)/2 -> 1 | I35: 158891 | J35: 0.22 | K35: =H35*I35/4 -> 39722.75 | L35: =K35*J35 -> 8739.005 | M35: =K35+L35 -> 48461.755 | N35: oews_median
A36: 10 | B36: key_person | C36: Chief Executive Officer (CEO) | E36: 1 | F36: 0 | G36: =E36+F36 -> 1 | H36: =(E36+G36)/2 -> 1 | I36: 158891 | J36: 0.22 | K36: =H36*I36/4 -> 39722.75 | L36: =K36*J36 -> 8739.005 | M36: =K36+L36 -> 48461.755 | N36: oews_median
A37: 11 | B37: key_person | C37: Chief Executive Officer (CEO) | E37: 1 | F37: 0 | G37: =E37+F37 -> 1 | H37: =(E37+G37)/2 -> 1 | I37: 158891 | J37: 0.22 | K37: =H37*I37/4 -> 39722.75 | L37: =K37*J37 -> 8739.005 | M37: =K37+L37 -> 48461.755 | N37: oews_median
A38: 12 | B38: key_person | C38: Chief Executive Officer (CEO) | E38: 1 | F38: 0 | G38: =E38+F38 -> 1 | H38: =(E38+G38)/2 -> 1 | I38: 158891 | J38: 0.22 | K38: =H38*I38/4 -> 39722.75 | L38: =K38*J38 -> 8739.005 | M38: =K38+L38 -> 48461.755 | N38: oews_median
... A66: 20 | B66: key_person | C66: Clinical Director | E66: 1 | F66: 0 | G66: =E66+F66 -> 1 | H66: =(E66+G66)/2 -> 1 | I66: 112799 | J66: 0.22 | K66: =H66*I66/4 -> 28199.75 | L66: =K66*J66 -> 6203.945 | M66: =K66+L66 -> 34403.695 | N66: oews_median
A67: 1 | B67: supporting_staff | C67: Registered Nurses | D67: Registered Nurses | E67: 1 | F67: 0 | G67: =E67+F67 -> 1 | H67: =(E67+G67)/2 -> 1 | I67: 98184 | J67: 0.25 | K67: =H67*I67/4 -> 24546 | L67: =K67*J67 -> 6136.5 | M67: =K67+L67 -> 30682.5 | N67: oews_title_catalog:oews_median
A68: 2 | B68: supporting_staff | C68: Registered Nurses | D68: Registered Nurses | E68: 1 | F68: 0 | G68: =E68+F68 -> 1 | H68: =(E68+G68)/2 -> 1 | I68: 98184 | J68: 0.25 | K68: =H68*I68/4 -> 24546 | L68: =K68*J68 -> 6136.5 | M68: =K68+L68 -> 30682.5 | N68: oews_title_catalog:oews_median
A69: 3 | B69: supporting_staff | C69: Registered Nurses | D69: Registered Nurses | E69: 1 | F69: 0 | G69: =E69+F69 -> 1 | H69: =(E69+G69)/2 -> 1 | I69: 98184 | J69: 0.25 | K69: =H69*I69/4 -> 24546 | L69: =K69*J69 -> 6136.5 | M69: =K69+L69 -> 30682.5 | N69: oews_title_catalog:oews_median
A70: 4 | B70: supporting_staff | C70: Registered Nurses | D70: Registered Nurses | E70: 1 | F70: 0 | G70: =E70+F70 -> 1 | H70: =(E70+G70)/2 -> 1 | I70: 98184 | J70: 0.25 | K70: =H70*I70/4 -> 24546 | L70: =K70*J70 -> 6136.5 | M70: =K70+L70 -> 30682.5 | N70: oews_title_catalog:oews_median
A71: 5 | B71: supporting_staff | C71: Registered Nurses | D71: Registered Nurses | E71: 1 | F71: 0 | G71: =E71+F71 -> 1 | H71: =(E71+G71)/2 -> 1 | I71: 101130 | J71: 0.25 | K71: =H71*I71/4 -> 25282.5 | L71: =K71*J71 -> 6320.625 | M71: =K71+L71 -> 31603.125 | N71: oews_title_catalog:oews_median
...

Sheet Debt Schedule
A1: Debt Schedule
A2: Debt, interest, and capital lease mechanics. Model Inputs links to calculated outputs.
C4: Stub | D4: Q1 | E4: Q2 | F4: Q3 | G4: Q4 | H4: Q5 | I4: Q6 | J4: Q7 | K4: Q8 | L4: Q9 | M4: Q10 | N4: Q11 | O4: Q12 | P4: Q13 | Q4: Q14 | R4: Q15 | S4: Q16 | T4: Q17 | U4: Q18 | V4: Q19 | W4: Q20 | X4: Y1 | Y4: Y2 | Z4: Y3 | AA4: Y4 | AB4: Y5
C5: 46162 | D5: 46295 | E5: 46387 | F5: 46477 | G5: 46568 | H5: 46660 | I5: 46752 | J5: 46843 | K5: 46934 | L5: 47026 | M5: 47118 | N5: 47208 | O5: 47299 | P5: 47391 | Q5: 47483 | R5: 47573 | S5: 47664 | T5: 47756 | U5: 47848 | V5: 47938 | W5: 48029 | X5: Annual | Y5: Annual | Z5: Annual | AA5: Annual | AB5: Annual
A6: Debt Amortization
A7: Opening Debt | B7: Calculated | C7: 30000 | D7: =C11 -> 30000 | E7: =D11 -> 28500 | F7: =E11 -> 27000 | G7: =F11 -> 25500 | H7: =G11 -> 24000 | I7: =H11 -> 22500 | J7: =I11 -> 21000 | K7: =J11 -> 19500 | ... W7: =V11 -> 1500 | X7: =G7 -> 25500 | Y7: =K7 -> 19500 | Z7: =O7 -> 13500 | AA7: =S7 -> 7500 | AB7: =W7 -> 1500
A8: Debt Issuance | B8: Source borrowing | C8: 0 | D8: 0 | E8: 0 | F8: 0 | G8: 0 | H8: 0 | I8: 0 | J8: 0 | K8: 0 | L8: 0 | M8: 0 | N8: 0 | O8: 0 | P8: 0 | Q8: 0 | R8: 0 | S8: 0 | T8: 0 | U8: 0 | V8: 0 | W8: 0 | X8: =SUM(D8:G8) -> 0 | Y8: =SUM(H8:K8) -> 0 | Z8: =SUM(L8:O8) -> 0 | AA8: =SUM(P8:S8) -> 0 | AB8: =SUM(T8:W8) -> 0
A9: Requested Debt Repayment | B9: Source scheduled repayment | C9: 0 | D9: 1500 | E9: 1500 | F9: 1500 | G9: 1500 | H9: 1500 | I9: 1500 | J9: 1500 | K9: 1500 | L9: 1500 | M9: 1500 | N9: 1500 | O9: 1500 | P9: 1500 | Q9: 1500 | R9: 1500 | S9: 1500 | T9: 1500 | U9: 1500 | V9: 1500 | W9: 1500 | X9: =SUM(D9:G9) -> 6000 | Y9: =SUM(H9:K9) -> 6000 | Z9: =SUM(L9:O9) -> 6000 | AA9: =SUM(P9:S9) -> 6000 | AB9: =SUM(T9:W9) -> 6000
A10: Actual Debt Repayment | B10: MIN(requested repayment, opening debt + issuance) | C10: =MIN(C9,C7+C8) -> 0 | D10: =MIN(D9,D7+D8) -> 1500 | E10: =MIN(E9,E7+E8) -> 1500 | F10: =MIN(F9,F7+F8) -> 1500 | G10: =MIN(G9,G7+G8) -> 1500 | H10: =MIN(H9,H7+H8) -> 1500 | I10: =MIN(I9,I7+I8) -> 1500 | J10: =MIN(J9,J7+J8) -> 1500 | ... W10: =MIN(W9,W7+W8) -> 1500 | X10: =SUM(D10:G10) -> 6000 | Y10: =SUM(H10:K10) -> 6000 | Z10: =SUM(L10:O10) -> 6000 | AA10: =SUM(P10:S10) -> 6000 | AB10: =SUM(T10:W10) -> 6000
A11: Closing Debt | B11: Calculated | C11: =MAX(0,C7+C8-C10) -> 30000 | D11: =MAX(0,D7+D8-D10) -> 28500 | E11: =MAX(0,E7+E8-E10) -> 27000 | F11: =MAX(0,F7+F8-F10) -> 25500 | G11: =MAX(0,G7+G8-G10) -> 24000 | H11: =MAX(0,H7+H8-H10) -> 22500 | I11: =MAX(0,I7+I8-I10) -> 21000 | J11: =MAX(0,J7+J8-J10) -> 19500 | ... W11: =MAX(0,W7+W8-W10) -> 0 | X11: =G11 -> 24000 | Y11: =K11 -> 18000 | Z11: =O11 -> 12000 | AA11: =S11 -> 6000 | AB11: =W11 -> 0
A12: Interest Rate | B12: Source rate | C12: 0.01 | D12: 0.025 | E12: 0.025 | F12: 0.025 | G12: 0.025 | H12: 0.025 | I12: 0.025 | J12: 0.025 | K12: 0.025 | L12: 0.025 | M12: 0.025 | N12: 0.025 | O12: 0.025 | P12: 0.025 | Q12: 0.025 | R12: 0.025 | S12: 0.025 | T12: 0.025 | U12: 0.025 | V12: 0.025 | W12: 0.025 | X12: =SUM(D12:G12) -> 0.1 | Y12: =SUM(H12:K12) -> 0.1 | Z12: =SUM(L12:O12) -> 0.1 | AA12: =SUM(P12:S12) -> 0.1 | AB12: =SUM(T12:W12) -> 0.1
A13: Interest Expense | B13: Average debt balance x rate | C13: =((C7+C11)/2)*C12 -> 300 | D13: =((D7+D11)/2)*D12 -> 731.25 | E13: =((E7+E11)/2)*E12 -> 693.75 | F13: =((F7+F11)/2)*F12 -> 656.25 | G13: =((G7+G11)/2)*G12 -> 618.75 | H13: =((H7+H11)/2)*H12 -> 581.25 | I13: =((I7+I11)/2)*I12 -> 543.75 | J13: =((J7+J11)/2)*J12 -> 506.25 | ... W13: =((W7+W11)/2)*W12 -> 18.75 | X13: =SUM(D13:G13) -> 2700 | Y13: =SUM(H13:K13) -> 2100 | Z13: =SUM(L13:O13) -> 1500 | AA13: =SUM(P13:S13) -> 900 | AB13: =SUM(T13:W13) -> 300
A14: Total Debt Service | B14: Interest + actual repayment | C14: =C13+C10 -> 300 | D14: =D13+D10 -> 2231.25 | E14: =E13+E10 -> 2193.75 | F14: =F13+F10 -> 2156.25 | G14: =G13+G10 -> 2118.75 | H14: =H13+H10 -> 2081.25 | I14: =I13+I10 -> 2043.75 | J14: =J13+J10 -> 2006.25 | ... W14: =W13+W10 -> 1518.75 | X14: =SUM(D14:G14) -> 8700 | Y14: =SUM(H14:K14) -> 8100 | Z14: =SUM(L14:O14) -> 7500 | AA14: =SUM(P14:S14) -> 6900 | AB14: =SUM(T14:W14) -> 6300
A17: Capital Lease Schedule
A18: Lease Opening Balance | B18: Capital leases | C18: 0 | D18: =C23 -> 0 | E18: =D23 -> 0 | F18: =E23 -> 0 | G18: =F23 -> 0 | H18: =G23 -> 0 | I18: =H23 -> 0 | J18: =I23 -> 0 | K18: =J23 -> 0 | ... W18: =V23 -> 0 | X18: =G18 -> 0 | Y18: =K18 -> 0 | Z18: =O18 -> 0 | AA18: =S18 -> 0 | AB18: =W18 -> 0
A19: Requested Lease Principal Repayments | B19: Capital leases | C19: 0 | D19: 2000 | E19: 2000 | F19: 2000 | G19: 2000 | H19: 2000 | I19: 2000 | J19: 2000 | K19: 2000 | L19: 2000 | M19: 2000 | N19: 2000 | O19: 2000 | P19: 2000 | Q19: 2000 | R19: 2000 | S19: 2000 | T19: 2000 | U19: 2000 | V19: 2000 | W19: 2000 | X19: =SUM(D19:G19) -> 8000 | Y19: =SUM(H19:K19) -> 8000 | Z19: =SUM(L19:O19) -> 8000 | AA19: =SUM(P19:S19) -> 8000 | AB19: =SUM(T19:W19) -> 8000
A20: Lease Principal Repayments | B20: Capital leases | C20: =MIN(C19,C18+C21) -> 0 | D20: =MIN(D19,D18+D21) -> 0 | E20: =MIN(E19,E18+E21) -> 0 | F20: =MIN(F19,F18+F21) -> 0 | G20: =MIN(G19,G18+G21) -> 0 | H20: =MIN(H19,H18+H21) -> 0 | I20: =MIN(I19,I18+I21) -> 0 | J20: =MIN(J19,J18+J21) -> 0 | ... W20: =MIN(W19,W18+W21) -> 0 | X20: =SUM(D20:G20) -> 0 | Y20: =SUM(H20:K20) -> 0 | Z20: =SUM(L20:O20) -> 0 | AA20: =SUM(P20:S20) -> 0 | AB20: =SUM(T20:W20) -> 0
A21: Lease Net Additions | B21: Capital leases | C21: 0 | D21: 0 | E21: 0 | F21: 0 | G21: 0 | H21: 0 | I21: 0 | J21: 0 | K21: 0 | L21: 0 | M21: 0 | N21: 0 | O21: 0 | P21: 0 | Q21: 0 | R21: 0 | S21: 0 | T21: 0 | U21: 0 | V21: 0 | W21: 0 | X21: =SUM(D21:G21) -> 0 | Y21: =SUM(H21:K21) -> 0 | Z21: =SUM(L21:O21) -> 0 | AA21: =SUM(P21:S21) -> 0 | AB21: =SUM(T21:W21) -> 0
A22: Lease Interest Expense | B22: Capital leases | C22: 0 | D22: =D18*D12 -> 0 | E22: =E18*E12 -> 0 | F22: =F18*F12 -> 0 | G22: =G18*G12 -> 0 | H22: =H18*H12 -> 0 | I22: =I18*I12 -> 0 | J22: =J18*J12 -> 0 | K22: =K18*K12 -> 0 | ... W22: =W18*W12 -> 0 | X22: =SUM(D22:G22) -> 0 | Y22: =SUM(H22:K22) -> 0 | Z22: =SUM(L22:O22) -> 0 | AA22: =SUM(P22:S22) -> 0 | AB22: =SUM(T22:W22) -> 0
A23: Lease Closing Balance | B23: Capital leases | C23: =MAX(0,C18+C21-C20) -> 0 | D23: =MAX(0,D18+D21-D20) -> 0 | E23: =MAX(0,E18+E21-E20) -> 0 | F23: =MAX(0,F18+F21-F20) -> 0 | G23: =MAX(0,G18+G21-G20) -> 0 | H23: =MAX(0,H18+H21-H20) -> 0 | I23: =MAX(0,I18+I21-I20) -> 0 | J23: =MAX(0,J18+J21-J20) -> 0 | ... W23: =MAX(0,W18+W21-W20) -> 0 | X23: =G23 -> 0 | Y23: =K23 -> 0 | Z23: =O23 -> 0 | AA23: =S23 -> 0 | AB23: =W23 -> 0
A24: Right-of-Use Asset Opening | B24: Capital leases | C24: 0 | D24: =C26 -> 0 | E24: =D26 -> 0 | F24: =E26 -> 0 | G24: =F26 -> 0 | H24: =G26 -> 0 | I24: =H26 -> 0 | J24: =I26 -> 0 | K24: =J26 -> 0 | ... W24: =V26 -> 0 | X24: =G24 -> 0 | Y24: =K24 -> 0 | Z24: =O24 -> 0 | AA24: =S24 -> 0 | AB24: =W24 -> 0
A25: Lease Asset Depreciation | B25: Capital leases | C25: 0 | D25: =MIN((C18/20),D24) -> 0 | E25: =MIN((C18/20),E24) -> 0 | F25: =MIN((C18/20),F24) -> 0 | G25: =MIN((C18/20),G24) -> 0 | H25: =MIN((C18/20),H24) -> 0 | I25: =MIN((C18/20),I24) -> 0 | J25: =MIN((C18/20),J24) -> 0 | K25: =MIN((C18/20),K24) -> 0 | L25: =MIN((C18/20),L24) -> 0 | M25: =MIN((C18/20),M24) -> 0 | N25: =MIN((C18/20),N24) -> 0 | O25: =MIN((C18/20),O24) -> 0 | P25: =MIN((C18/20),P24) -> 0 | Q25: =MIN((C18/20),Q24) -> 0 | R25: =MIN((C18/20),R24) -> 0 | S25: =MIN((C18/20),S24) -> 0 | T25: =MIN((C18/20),T24) -> 0 | U25: =MIN((C18/20),U24) -> 0 | V25: =MIN((C18/20),V24) -> 0 | W25: =MIN((C18/20),W24) -> 0 | X25: =SUM(D25:G25) -> 0 | Y25: =SUM(H25:K25) -> 0 | Z25: =SUM(L25:O25) -> 0 | AA25: =SUM(P25:S25) -> 0 | AB25: =SUM(T25:W25) -> 0
A26: Right-of-Use Asset Closing | B26: Capital leases | C26: =MAX(0,C24-C25) -> 0 | D26: =MAX(0,D24-D25) -> 0 | E26: =MAX(0,E24-E25) -> 0 | F26: =MAX(0,F24-F25) -> 0 | G26: =MAX(0,G24-G25) -> 0 | H26: =MAX(0,H24-H25) -> 0 | I26: =MAX(0,I24-I25) -> 0 | J26: =MAX(0,J24-J25) -> 0 | ... W26: =MAX(0,W24-W25) -> 0 | X26: =G26 -> 0 | Y26: =K26 -> 0 | Z26: =O26 -> 0 | AA26: =S26 -> 0 | AB26: =W26 -> 0

Sheet CapEx Depreciation
A1: CapEx & Depreciation Schedule
A2: Capital expenditure and depreciation mechanics. Model Inputs links to calculated outputs.
C4: Stub | D4: Q1 | E4: Q2 | F4: Q3 | G4: Q4 | H4: Q5 | I4: Q6 | J4: Q7 | K4: Q8 | L4: Q9 | M4: Q10 | N4: Q11 | O4: Q12 | P4: Q13 | Q4: Q14 | R4: Q15 | S4: Q16 | T4: Q17 | U4: Q18 | V4: Q19 | W4: Q20 | X4: Y1 | Y4: Y2 | Z4: Y3 | AA4: Y4 | AB4: Y5
C5: 46162 | D5: 46295 | E5: 46387 | F5: 46477 | G5: 46568 | H5: 46660 | I5: 46752 | J5: 46843 | K5: 46934 | L5: 47026 | M5: 47118 | N5: 47208 | O5: 47299 | P5: 47391 | Q5: 47483 | R5: 47573 | S5: 47664 | T5: 47756 | U5: 47848 | V5: 47938 | W5: 48029 | X5: Annual | Y5: Annual | Z5: Annual | AA5: Annual | AB5: Annual
A6: PPE and Depreciation
A7: Opening PPE | B7: Calculated | C7: 40000 | D7: =C12 -> 40000 | E7: =D12 -> 40190 | F7: =E12 -> 40370.895 | G7: =F12 -> 40542.593 | H7: =G12 -> 40705.047 | I7: =H12 -> 40858.138 | J7: =I12 -> 41001.755 | K7: =J12 -> 41135.831 | ... W7: =V12 -> 41973.955 | X7: =G7 -> 40542.593 | Y7: =K7 -> 41135.831 | Z7: =O7 -> 41575.259 | AA7: =S7 -> 41856.096 | AB7: =W7 -> 41973.955
A8: Capital Expenditures | B8: Schedule source | C8: 0 | D8: 200 | E8: 200.95 | F8: 201.85448 | G8: 202.71296 | H8: 203.52523 | I8: 204.29069 | J8: 205.00877 | K8: 205.67915 | L8: 206.30154 | M8: 206.87547 | N8: 207.40052 | O8: 207.87629 | P8: 208.30265 | Q8: 208.67905 | R8: 209.00501 | S8: 209.28048 | T8: 209.50504 | U8: 209.6783 | V8: 209.79991 | W8: 209.86977 | X8: =SUM(D8:G8) -> 805.51744 | Y8: =SUM(H8:K8) -> 818.50385 | Z8: =SUM(L8:O8) -> 828.45382 | AA8: =SUM(P8:S8) -> 835.26719 | AB8: =SUM(T8:W8) -> 838.85302
A9: Lease Additions | B9: Schedule source | C9: 0 | D9: ='Debt Schedule'!D21 -> 0 | E9: ='Debt Schedule'!E21 -> 0 | F9: ='Debt Schedule'!F21 -> 0 | G9: ='Debt Schedule'!G21 -> 0 | H9: ='Debt Schedule'!H21 -> 0 | I9: ='Debt Schedule'!I21 -> 0 | J9: ='Debt Schedule'!J21 -> 0 | K9: ='Debt Schedule'!K21 -> 0 | ... W9: ='Debt Schedule'!W21 -> 0 | X9: =SUM(D9:G9) -> 0 | Y9: =SUM(H9:K9) -> 0 | Z9: =SUM(L9:O9) -> 0 | AA9: =SUM(P9:S9) -> 0 | AB9: =SUM(T9:W9) -> 0
A10: Depreciation Rate | B10: Schedule source | C10: 0 | D10: 0.00025 | E10: 0.000499 | F10: 0.000747 | G10: 0.000993 | H10: 0.001239 | I10: 0.001485 | J10: 0.00173 | K10: 0.001974 | L10: 0.002218 | M10: 0.002462 | N10: 0.002706 | O10: 0.002949 | P10: 0.003193 | Q10: 0.003438 | R10: 0.003682 | S10: 0.003927 | T10: 0.004173 | U10: 0.00442 | V10: 0.004667 | W10: 0.004916 | X10: =SUM(D10:G10) -> 0.002489 | Y10: =SUM(H10:K10) -> 0.006428 | Z10: =SUM(L10:O10) -> 0.010335 | AA10: =SUM(P10:S10) -> 0.01424 | AB10: =SUM(T10:W10) -> 0.018176
A11: Depreciation Expense | B11: Calculated | C11: =MIN(C7*C10,C7) -> 0 | D11: =MIN(D7*D10,D7) -> 10 | E11: =MIN(E7*E10,E7) -> 20.05481 | F11: =MIN(F7*F10,F7) -> 30.157059 | G11: =MIN(G7*G10,G7) -> 40.258794 | H11: =MIN(H7*H10,H7) -> 50.433553 | I11: =MIN(I7*I10,I7) -> 60.674336 | J11: =MIN(J7*J10,J7) -> 70.933036 | ... W11: =MIN(W7*W10,W7) -> 206.34396 | X11: =SUM(D11:G11) -> 100.47066 | Y11: =SUM(H11:K11) -> 263.24305 | Z11: =SUM(L11:O11) -> 428.23144 | AA11: =SUM(P11:S11) -> 594.78996 | AB11: =SUM(T11:W11) -> 762.37971
A12: Closing PPE | B12: Calculated | C12: =MAX(0,C7+C8+C9-C11) -> 40000 | D12: =MAX(0,D7+D8+D9-D11) -> 40190 | E12: =MAX(0,E7+E8+E9-E11) -> 40370.895 | F12: =MAX(0,F7+F8+F9-F11) -> 40542.593 | G12: =MAX(0,G7+G8+G9-G11) -> 40705.047 | H12: =MAX(0,H7+H8+H9-H11) -> 40858.138 | I12: =MAX(0,I7+I8+I9-I11) -> 41001.755 | J12: =MAX(0,J7+J8+J9-J11) -> 41135.831 | ... W12: =MAX(0,W7+W8+W9-W11) -> 41977.48 | X12: =G12 -> 40705.047 | Y12: =K12 -> 41260.308 | Z12: =O12 -> 41660.53 | AA12: =S12 -> 41901.007 | AB12: =W12 -> 41977.48
A13: Opening Accumulated Depreciation | B13: Calculated | C13: 0 | D13: =C14 -> 0 | E13: =D14 -> -10 | F13: =E14 -> -30.05481 | G13: =F14 -> -60.211869 | H13: =G14 -> -100.47066 | I13: =H14 -> -150.90422 | J13: =I14 -> -211.57855 | K13: =J14 -> -282.51159 | ... W13: =V14 -> -1942.7709 | X13: =G13 -> -60.211869 | Y13: =K13 -> -282.51159 | Z13: =O13 -> -669.33972 | AA13: =S13 -> -1222.3662 | AB13: =W13 -> -1942.7709
A14: Accumulated Depreciation | B14: Calculated | C14: =C13-C11 -> 0 | D14: =D13-D11 -> -10 | E14: =E13-E11 -> -30.05481 | F14: =F13-F11 -> -60.211869 | G14: =G13-G11 -> -100.47066 | H14: =H13-H11 -> -150.90422 | I14: =I13-I11 -> -211.57855 | J14: =J13-J11 -> -282.51159 | ... W14: =W13-W11 -> -2149.1148 | X14: =G14 -> -100.47066 | Y14: =K14 -> -363.71372 | Z14: =O14 -> -791.94516 | AA14: =S14 -> -1386.7351 | AB14: =W14 -> -2149.1148

Sheet Working Capital
A1: Working Capital Schedule
A2: Working-capital drivers. Model Inputs links to these source rows.
C4: Stub | D4: Q1 | E4: Q2 | F4: Q3 | G4: Q4 | H4: Q5 | I4: Q6 | J4: Q7 | K4: Q8 | L4: Q9 | M4: Q10 | N4: Q11 | O4: Q12 | P4: Q13 | Q4: Q14 | R4: Q15 | S4: Q16 | T4: Q17 | U4: Q18 | V4: Q19 | W4: Q20 | X4: Y1 | Y4: Y2 | Z4: Y3 | AA4: Y4 | AB4: Y5
C5: 46162 | D5: 46295 | E5: 46387 | F5: 46477 | G5: 46568 | H5: 46660 | I5: 46752 | J5: 46843 | K5: 46934 | L5: 47026 | M5: 47118 | N5: 47208 | O5: 47299 | P5: 47391 | Q5: 47483 | R5: 47573 | S5: 47664 | T5: 47756 | U5: 47848 | V5: 47938 | W5: 48029 | X5: Annual | Y5: Annual | Z5: Annual | AA5: Annual | AB5: Annual
A6: Working Capital Drivers
A7: Accounts Receivable Days | B7: Working capital driver | C7: 0 | D7: 30 | E7: 30 | F7: 30 | G7: 30 | H7: 30 | I7: 30 | J7: 30 | K7: 30 | L7: 30 | M7: 30 | N7: 30 | O7: 30 | P7: 30 | Q7: 30 | R7: 30 | S7: 30 | T7: 30 | U7: 30 | V7: 30 | W7: 30
A8: Inventory Days | B8: Working capital driver | C8: 0 | D8: 0 | E8: 0 | F8: 0 | G8: 0 | H8: 0 | I8: 0 | J8: 0 | K8: 0 | L8: 0 | M8: 0 | N8: 0 | O8: 0 | P8: 0 | Q8: 0 | R8: 0 | S8: 0 | T8: 0 | U8: 0 | V8: 0 | W8: 0
A9: Accounts Payable Days | B9: Working capital driver | C9: 0 | D9: 30 | E9: 30 | F9: 30 | G9: 30 | H9: 30 | I9: 30 | J9: 30 | K9: 30 | L9: 30 | M9: 30 | N9: 30 | O9: 30 | P9: 30 | Q9: 30 | R9: 30 | S9: 30 | T9: 30 | U9: 30 | V9: 30 | W9: 30
A10: Prepaid Expenses (% of Revenue) | B10: Working capital driver | C10: 0 | D10: 5 | E10: 5 | F10: 5 | G10: 5 | H10: 5 | I10: 5 | J10: 5 | K10: 5 | L10: 5 | M10: 5 | N10: 5 | O10: 5 | P10: 5 | Q10: 5 | R10: 5 | S10: 5 | T10: 5 | U10: 5 | V10: 5 | W10: 5
A11: Deferred Revenue (% of Revenue) | B11: Working capital driver | C11: 0 | D11: 0 | E11: 0 | F11: 0 | G11: 0 | H11: 0 | I11: 0 | J11: 0 | K11: 0 | L11: 0 | M11: 0 | N11: 0 | O11: 0 | P11: 0 | Q11: 0 | R11: 0 | S11: 0 | T11: 0 | U11: 0 | V11: 0 | W11: 0
A12: Short Term Debt (% of LTD) | B12: Working capital driver | C12: 0 | D12: 0 | E12: 0 | F12: 0 | G12: 0 | H12: 0 | I12: 0 | J12: 0 | K12: 0 | L12: 0 | M12: 0 | N12: 0 | O12: 0 | P12: 0 | Q12: 0 | R12: 0 | S12: 0 | T12: 0 | U12: 0 | V12: 0 | W12: 0
A14: Opening Working Capital Seeds
A15: Cash Opening Balance | B15: Opening balance seed | C15: 12000 | D15: 0 | E15: 0 | F15: 0 | G15: 0 | H15: 0 | I15: 0 | J15: 0 | K15: 0 | L15: 0 | M15: 0 | N15: 0 | O15: 0 | P15: 0 | Q15: 0 | R15: 0 | S15: 0 | T15: 0 | U15: 0 | V15: 0 | W15: 0
A16: Accounts Receivable Opening Balance | B16: Opening balance seed | C16: 0 | D16: 0 | E16: 0 | F16: 0 | G16: 0 | H16: 0 | I16: 0 | J16: 0 | K16: 0 | L16: 0 | M16: 0 | N16: 0 | O16: 0 | P16: 0 | Q16: 0 | R16: 0 | S16: 0 | T16: 0 | U16: 0 | V16: 0 | W16: 0
A17: Inventory Opening Balance | B17: Opening balance seed | C17: 0 | D17: 0 | E17: 0 | F17: 0 | G17: 0 | H17: 0 | I17: 0 | J17: 0 | K17: 0 | L17: 0 | M17: 0 | N17: 0 | O17: 0 | P17: 0 | Q17: 0 | R17: 0 | S17: 0 | T17: 0 | U17: 0 | V17: 0 | W17: 0
A18: Accounts Payable Opening Balance | B18: Opening balance seed | C18: 4000 | D18: 0 | E18: 0 | F18: 0 | G18: 0 | H18: 0 | I18: 0 | J18: 0 | K18: 0 | L18: 0 | M18: 0 | N18: 0 | O18: 0 | P18: 0 | Q18: 0 | R18: 0 | S18: 0 | T18: 0 | U18: 0 | V18: 0 | W18: 0
A19: Short Term Debt Opening Balance | B19: Opening balance seed | C19: 0 | D19: 0 | E19: 0 | F19: 0 | G19: 0 | H19: 0 | I19: 0 | J19: 0 | K19: 0 | L19: 0 | M19: 0 | N19: 0 | O19: 0 | P19: 0 | Q19: 0 | R19: 0 | S19: 0 | T19: 0 | U19: 0 | V19: 0 | W19: 0

Sheet Cash Equity Schedule
A1: Cash & Equity Schedule
A2: Equity, distributions, lease/rent, and opening cash seeds. Model Inputs links to these rows.
C4: Stub | D4: Q1 | E4: Q2 | F4: Q3 | G4: Q4 | H4: Q5 | I4: Q6 | J4: Q7 | K4: Q8 | L4: Q9 | M4: Q10 | N4: Q11 | O4: Q12 | P4: Q13 | Q4: Q14 | R4: Q15 | S4: Q16 | T4: Q17 | U4: Q18 | V4: Q19 | W4: Q20 | X4: Y1 | Y4: Y2 | Z4: Y3 | AA4: Y4 | AB4: Y5
C5: 46162 | D5: 46295 | E5: 46387 | F5: 46477 | G5: 46568 | H5: 46660 | I5: 46752 | J5: 46843 | K5: 46934 | L5: 47026 | M5: 47118 | N5: 47208 | O5: 47299 | P5: 47391 | Q5: 47483 | R5: 47573 | S5: 47664 | T5: 47756 | U5: 47848 | V5: 47938 | W5: 48029 | X5: Annual | Y5: Annual | Z5: Annual | AA5: Annual | AB5: Annual
A6: Equity and Distributions
A7: Owner's Capital | B7: Equity / distribution input | C7: 45000 | D7: 46229083 | E7: 78731191 | F7: 110631979 | G7: 141884050 | H7: 172083847 | I7: 200913067 | J7: 228094164 | K7: 253394736 | L7: 276500513 | M7: 297047509 | N7: 314722680 | O7: 332761977 | P7: 350530836 | Q7: 368013828 | R7: 385201629 | S7: 402128145 | T7: 418770617 | U7: 435114802 | V7: 451152836 | W7: 466911700
A8: Other Equity | B8: Equity / distribution input | C8: 0 | D8: 0 | E8: 0 | F8: 0 | G8: 0 | H8: 0 | I8: 0 | J8: 0 | K8: 0 | L8: 0 | M8: 0 | N8: 0 | O8: 0 | P8: 0 | Q8: 0 | R8: 0 | S8: 0 | T8: 0 | U8: 0 | V8: 0 | W8: 0
A9: Distributions | B9: Equity / distribution input | C9: 0 | D9: 0 | E9: 0 | F9: 0 | G9: 0 | H9: 0 | I9: 0 | J9: 0 | K9: 0 | L9: 0 | M9: 0 | N9: 0 | O9: 0 | P9: 0 | Q9: 0 | R9: 0 | S9: 0 | T9: 0 | U9: 0 | V9: 0 | W9: 0
A11: Operating Fixed Cash Items
A12: Lease | B12: Operating lease/rent input | C12: 7500 | D12: 7500 | E12: 7500 | F12: 7500 | G12: 7500 | H12: 7500 | I12: 7500 | J12: 7500 | K12: 7500 | L12: 7500 | M12: 7500 | N12: 7500 | O12: 7500 | P12: 7500 | Q12: 7500 | R12: 7500 | S12: 7500 | T12: 7500 | U12: 7500 | V12: 7500 | W12: 7500

Sheet Model Inputs
A1: Model Inputs
A2: Formula-driven bridge from schedules into FINMO. FINMO references this sheet only.
C4: Stub | D4: Q1 | E4: Q2 | F4: Q3 | G4: Q4 | H4: Q5 | I4: Q6 | J4: Q7 | K4: Q8 | L4: Q9 | M4: Q10 | N4: Q11 | O4: Q12 | P4: Q13 | Q4: Q14 | R4: Q15 | S4: Q16 | T4: Q17 | U4: Q18 | V4: Q19 | W4: Q20 | X4: Y1 | Y4: Y2 | Z4: Y3 | AA4: Y4 | AB4: Y5
C5: 46162 | D5: 46295 | E5: 46387 | F5: 46477 | G5: 46568 | H5: 46660 | I5: 46752 | J5: 46843 | K5: 46934 | L5: 47026 | M5: 47118 | N5: 47208 | O5: 47299 | P5: 47391 | Q5: 47483 | R5: 47573 | S5: 47664 | T5: 47756 | U5: 47848 | V5: 47938 | W5: 48029 | X5: Annual | Y5: Annual | Z5: Annual | AA5: Annual | AB5: Annual
A6: Income Statement Inputs
A7: Primary line of business / Billable home visit - Capacity | B7: Revenue Drivers schedule | C7: ='Revenue Drivers'!C8 -> 1040 | D7: ='Revenue Drivers'!D8 -> 2364.03 | E7: ='Revenue Drivers'!E8 -> 2364.03 | F7: ='Revenue Drivers'!F8 -> 2364.03 | G7: ='Revenue Drivers'!G8 -> 2364.03 | H7: ='Revenue Drivers'!H8 -> 2364.03 | I7: ='Revenue Drivers'!I8 -> 2364.03 | J7: ='Revenue Drivers'!J8 -> 2364.03 | ... W7: ='Revenue Drivers'!W8 -> 2364.03 | X7: =SUM(D7:G7) -> 9456.12 | Y7: =SUM(H7:K7) -> 9456.12 | Z7: =SUM(L7:O7) -> 9456.12 | AA7: =SUM(P7:S7) -> 9456.12 | AB7: =SUM(T7:W7) -> 9456.12
A8: Primary line of business / Billable home visit - Unit Price | B8: Revenue Drivers schedule | C8: ='Revenue Drivers'!C9 -> 150 | D8: ='Revenue Drivers'!D9 -> 150 | E8: ='Revenue Drivers'!E9 -> 158 | F8: ='Revenue Drivers'!F9 -> 166 | G8: ='Revenue Drivers'!G9 -> 174 | H8: ='Revenue Drivers'!H9 -> 182 | I8: ='Revenue Drivers'!I9 -> 190 | J8: ='Revenue Drivers'!J9 -> 198 | ... W8: ='Revenue Drivers'!W9 -> 240 | X8: =SUM(D8:G8) -> 648 | Y8: =SUM(H8:K8) -> 776 | Z8: =SUM(L8:O8) -> 897.11111 | AA8: =SUM(P8:S8) -> 935.55556 | AB8: =SUM(T8:W8) -> 953.33333
A9: Primary line of business / Billable home visit - Utilization | B9: Revenue Drivers schedule | C9: ='Revenue Drivers'!C10 -> 0.75 | D9: ='Revenue Drivers'!D10 -> 0.75 | E9: ='Revenue Drivers'!E10 -> 0.759 | F9: ='Revenue Drivers'!F10 -> 0.768 | G9: ='Revenue Drivers'!G10 -> 0.777 | H9: ='Revenue Drivers'!H10 -> 0.786 | I9: ='Revenue Drivers'!I10 -> 0.795 | J9: ='Revenue Drivers'!J10 -> 0.804 | ... W9: ='Revenue Drivers'!W10 -> 0.84 | X9: =SUM(D9:G9) -> 3.054 | Y9: =SUM(H9:K9) -> 3.198 | Z9: =SUM(L9:O9) -> 3.333 | AA9: =SUM(P9:S9) -> 3.36 | AB9: =SUM(T9:W9) -> 3.36
A10: Primary line of business / Billable home visit - Revenue | B10: Revenue Drivers schedule | C10: ='Revenue Drivers'!C11 -> 117000 | D10: ='Revenue Drivers'!D11 -> 265953.38 | E10: ='Revenue Drivers'!E11 -> 283499.21 | F10: ='Revenue Drivers'!F11 -> 301385.46 | G10: ='Revenue Drivers'!G11 -> 319612.13 | H10: ='Revenue Drivers'!H11 -> 338179.22 | I10: ='Revenue Drivers'!I11 -> 357086.73 | J10: ='Revenue Drivers'!J11 -> 376334.66 | ... W10: ='Revenue Drivers'!W11 -> 476588.45 | X10: =SUM(D10:G10) -> 1170450.2 | Y10: =SUM(H10:K10) -> 1467523.6 | Z10: =SUM(L10:O10) -> 1767640.4 | AA10: =SUM(P10:S10) -> 1857812.4 | AB10: =SUM(T10:W10) -> 1893115.2
A11: Revenue | B11: Revenue Drivers schedule | C11: ='Revenue Drivers'!C14 -> 117000 | D11: ='Revenue Drivers'!D14 -> 265953.38 | E11: ='Revenue Drivers'!E14 -> 283499.21 | F11: ='Revenue Drivers'!F14 -> 301385.46 | G11: ='Revenue Drivers'!G14 -> 319612.13 | H11: ='Revenue Drivers'!H14 -> 338179.22 | I11: ='Revenue Drivers'!I14 -> 357086.73 | J11: ='Revenue Drivers'!J14 -> 376334.66 | ... W11: ='Revenue Drivers'!W14 -> 476588.45 | X11: =SUM(D11:G11) -> 1170450.2 | Y11: =SUM(H11:K11) -> 1467523.6 | Z11: =SUM(L11:O11) -> 1767640.4 | AA11: =SUM(P11:S11) -> 1857812.4 | AB11: =SUM(T11:W11) -> 1893115.2
A12: Cost of Goods Sold | B12: Direct model driver | C12: 0.675518 | D12: 75 | E12: 71 | F12: 67 | G12: 63 | H12: 59 | I12: 55 | J12: 51 | K12: 47 | L12: 43 | M12: 39 | N12: 35 | O12: 34.444444 | P12: 33.888889 | Q12: 33.333333 | R12: 32.777778 | S12: 32.222222 | T12: 31.666667 | U12: 31.111111 | V12: 30.555556 | W12: 30 | X12: =SUM(D12:G12) -> 276 | Y12: =SUM(H12:K12) -> 212 | Z12: =SUM(L12:O12) -> 151.44444 | AA12: =SUM(P12:S12) -> 132.22222 | AB12: =SUM(T12:W12) -> 123.33333
A13: Marketing | B13: Direct model driver | C13: 0.079412 | D13: 24 | E13: 21.9 | F13: 19.8 | G13: 17.7 | H13: 15.6 | I13: 13.5 | J13: 11.4 | K13: 9.3 | L13: 7.2 | M13: 5.1 | N13: 3 | O13: 2.8888889 | P13: 2.7777778 | Q13: 2.6666667 | R13: 2.5555556 | S13: 2.4444444 | T13: 2.3333333 | U13: 2.2222222 | V13: 2.1111111 | W13: 2 | X13: =SUM(D13:G13) -> 83.4 | Y13: =SUM(H13:K13) -> 49.8 | Z13: =SUM(L13:O13) -> 18.188889 | AA13: =SUM(P13:S13) -> 10.444444 | AB13: =SUM(T13:W13) -> 8.6666667
A14: Research & Development | B14: Direct model driver | C14: 0 | D14: 0 | E14: 0 | F14: 0 | G14: 0 | H14: 0 | I14: 0 | J14: 0 | K14: 0 | L14: 0 | M14: 0 | N14: 0 | O14: 0 | P14: 0 | Q14: 0 | R14: 0 | S14: 0 | T14: 0 | U14: 0 | V14: 0 | W14: 0 | X14: =SUM(D14:G14) -> 0 | Y14: =SUM(H14:K14) -> 0 | Z14: =SUM(L14:O14) -> 0 | AA14: =SUM(P14:S14) -> 0 | AB14: =SUM(T14:W14) -> 0
A15: Lease | B15: Cash Equity Schedule output | C15: ='Cash Equity Schedule'!C12 -> 7500 | D15: ='Cash Equity Schedule'!D12 -> 7500 | E15: ='Cash Equity Schedule'!E12 -> 7500 | F15: ='Cash Equity Schedule'!F12 -> 7500 | G15: ='Cash Equity Schedule'!G12 -> 7500 | H15: ='Cash Equity Schedule'!H12 -> 7500 | I15: ='Cash Equity Schedule'!I12 -> 7500 | J15: ='Cash Equity Schedule'!J12 -> 7500 | ... W15: ='Cash Equity Schedule'!W12 -> 7500 | X15: =SUM(D15:G15) -> 30000 | Y15: =SUM(H15:K15) -> 30000 | Z15: =SUM(L15:O15) -> 30000 | AA15: =SUM(P15:S15) -> 30000 | AB15: =SUM(T15:W15) -> 30000
A16: Payroll | B16: Payroll Schedule output | C16: 102356.25 | D16: ='Payroll Schedule'!D17 -> 106929.45 | E16: ='Payroll Schedule'!E17 -> 106929.45 | F16: ='Payroll Schedule'!F17 -> 106929.45 | G16: ='Payroll Schedule'!G17 -> 106929.45 | H16: ='Payroll Schedule'!H17 -> 110137.57 | I16: ='Payroll Schedule'!I17 -> 110137.57 | J16: ='Payroll Schedule'!J17 -> 110137.57 | K16: ='Payroll Schedule'!K17 -> 110137.57 | ... W16: ='Payroll Schedule'!W17 -> 120350.07 | X16: =SUM(D16:G16) -> 427717.8 | Y16: =SUM(H16:K16) -> 440550.3 | Z16: =SUM(L16:O16) -> 453764.83 | AA16: =SUM(P16:S16) -> 467378.62 | AB16: =SUM(T16:W16) -> 481400.27
A17: General & Administrative | B17: Direct model driver | C17: 0.002024 | D17: 24 | E17: 21.9 | F17: 19.8 | G17: 17.7 | H17: 15.6 | I17: 13.5 | J17: 11.4 | K17: 9.3 | L17: 7.2 | M17: 5.1 | N17: 3 | O17: 2.8888889 | P17: 2.7777778 | Q17: 2.6666667 | R17: 2.5555556 | S17: 2.4444444 | T17: 2.3333333 | U17: 2.2222222 | V17: 2.1111111 | W17: 2 | X17: =SUM(D17:G17) -> 83.4 | Y17: =SUM(H17:K17) -> 49.8 | Z17: =SUM(L17:O17) -> 18.188889 | AA17: =SUM(P17:S17) -> 10.444444 | AB17: =SUM(T17:W17) -> 8.6666667
A18: Interest Rate | B18: Debt Schedule output | C18: ='Debt Schedule'!C12 -> 0.01 | D18: ='Debt Schedule'!D12 -> 0.025 | E18: ='Debt Schedule'!E12 -> 0.025 | F18: ='Debt Schedule'!F12 -> 0.025 | G18: ='Debt Schedule'!G12 -> 0.025 | H18: ='Debt Schedule'!H12 -> 0.025 | I18: ='Debt Schedule'!I12 -> 0.025 | J18: ='Debt Schedule'!J12 -> 0.025 | ... W18: ='Debt Schedule'!W12 -> 0.025 | X18: =SUM(D18:G18) -> 0.1 | Y18: =SUM(H18:K18) -> 0.1 | Z18: =SUM(L18:O18) -> 0.1 | AA18: =SUM(P18:S18) -> 0.1 | AB18: =SUM(T18:W18) -> 0.1
A19: Interest Expense | B19: Debt Schedule output | C19: 0 | D19: ='Debt Schedule'!D13 -> 731.25 | E19: ='Debt Schedule'!E13 -> 693.75 | F19: ='Debt Schedule'!F13 -> 656.25 | G19: ='Debt Schedule'!G13 -> 618.75 | H19: ='Debt Schedule'!H13 -> 581.25 | I19: ='Debt Schedule'!I13 -> 543.75 | J19: ='Debt Schedule'!J13 -> 506.25 | K19: ='Debt Schedule'!K13 -> 468.75 | ... W19: ='Debt Schedule'!W13 -> 18.75 | X19: =SUM(D19:G19) -> 2700 | Y19: =SUM(H19:K19) -> 2100 | Z19: =SUM(L19:O19) -> 1500 | AA19: =SUM(P19:S19) -> 900 | AB19: =SUM(T19:W19) -> 300
A20: Depreciation | B20: CapEx Depreciation output | C20: ='CapEx Depreciation'!C10 -> 0 | D20: ='CapEx Depreciation'!D10 -> 0.00025 | E20: ='CapEx Depreciation'!E10 -> 0.000499 | F20: ='CapEx Depreciation'!F10 -> 0.000747 | G20: ='CapEx Depreciation'!G10 -> 0.000993 | H20: ='CapEx Depreciation'!H10 -> 0.001239 | I20: ='CapEx Depreciation'!I10 -> 0.001485 | J20: ='CapEx Depreciation'!J10 -> 0.00173 | ... W20: ='CapEx Depreciation'!W10 -> 0.004916 | X20: =SUM(D20:G20) -> 0.002489 | Y20: =SUM(H20:K20) -> 0.006428 | Z20: =SUM(L20:O20) -> 0.010335 | AA20: =SUM(P20:S20) -> 0.01424 | AB20: =SUM(T20:W20) -> 0.018176
A21: Depreciation Expense | B21: CapEx Depreciation output | C21: ='CapEx Depreciation'!C11 -> 0 | D21: ='CapEx Depreciation'!D11 -> 10 | E21: ='CapEx Depreciation'!E11 -> 20.05481 | F21: ='CapEx Depreciation'!F11 -> 30.157059 | G21: ='CapEx Depreciation'!G11 -> 40.258794 | H21: ='CapEx Depreciation'!H11 -> 50.433553 | I21: ='CapEx Depreciation'!I11 -> 60.674336 | J21: ='CapEx Depreciation'!J11 -> 70.933036 | ... W21: ='CapEx Depreciation'!W11 -> 206.34396 | X21: =SUM(D21:G21) -> 100.47066 | Y21: =SUM(H21:K21) -> 263.24305 | Z21: =SUM(L21:O21) -> 428.23144 | AA21: =SUM(P21:S21) -> 594.78996 | AB21: =SUM(T21:W21) -> 762.37971
A22: Taxes | B22: Direct model driver | C22: 0.237834 | D22: 0.237834 | E22: 0.237834 | F22: 0.237834 | G22: 0.237834 | H22: 0.237834 | I22: 0.237834 | J22: 0.237834 | K22: 0.237834 | L22: 0.237834 | M22: 0.237834 | N22: 0.237834 | O22: 0.237834 | P22: 0.237834 | Q22: 0.237834 | R22: 0.237834 | S22: 0.237834 | T22: 0.237834 | U22: 0.237834 | V22: 0.237834 | W22: 0.237834 | X22: =SUM(D22:G22) -> 0.951336 | Y22: =SUM(H22:K22) -> 0.951336 | Z22: =SUM(L22:O22) -> 0.951336 | AA22: =SUM(P22:S22) -> 0.951336 | AB22: =SUM(T22:W22) -> 0.951336
A24: Balance Sheet Inputs
A25: Accounts Receivable Days | B25: Working Capital schedule | C25: ='Working Capital'!C7 -> 0 | D25: ='Working Capital'!D7 -> 30 | E25: ='Working Capital'!E7 -> 30 | F25: ='Working Capital'!F7 -> 30 | G25: ='Working Capital'!G7 -> 30 | H25: ='Working Capital'!H7 -> 30 | I25: ='Working Capital'!I7 -> 30 | J25: ='Working Capital'!J7 -> 30 | ... W25: ='Working Capital'!W7 -> 30 | X25: =SUM(D25:G25) -> 120 | Y25: =SUM(H25:K25) -> 120 | Z25: =SUM(L25:O25) -> 120 | AA25: =SUM(P25:S25) -> 120 | AB25: =SUM(T25:W25) -> 120
A26: Inventory Days | B26: Working Capital schedule | C26: ='Working Capital'!C8 -> 0 | D26: ='Working Capital'!D8 -> 0 | E26: ='Working Capital'!E8 -> 0 | F26: ='Working Capital'!F8 -> 0 | G26: ='Working Capital'!G8 -> 0 | H26: ='Working Capital'!H8 -> 0 | I26: ='Working Capital'!I8 -> 0 | J26: ='Working Capital'!J8 -> 0 | ... W26: ='Working Capital'!W8 -> 0 | X26: =SUM(D26:G26) -> 0 | Y26: =SUM(H26:K26) -> 0 | Z26: =SUM(L26:O26) -> 0 | AA26: =SUM(P26:S26) -> 0 | AB26: =SUM(T26:W26) -> 0
A27: Accounts Payable Days | B27: Working Capital schedule | C27: ='Working Capital'!C9 -> 0 | D27: ='Working Capital'!D9 -> 30 | E27: ='Working Capital'!E9 -> 30 | F27: ='Working Capital'!F9 -> 30 | G27: ='Working Capital'!G9 -> 30 | H27: ='Working Capital'!H9 -> 30 | I27: ='Working Capital'!I9 -> 30 | J27: ='Working Capital'!J9 -> 30 | ... W27: ='Working Capital'!W9 -> 30 | X27: =SUM(D27:G27) -> 120 | Y27: =SUM(H27:K27) -> 120 | Z27: =SUM(L27:O27) -> 120 | AA27: =SUM(P27:S27) -> 120 | AB27: =SUM(T27:W27) -> 120
A28: Prepaid Expenses (% of Revenue) | B28: Working Capital schedule | C28: ='Working Capital'!C10 -> 0 | D28: ='Working Capital'!D10 -> 5 | E28: ='Working Capital'!E10 -> 5 | F28: ='Working Capital'!F10 -> 5 | G28: ='Working Capital'!G10 -> 5 | H28: ='Working Capital'!H10 -> 5 | I28: ='Working Capital'!I10 -> 5 | J28: ='Working Capital'!J10 -> 5 | ... W28: ='Working Capital'!W10 -> 5 | X28: =SUM(D28:G28) -> 20 | Y28: =SUM(H28:K28) -> 20 | Z28: =SUM(L28:O28) -> 20 | AA28: =SUM(P28:S28) -> 20 | AB28: =SUM(T28:W28) -> 20
A29: Deferred Revenue (% of Revenue) | B29: Working Capital schedule | C29: ='Working Capital'!C11 -> 0 | D29: ='Working Capital'!D11 -> 0 | E29: ='Working Capital'!E11 -> 0 | F29: ='Working Capital'!F11 -> 0 | G29: ='Working Capital'!G11 -> 0 | H29: ='Working Capital'!H11 -> 0 | I29: ='Working Capital'!I11 -> 0 | J29: ='Working Capital'!J11 -> 0 | ... W29: ='Working Capital'!W11 -> 0 | X29: =SUM(D29:G29) -> 0 | Y29: =SUM(H29:K29) -> 0 | Z29: =SUM(L29:O29) -> 0 | AA29: =SUM(P29:S29) -> 0 | AB29: =SUM(T29:W29) -> 0
A30: Short Term Debt (% of LTD) | B30: Working Capital schedule | C30: ='Working Capital'!C12 -> 0 | D30: ='Working Capital'!D12 -> 0 | E30: ='Working Capital'!E12 -> 0 | F30: ='Working Capital'!F12 -> 0 | G30: ='Working Capital'!G12 -> 0 | H30: ='Working Capital'!H12 -> 0 | I30: ='Working Capital'!I12 -> 0 | J30: ='Working Capital'!J12 -> 0 | ... W30: ='Working Capital'!W12 -> 0 | X30: =SUM(D30:G30) -> 0 | Y30: =SUM(H30:K30) -> 0 | Z30: =SUM(L30:O30) -> 0 | AA30: =SUM(P30:S30) -> 0 | AB30: =SUM(T30:W30) -> 0
A31: Owner's Capital | B31: Cash Equity Schedule schedule | C31: ='Cash Equity Schedule'!C7 -> 45000 | D31: ='Cash Equity Schedule'!D7 -> 46229083 | E31: ='Cash Equity Schedule'!E7 -> 78731191 | F31: ='Cash Equity Schedule'!F7 -> 110631979 | G31: ='Cash Equity Schedule'!G7 -> 141884050 | H31: ='Cash Equity Schedule'!H7 -> 172083847 | I31: ='Cash Equity Schedule'!I7 -> 200913067 | J31: ='Cash Equity Schedule'!J7 -> 228094164 | ... W31: ='Cash Equity Schedule'!W7 -> 466911700 | X31: =G31 -> 141884050 | Y31: =K31 -> 253394736 | Z31: =O31 -> 332761977 | AA31: =S31 -> 402128145 | AB31: =W31 -> 466911700
A32: Other Equity | B32: Cash Equity Schedule schedule | C32: ='Cash Equity Schedule'!C8 -> 0 | D32: ='Cash Equity Schedule'!D8 -> 0 | E32: ='Cash Equity Schedule'!E8 -> 0 | F32: ='Cash Equity Schedule'!F8 -> 0 | G32: ='Cash Equity Schedule'!G8 -> 0 | H32: ='Cash Equity Schedule'!H8 -> 0 | I32: ='Cash Equity Schedule'!I8 -> 0 | J32: ='Cash Equity Schedule'!J8 -> 0 | ... W32: ='Cash Equity Schedule'!W8 -> 0 | X32: =G32 -> 0 | Y32: =K32 -> 0 | Z32: =O32 -> 0 | AA32: =S32 -> 0 | AB32: =W32 -> 0
A33: Distributions | B33: Cash Equity Schedule schedule | C33: ='Cash Equity Schedule'!C9 -> 0 | D33: ='Cash Equity Schedule'!D9 -> 0 | E33: ='Cash Equity Schedule'!E9 -> 0 | F33: ='Cash Equity Schedule'!F9 -> 0 | G33: ='Cash Equity Schedule'!G9 -> 0 | H33: ='Cash Equity Schedule'!H9 -> 0 | I33: ='Cash Equity Schedule'!I9 -> 0 | J33: ='Cash Equity Schedule'!J9 -> 0 | ... W33: ='Cash Equity Schedule'!W9 -> 0 | X33: =G33 -> 0 | Y33: =K33 -> 0 | Z33: =O33 -> 0 | AA33: =S33 -> 0 | AB33: =W33 -> 0
A35: Cash Flow and Schedule Inputs
A36: Cash Opening Balance | B36: Working Capital schedule | C36: ='Working Capital'!C15 -> 12000 | D36: ='Working Capital'!D15 -> 0 | E36: ='Working Capital'!E15 -> 0 | F36: ='Working Capital'!F15 -> 0 | G36: ='Working Capital'!G15 -> 0 | H36: ='Working Capital'!H15 -> 0 | I36: ='Working Capital'!I15 -> 0 | J36: ='Working Capital'!J15 -> 0 | ... W36: ='Working Capital'!W15 -> 0 | X36: =G36 -> 0 | Y36: =K36 -> 0 | Z36: =O36 -> 0 | AA36: =S36 -> 0 | AB36: =W36 -> 0
A37: Accounts Receivable Opening Balance | B37: Working Capital schedule | C37: ='Working Capital'!C16 -> 0 | D37: ='Working Capital'!D16 -> 0 | E37: ='Working Capital'!E16 -> 0 | F37: ='Working Capital'!F16 -> 0 | G37: ='Working Capital'!G16 -> 0 | H37: ='Working Capital'!H16 -> 0 | I37: ='Working Capital'!I16 -> 0 | J37: ='Working Capital'!J16 -> 0 | ... W37: ='Working Capital'!W16 -> 0 | X37: =G37 -> 0 | Y37: =K37 -> 0 | Z37: =O37 -> 0 | AA37: =S37 -> 0 | AB37: =W37 -> 0
A38: Inventory Opening Balance | B38: Working Capital schedule | C38: ='Working Capital'!C17 -> 0 | D38: ='Working Capital'!D17 -> 0 | E38: ='Working Capital'!E17 -> 0 | F38: ='Working Capital'!F17 -> 0 | G38: ='Working Capital'!G17 -> 0 | H38: ='Working Capital'!H17 -> 0 | I38: ='Working Capital'!I17 -> 0 | J38: ='Working Capital'!J17 -> 0 | ... W38: ='Working Capital'!W17 -> 0 | X38: =G38 -> 0 | Y38: =K38 -> 0 | Z38: =O38 -> 0 | AA38: =S38 -> 0 | AB38: =W38 -> 0
A39: Accounts Payable Opening Balance | B39: Working Capital schedule | C39: ='Working Capital'!C18 -> 4000 | D39: ='Working Capital'!D18 -> 0 | E39: ='Working Capital'!E18 -> 0 | F39: ='Working Capital'!F18 -> 0 | G39: ='Working Capital'!G18 -> 0 | H39: ='Working Capital'!H18 -> 0 | I39: ='Working Capital'!I18 -> 0 | J39: ='Working Capital'!J18 -> 0 | ... W39: ='Working Capital'!W18 -> 0 | X39: =G39 -> 0 | Y39: =K39 -> 0 | Z39: =O39 -> 0 | AA39: =S39 -> 0 | AB39: =W39 -> 0
A40: Short Term Debt Opening Balance | B40: Working Capital schedule | C40: ='Working Capital'!C19 -> 0 | D40: ='Working Capital'!D19 -> 0 | E40: ='Working Capital'!E19 -> 0 | F40: ='Working Capital'!F19 -> 0 | G40: ='Working Capital'!G19 -> 0 | H40: ='Working Capital'!H19 -> 0 | I40: ='Working Capital'!I19 -> 0 | J40: ='Working Capital'!J19 -> 0 | ... W40: ='Working Capital'!W19 -> 0 | X40: =G40 -> 0 | Y40: =K40 -> 0 | Z40: =O40 -> 0 | AA40: =S40 -> 0 | AB40: =W40 -> 0
A41: Debt Opening Balance | B41: Debt Schedule schedule | C41: ='Debt Schedule'!C7 -> 30000 | D41: ='Debt Schedule'!D7 -> 30000 | E41: ='Debt Schedule'!E7 -> 28500 | F41: ='Debt Schedule'!F7 -> 27000 | G41: ='Debt Schedule'!G7 -> 25500 | H41: ='Debt Schedule'!H7 -> 24000 | I41: ='Debt Schedule'!I7 -> 22500 | J41: ='Debt Schedule'!J7 -> 21000 | ... W41: ='Debt Schedule'!W7 -> 1500 | X41: =G41 -> 25500 | Y41: =K41 -> 19500 | Z41: =O41 -> 13500 | AA41: =S41 -> 7500 | AB41: =W41 -> 1500
A42: Debt Issuance | B42: Debt Schedule schedule | C42: ='Debt Schedule'!C8 -> 0 | D42: ='Debt Schedule'!D8 -> 0 | E42: ='Debt Schedule'!E8 -> 0 | F42: ='Debt Schedule'!F8 -> 0 | G42: ='Debt Schedule'!G8 -> 0 | H42: ='Debt Schedule'!H8 -> 0 | I42: ='Debt Schedule'!I8 -> 0 | J42: ='Debt Schedule'!J8 -> 0 | ... W42: ='Debt Schedule'!W8 -> 0 | X42: =SUM(D42:G42) -> 0 | Y42: =SUM(H42:K42) -> 0 | Z42: =SUM(L42:O42) -> 0 | AA42: =SUM(P42:S42) -> 0 | AB42: =SUM(T42:W42) -> 0
A43: Debt Repayment | B43: Debt Schedule schedule | C43: ='Debt Schedule'!C10 -> 0 | D43: ='Debt Schedule'!D10 -> 1500 | E43: ='Debt Schedule'!E10 -> 1500 | F43: ='Debt Schedule'!F10 -> 1500 | G43: ='Debt Schedule'!G10 -> 1500 | H43: ='Debt Schedule'!H10 -> 1500 | I43: ='Debt Schedule'!I10 -> 1500 | J43: ='Debt Schedule'!J10 -> 1500 | ... W43: ='Debt Schedule'!W10 -> 1500 | X43: =SUM(D43:G43) -> 6000 | Y43: =SUM(H43:K43) -> 6000 | Z43: =SUM(L43:O43) -> 6000 | AA43: =SUM(P43:S43) -> 6000 | AB43: =SUM(T43:W43) -> 6000
...

Sheet FINMO
A1: FINMO
A2: Three-statement financial model. All formulas reference Model Inputs and in-sheet statement rows.
C4: Stub | D4: Q1 | E4: Q2 | F4: Q3 | G4: Q4 | H4: Q5 | I4: Q6 | J4: Q7 | K4: Q8 | L4: Q9 | M4: Q10 | N4: Q11 | O4: Q12 | P4: Q13 | Q4: Q14 | R4: Q15 | S4: Q16 | T4: Q17 | U4: Q18 | V4: Q19 | W4: Q20 | X4: Y1 | Y4: Y2 | Z4: Y3 | AA4: Y4 | AB4: Y5
C5: 46162 | D5: 46295 | E5: 46387 | F5: 46477 | G5: 46568 | H5: 46660 | I5: 46752 | J5: 46843 | K5: 46934 | L5: 47026 | M5: 47118 | N5: 47208 | O5: 47299 | P5: 47391 | Q5: 47483 | R5: 47573 | S5: 47664 | T5: 47756 | U5: 47848 | V5: 47938 | W5: 48029 | X5: Annual | Y5: Annual | Z5: Annual | AA5: Annual | AB5: Annual
A6: Days in Quarter | C6: 0 | D6: 92 | E6: 92 | F6: 90 | G6: 91 | H6: 92 | I6: 92 | J6: 91 | K6: 91 | L6: 92 | M6: 92 | N6: 90 | O6: 91 | P6: 92 | Q6: 92 | R6: 90 | S6: 91 | T6: 92 | U6: 92 | V6: 90 | W6: 91
A7: Income Statement
A8: Revenue | B8: Formula | C8: ='Model Inputs'!C11 -> 117000 | D8: ='Model Inputs'!D11 -> 265953.38 | E8: ='Model Inputs'!E11 -> 283499.21 | F8: ='Model Inputs'!F11 -> 301385.46 | G8: ='Model Inputs'!G11 -> 319612.13 | H8: ='Model Inputs'!H11 -> 338179.22 | I8: ='Model Inputs'!I11 -> 357086.73 | J8: ='Model Inputs'!J11 -> 376334.66 | ... W8: ='Model Inputs'!W11 -> 476588.45 | X8: =SUM(D8:G8) -> 1170450.2 | Y8: =SUM(H8:K8) -> 1467523.6 | Z8: =SUM(L8:O8) -> 1767640.4 | AA8: =SUM(P8:S8) -> 1857812.4 | AB8: =SUM(T8:W8) -> 1893115.2
